Workbook
Name A73A73: 'Combined Delivery Data'!$A$73:$A$73
Name B49B81: 'Combined Delivery Data'!$B$49:$B$49
Name cmsBlocked: CombinedDeliveryData[Blocked?]
Name cmsCheck: CombinedDeliveryData[Data Check]
Name cmsDBDev: CombinedDeliveryData[DB Developer]
Name cmsDBDone: CombinedDeliveryData[DB Dev Actual Completion Date]
Name cmsDom: CombinedDeliveryData[Domain]
Name cmsDPO: CombinedDeliveryData[DPO Approval Reviewer]
Name cmsDPODone: CombinedDeliveryData[DPO Approval Completion Date]
Name cmsMonth: CombinedDeliveryData[Plan Delivery Month]
Name cmsName: CombinedDeliveryData[Report Name]
Name cmsPBIDev: CombinedDeliveryData[PBI Developer]
Name cmsPBIDone: CombinedDeliveryData[PBI Dev Actual Completion Date]
Name cmsQA: CombinedDeliveryData[QA Tester]
Name cmsQADone: CombinedDeliveryData[QA Actual Completion Date]
Name cmsStatus: CombinedDeliveryData[Current Status (Update next stage after completion date)]
Name DB_Dev_List: 'Data Validation'!$B$3:$B$12
Name DPO_Approval_List: 'Data Validation'!$K$3:$K$6
Name L2T2: 'Rework Log'!$L$1:$L$1
Name PBI_Dev_List: 'Data Validation'!$C$3:$C$5
Name QA_List: 'Data Validation'!$H$3:$H$7

Sheet Combined Delivery Data
A1: Domain | B1: Report Name | C1: Current Status (Update next stage after completion date) | D1: Status Flag | E1: Business Value Rank | F1: PO | G1: Schema | H1: Plan Delivery Date | I1: Plan Delivery Month | J1: DB Developer | K1: DB Dev Baseline Completion Date | L1: DB Dev Reforecast Completion Date | M1: DB Dev Actual Completion Date | N1: Build Source | O1: Sprint DB | P1: PBI Developer | Q1: PBI Dev Baseline Completion Date | R1: PBI Dev Reforecast Completion Date | S1: PBI Dev Actual Completion Date | T1: Sprint PBI | U1: QA Tester | V1: QA Baseline Completion Date | W1: QA Reforecast Completion Date | X1: Initial QA Completion Date | Y1: QA Actual Completion Date | Z1: Sprint QA | AA1: DPO Approval Baseline Completion Date | AB1: DPO Approval Reforecast Completion Date | AC1: DPO Approval Completion Date | AD1: DPO Approval Reviewer | AE1: Report Type | AF1: Confirmed Deployed? | AG1: Confirmed Deployed Date | AH1: UAT Report URL | AI1: Production URL | AJ1: Blocked? | AK1: Data Check | AL1: Comments | AM1: QA Rework Due DPO Rework Due | AN1: Column1
A2: Leaks | B2: RPT_04_Active Leaks | C2: RELEASED IN PROD | D2: {=IF(AND(C2="Ready for Release in Prod",LEFT($AJ2,3)<>"Yes"),IF(AG2<>"","Delivered","On track"),IF($B2="","",IF(LEFT($AJ2,3)="Yes","Blocked - "&MID($AJ2,7,100)&IF(SUMPRODUCT(('Rework Log'!$A$2:$A$497=$B2)*('Rework Log'!$G$2:$G$497<>"Yes")*('Rework Log'!$G$2:$G$497<>"Did not pass re-test"))=0,"",IF(SUMPRODUCT(MAX((('Rework Log'!$A$2:$A$497=$B2)*('Rework Log'!$G$2:$G$497<>"Yes")*('Rework Log'!$G$2:$G$497<>"Did not pass re-test"))*'Rework Log'!$I$2:$I$497))=0," - unclaimed"," - promised "&TEXT(SUMPRODUCT(MAX((('Rework Log'!$A$2:$A$497=$B2)*('Rework Log'!$G$2:$G$497<>"Yes")*('Rework Log'!$G$2:$G$497<>"Did not pass re-test"))*'Rework Log'!$I$2:$I$497)),"m/d"))),IF(C2="NOT STARTED",IF(H2="","No plan date set",IF(H2<TODAY(),"Review - planned start passed","On track")),IF(C2="DB Dev",_xlfn.LET(_xlpm.sent,_xlfn.MAXIFS('Rework Log'!$B$2:$B$497,'Rework Log'!$A$2:$A$497,$B2,'Rework Log'!$D$2:$D$497,"DB Dev"),_xlpm.expfix,_xlfn.MAXIFS('Rework Log'!$I$2:$I$497,'Rework Log'!$A$2:$A$497,$B2,'Rework Log'!$D$2:$D$497,"DB Dev",'Rework Log'!$B$2:$B$497,_xlpm.sent),_xlpm.tgt,IF(_xlpm.expfix>0,_xlpm.expfix,IF(L2<>"",L2,K2)),_xlpm.act,IF(AND(M2<>"",M2>=_xlpm.sent),M2,""),IF(_xlpm.tgt="","No target set",IF(AND(_xlpm.tgt<TODAY(),_xlpm.act=""),"Overdue","On track"))),IF(C2="PBI Dev",_xlfn.LET(_xlpm.sent,_xlfn.MAXIFS('Rework Log'!$B$2:$B$497,'Rework Log'!$A$2:$A$497,$B2,'Rework Log'!$D$2:$D$497,"PBI Dev"),_xlpm.expfix,_xlfn.MAXIFS('Rework Log'!$I$2:$I$497,'Rework Log'!$A$2:$A$497,$B2,'Rework Log'!$D$2:$D$497,"PBI Dev",'Rework Log'!$B$2:$B$497,_xlpm.sent),_xlpm.tgt,IF(_xlpm.expfix>0,_xlpm.expfix,IF(R2<>"",R2,Q2)),_xlpm.act,IF(AND(S2<>"",S2>=_xlpm.sent),S2,""),IF(_xlpm.tgt="","No target set",IF(AND(_xlpm.tgt<TODAY(),_xlpm.act=""),"Overdue","On track"))),IF(C2="QA",_xlfn.LET(_xlpm.tgt,IF(AM2<>"",AM2,IF(W2<>"",W2,V2)),_xlpm.sent,_xlfn.MAXIFS('Rework Log'!$B$2:$B$497,'Rework Log'!$A$2:$A$497,$B2,'Rework Log'!$C$2:$C$497,"QA"),_xlpm.act,IF(AND(Y2<>"",Y2>=_xlpm.sent),Y2,""),IF(_xlpm.tgt="","No target set",IF(AND(_xlpm.tgt<TODAY(),_xlpm.act=""),"Overdue","On track"))),IF(C2="DPO Approval",_xlfn.LET(_xlpm.tgt,IF(AN2<>"",AN2,IF(AB2<>"",AB2,AA2)),_xlpm.sent,_xlfn.MAXIFS('Rework Log'!$B$2:$B$497,'Rework Log'!$A$2:$A$497,$B2,'Rework Log'!$C$2:$C$497,"DPO*"),_xlpm.act,IF(AND(AC2<>"",AC2>=_xlpm.sent),AC2,""),IF(_xlpm.tgt="","No target set",IF(AND(_xlpm.tgt<TODAY(),_xlpm.act=""),"Overdue","On track"))),IF(C2="RELEASED IN PROD","Delivered","")))))))))} -> Delivered | E2: 1 | H2: 46142 | I2: April | J2: Fetwi | K2: 46122 | M2: 46115 | N2: Curated | P2: Sarath | Q2: 46129 | S2: 46114 | U2: Preety | V2: 46136 | Y2: 46122 | AA2: 46140 | AD2: Kelvin Hu | AE2: compliance | AF2: Yes | AG2: 46122 | AH2: https://app.powerbi.com/groups/me/apps/eedba83d-be9a-45f9-9504-7bfa41e6051a/reports/62307ec4-3158-4457-8dcc-4acc2150cdc3/ccfe9e7f0a40d49acb85?experience=power-bi | AI2: https://app.powerbi.com/groups/me/apps/2c7180b1-0d3d-45be-979e-f7dc86b3557d/reports/8cd4a21d-3abe-4e55-a99e-3af846ab1c67/ccfe9e7f0a40d49acb85?ctid=f98a6a53-25f3-4212-901c-c7787fcd3495&experience=power-bi | AJ2: No | AK2: {=IF($B2="","",_xlfn.LET(_xlpm.nm,$B2,_xlpm.st,$C2,_xlpm.ou,SUMPRODUCT(('Rework Log'!$A$2:$A$497=_xlpm.nm)*('Rework Log'!$G$2:$G$497<>"Yes")*('Rework Log'!$G$2:$G$497<>"Did not pass re-test")*('Rework Log'!$J$2:$J$497="")),_xlpm.ob,SUMPRODUCT(('Rework Log'!$A$2:$A$497=_xlpm.nm)*('Rework Log'!$G$2:$G$497<>"Yes")*('Rework Log'!$G$2:$G$497<>"Did not pass re-test")),_xlpm.oto,IF(SUMPRODUCT(('Rework Log'!$A$2:$A$497=_xlpm.nm)*('Rework Log'!$G$2:$G$497<>"Yes")*('Rework Log'!$G$2:$G$497<>"Did not pass re-test")*('Rework Log'!$J$2:$J$497=""))=0,"",INDEX('Rework Log'!$D$2:$D$497,MATCH(1,('Rework Log'!$A$2:$A$497=_xlpm.nm)*('Rework Log'!$G$2:$G$497<>"Yes")*('Rework Log'!$G$2:$G$497<>"Did not pass re-test")*('Rework Log'!$J$2:$J$497=""),0))),_xlpm.sent,_xlfn.MAXIFS('Rework Log'!$B$2:$B$497,'Rework Log'!$A$2:$A$497,_xlpm.nm),_xlpm.act,_xlfn.IFS(_xlpm.st="NOT STARTED",$M2,_xlpm.st="DB Dev",$M2,_xlpm.st="PBI Dev",$S2,_xlpm.st="QA",$Y2,_xlpm.st="DPO Approval",$AC2,_xlpm.st="Ready for Release in Prod",$AG2,TRUE,""),_xlpm.nxt,_xlfn.IFS(_xlpm.st="NOT STARTED","PBI Dev",_xlpm.st="DB Dev","PBI Dev",_xlpm.st="PBI Dev","QA",_xlpm.st="QA","DPO Approval",_xlpm.st="DPO Approval","Ready for Release in Prod",_xlpm.st="Ready for Release in Prod","RELEASED IN PROD",TRUE,""),IF(AND(_xlpm.ou>0,_xlpm.st<>_xlpm.oto),"Move status back to "&_xlpm.oto,IF(AND(_xlpm.ob=0,LEFT($AJ2,3)="Yes"),"Blocked - log it on Rework Log",IF(AND(_xlpm.ob>0,LEFT($AJ2,3)<>"Yes"),"Open rework row - mark Blocked or close it",IF(AND(_xlpm.ob=0,_xlpm.act<>"",_xlpm.act>=_xlpm.sent,_xlpm.nxt<>""),"Move status to "&_xlpm.nxt,IF(COUNTIF($B$2:$B$528,$B2)>1,"Duplicate name - check row",IF(COUNTIF('Rework Log'!$A$2:$A$497,$B2)>0,"",IF(AND($V2<>"",$K2<>"",$V2<$K2),"QA target is before DB Dev target",IF(AND($V2<>"",$Q2<>"",$V2<$Q2),"QA target is before PBI Dev target",IF(AND($AA2<>"",$V2<>"",$AA2<$V2),"DPO Approval target is before QA target",IF(AND($AG2<>"",$AA2<>"",$AG2<$AA2),"Confirmed Deployed date is before DPO Approval target",""))))))))))))} -> Confirmed Deployed date is before DPO Approval target | AL2: [Historical, April 2026]: QA found an issue - date calendar dimension broken. Fetwi assigned to fix. | AM2: {=_xlfn.LET(_xlpm.rep,$B2,_xlpm.sent,_xlfn.MAXIFS('Rework Log'!$B$2:$B$497,'Rework Log'!$A$2:$A$497,_xlpm.rep,'Rework Log'!$C$2:$C$497,"QA"),_xlpm.fixdate,_xlfn.MAXIFS('Rework Log'!$J$2:$J$497,'Rework Log'!$A$2:$A$497,_xlpm.rep,'Rework Log'!$C$2:$C$497,"QA",'Rework Log'!$B$2:$B$497,_xlpm.sent),_xlpm.expfix,_xlfn.MAXIFS('Rework Log'!$I$2:$I$497,'Rework Log'!$A$2:$A$497,_xlpm.rep,'Rework Log'!$C$2:$C$497,"QA",'Rework Log'!$B$2:$B$497,_xlpm.sent),_xlpm.base,IF(_xlpm.fixdate>0,_xlpm.fixdate,_xlpm.expfix),IF(OR(_xlpm.rep="",_xlpm.sent=0,_xlpm.base=0),"",WORKDAY(_xlpm.base,3)))} | AN2: {=_xlfn.LET(_xlpm.rep,$B2,_xlpm.sent,_xlfn.MAXIFS('Rework Log'!$B$2:$B$497,'Rework Log'!$A$2:$A$497,_xlpm.rep,'Rework Log'!$C$2:$C$497,"DPO*"),_xlpm.fixdate,_xlfn.MAXIFS('Rework Log'!$J$2:$J$497,'Rework Log'!$A$2:$A$497,_xlpm.rep,'Rework Log'!$C$2:$C$497,"DPO*",'Rework Log'!$B$2:$B$497,_xlpm.sent),_xlpm.expfix,_xlfn.MAXIFS('Rework Log'!$I$2:$I$497,'Rework Log'!$A$2:$A$497,_xlpm.rep,'Rework Log'!$C$2:$C$497,"DPO*",'Rework Log'!$B$2:$B$497,_xlpm.sent),_xlpm.base,IF(_xlpm.fixdate>0,_xlpm.fixdate,_xlpm.expfix),IF(OR(_xlpm.rep="",_xlpm.sent=0,_xlpm.base=0),"",WORKDAY(_xlpm.base,7)))}
A3: Leaks | B3: RPT_04_Count of Active Leaks On Hand | C3: RELEASED IN PROD | D3: {=IF(AND(C3="Ready for Release in Prod",LEFT($AJ3,3)<>"Yes"),IF(AG3<>"","Delivered","On track"),IF($B3="","",IF(LEFT($AJ3,3)="Yes","Blocked - "&MID($AJ3,7,100)&IF(SUMPRODUCT(('Rework Log'!$A$2:$A$497=$B3)*('Rework Log'!$G$2:$G$497<>"Yes")*('Rework Log'!$G$2:$G$497<>"Did not pass re-test"))=0,"",IF(SUMPRODUCT(MAX((('Rework Log'!$A$2:$A$497=$B3)*('Rework Log'!$G$2:$G$497<>"Yes")*('Rework Log'!$G$2:$G$497<>"Did not pass re-test"))*'Rework Log'!$I$2:$I$497))=0," - unclaimed"," - promised "&TEXT(SUMPRODUCT(MAX((('Rework Log'!$A$2:$A$497=$B3)*('Rework Log'!$G$2:$G$497<>"Yes")*('Rework Log'!$G$2:$G$497<>"Did not pass re-test"))*'Rework Log'!$I$2:$I$497)),"m/d"))),IF(C3="NOT STARTED",IF(H3="","No plan date set",IF(H3<TODAY(),"Review - planned start passed","On track")),IF(C3="DB Dev",_xlfn.LET(_xlpm.sent,_xlfn.MAXIFS('Rework Log'!$B$2:$B$497,'Rework Log'!$A$2:$A$497,$B3,'Rework Log'!$D$2:$D$497,"DB Dev"),_xlpm.expfix,_xlfn.MAXIFS('Rework Log'!$I$2:$I$497,'Rework Log'!$A$2:$A$497,$B3,'Rework Log'!$D$2:$D$497,"DB Dev",'Rework Log'!$B$2:$B$497,_xlpm.sent),_xlpm.tgt,IF(_xlpm.expfix>0,_xlpm.expfix,IF(L3<>"",L3,K3)),_xlpm.act,IF(AND(M3<>"",M3>=_xlpm.sent),M3,""),IF(_xlpm.tgt="","No target set",IF(AND(_xlpm.tgt<TODAY(),_xlpm.act=""),"Overdue","On track"))),IF(C3="PBI Dev",_xlfn.LET(_xlpm.sent,_xlfn.MAXIFS('Rework Log'!$B$2:$B$497,'Rework Log'!$A$2:$A$497,$B3,'Rework Log'!$D$2:$D$497,"PBI Dev"),_xlpm.expfix,_xlfn.MAXIFS('Rework Log'!$I$2:$I$497,'Rework Log'!$A$2:$A$497,$B3,'Rework Log'!$D$2:$D$497,"PBI Dev",'Rework Log'!$B$2:$B$497,_xlpm.sent),_xlpm.tgt,IF(_xlpm.expfix>0,_xlpm.expfix,IF(R3<>"",R3,Q3)),_xlpm.act,IF(AND(S3<>"",S3>=_xlpm.sent),S3,""),IF(_xlpm.tgt="","No target set",IF(AND(_xlpm.tgt<TODAY(),_xlpm.act=""),"Overdue","On track"))),IF(C3="QA",_xlfn.LET(_xlpm.tgt,IF(AM3<>"",AM3,IF(W3<>"",W3,V3)),_xlpm.sent,_xlfn.MAXIFS('Rework Log'!$B$2:$B$497,'Rework Log'!$A$2:$A$497,$B3,'Rework Log'!$C$2:$C$497,"QA"),_xlpm.act,IF(AND(Y3<>"",Y3>=_xlpm.sent),Y3,""),IF(_xlpm.tgt="","No target set",IF(AND(_xlpm.tgt<TODAY(),_xlpm.act=""),"Overdue","On track"))),IF(C3="DPO Approval",_xlfn.LET(_xlpm.tgt,IF(AN3<>"",AN3,IF(AB3<>"",AB3,AA3)),_xlpm.sent,_xlfn.MAXIFS('Rework Log'!$B$2:$B$497,'Rework Log'!$A$2:$A$497,$B3,'Rework Log'!$C$2:$C$497,"DPO*"),_xlpm.act,IF(AND(AC3<>"",AC3>=_xlpm.sent),AC3,""),IF(_xlpm.tgt="","No target set",IF(AND(_xlpm.tgt<TODAY(),_xlpm.act=""),"Overdue","On track"))),IF(C3="RELEASED IN PROD","Delivered","")))))))))} -> Delivered | E3: 2 | H3: 46142 | I3: April | J3: Fetwi | K3: 46122 | M3: 46115 | N3: Curated | P3: Sarath | Q3: 46129 | S3: 46114 | U3: Preety | V3: 46136 | Y3: 46122 | AA3: 46140 | AD3: Kelvin Hu | AE3: compliance | AF3: Yes | AG3: 46122 | AH3: https://app.powerbi.com/groups/me/apps/eedba83d-be9a-45f9-9504-7bfa41e6051a/reports/c0b3f0ae-dedd-485b-8bbc-aa0e5f3fd077/24a66431d0637282f4b7?experience=power-bi | AI3: https://app.powerbi.com/groups/me/apps/2c7180b1-0d3d-45be-979e-f7dc86b3557d/reports/5ffd546f-ad77-4a7f-8e6d-94dc08bef796/24a66431d0637282f4b7?ctid=f98a6a53-25f3-4212-901c-c7787fcd3495&experience=power-bi | AJ3: No | AK3: {=IF($B3="","",_xlfn.LET(_xlpm.nm,$B3,_xlpm.st,$C3,_xlpm.ou,SUMPRODUCT(('Rework Log'!$A$2:$A$497=_xlpm.nm)*('Rework Log'!$G$2:$G$497<>"Yes")*('Rework Log'!$G$2:$G$497<>"Did not pass re-test")*('Rework Log'!$J$2:$J$497="")),_xlpm.ob,SUMPRODUCT(('Rework Log'!$A$2:$A$497=_xlpm.nm)*('Rework Log'!$G$2:$G$497<>"Yes")*('Rework Log'!$G$2:$G$497<>"Did not pass re-test")),_xlpm.oto,IF(SUMPRODUCT(('Rework Log'!$A$2:$A$497=_xlpm.nm)*('Rework Log'!$G$2:$G$497<>"Yes")*('Rework Log'!$G$2:$G$497<>"Did not pass re-test")*('Rework Log'!$J$2:$J$497=""))=0,"",INDEX('Rework Log'!$D$2:$D$497,MATCH(1,('Rework Log'!$A$2:$A$497=_xlpm.nm)*('Rework Log'!$G$2:$G$497<>"Yes")*('Rework Log'!$G$2:$G$497<>"Did not pass re-test")*('Rework Log'!$J$2:$J$497=""),0))),_xlpm.sent,_xlfn.MAXIFS('Rework Log'!$B$2:$B$497,'Rework Log'!$A$2:$A$497,_xlpm.nm),_xlpm.act,_xlfn.IFS(_xlpm.st="NOT STARTED",$M3,_xlpm.st="DB Dev",$M3,_xlpm.st="PBI Dev",$S3,_xlpm.st="QA",$Y3,_xlpm.st="DPO Approval",$AC3,_xlpm.st="Ready for Release in Prod",$AG3,TRUE,""),_xlpm.nxt,_xlfn.IFS(_xlpm.st="NOT STARTED","PBI Dev",_xlpm.st="DB Dev","PBI Dev",_xlpm.st="PBI Dev","QA",_xlpm.st="QA","DPO Approval",_xlpm.st="DPO Approval","Ready for Release in Prod",_xlpm.st="Ready for Release in Prod","RELEASED IN PROD",TRUE,""),IF(AND(_xlpm.ou>0,_xlpm.st<>_xlpm.oto),"Move status back to "&_xlpm.oto,IF(AND(_xlpm.ob=0,LEFT($AJ3,3)="Yes"),"Blocked - log it on Rework Log",IF(AND(_xlpm.ob>0,LEFT($AJ3,3)<>"Yes"),"Open rework row - mark Blocked or close it",IF(AND(_xlpm.ob=0,_xlpm.act<>"",_xlpm.act>=_xlpm.sent,_xlpm.nxt<>""),"Move status to "&_xlpm.nxt,IF(COUNTIF($B$2:$B$528,$B3)>1,"Duplicate name - check row",IF(COUNTIF('Rework Log'!$A$2:$A$497,$B3)>0,"",IF(AND($V3<>"",$K3<>"",$V3<$K3),"QA target is before DB Dev target",IF(AND($V3<>"",$Q3<>"",$V3<$Q3),"QA target is before PBI Dev target",IF(AND($AA3<>"",$V3<>"",$AA3<$V3),"DPO Approval target is before QA target",IF(AND($AG3<>"",$AA3<>"",$AG3<$AA3),"Confirmed Deployed date is before DPO Approval target",""))))))))))))} -> Confirmed Deployed date is before DPO Approval target | AL3: [Historical, April 2026]: QA found an issue - date calendar dimension broken. Fetwi assigned to fix. | AM3: {=_xlfn.LET(_xlpm.rep,$B3,_xlpm.sent,_xlfn.MAXIFS('Rework Log'!$B$2:$B$497,'Rework Log'!$A$2:$A$497,_xlpm.rep,'Rework Log'!$C$2:$C$497,"QA"),_xlpm.fixdate,_xlfn.MAXIFS('Rework Log'!$J$2:$J$497,'Rework Log'!$A$2:$A$497,_xlpm.rep,'Rework Log'!$C$2:$C$497,"QA",'Rework Log'!$B$2:$B$497,_xlpm.sent),_xlpm.expfix,_xlfn.MAXIFS('Rework Log'!$I$2:$I$497,'Rework Log'!$A$2:$A$497,_xlpm.rep,'Rework Log'!$C$2:$C$497,"QA",'Rework Log'!$B$2:$B$497,_xlpm.sent),_xlpm.base,IF(_xlpm.fixdate>0,_xlpm.fixdate,_xlpm.expfix),IF(OR(_xlpm.rep="",_xlpm.sent=0,_xlpm.base=0),"",WORKDAY(_xlpm.base,3)))} | AN3: {=_xlfn.LET(_xlpm.rep,$B3,_xlpm.sent,_xlfn.MAXIFS('Rework Log'!$B$2:$B$497,'Rework Log'!$A$2:$A$497,_xlpm.rep,'Rework Log'!$C$2:$C$497,"DPO*"),_xlpm.fixdate,_xlfn.MAXIFS('Rework Log'!$J$2:$J$497,'Rework Log'!$A$2:$A$497,_xlpm.rep,'Rework Log'!$C$2:$C$497,"DPO*",'Rework Log'!$B$2:$B$497,_xlpm.sent),_xlpm.expfix,_xlfn.MAXIFS('Rework Log'!$I$2:$I$497,'Rework Log'!$A$2:$A$497,_xlpm.rep,'Rework Log'!$C$2:$C$497,"DPO*",'Rework Log'!$B$2:$B$497,_xlpm.sent),_xlpm.base,IF(_xlpm.fixdate>0,_xlpm.fixdate,_xlpm.expfix),IF(OR(_xlpm.rep="",_xlpm.sent=0,_xlpm.base=0),"",WORKDAY(_xlpm.base,7)))}
A4: Leaks | B4: RPT_04_Leak Days Remaining | C4: RELEASED IN PROD | D4: {=IF(AND(C4="Ready for Release in Prod",LEFT($AJ4,3)<>"Yes"),IF(AG4<>"","Delivered","On track"),IF($B4="","",IF(LEFT($AJ4,3)="Yes","Blocked - "&MID($AJ4,7,100)&IF(SUMPRODUCT(('Rework Log'!$A$2:$A$497=$B4)*('Rework Log'!$G$2:$G$497<>"Yes")*('Rework Log'!$G$2:$G$497<>"Did not pass re-test"))=0,"",IF(SUMPRODUCT(MAX((('Rework Log'!$A$2:$A$497=$B4)*('Rework Log'!$G$2:$G$497<>"Yes")*('Rework Log'!$G$2:$G$497<>"Did not pass re-test"))*'Rework Log'!$I$2:$I$497))=0," - unclaimed"," - promised "&TEXT(SUMPRODUCT(MAX((('Rework Log'!$A$2:$A$497=$B4)*('Rework Log'!$G$2:$G$497<>"Yes")*('Rework Log'!$G$2:$G$497<>"Did not pass re-test"))*'Rework Log'!$I$2:$I$497)),"m/d"))),IF(C4="NOT STARTED",IF(H4="","No plan date set",IF(H4<TODAY(),"Review - planned start passed","On track")),IF(C4="DB Dev",_xlfn.LET(_xlpm.sent,_xlfn.MAXIFS('Rework Log'!$B$2:$B$497,'Rework Log'!$A$2:$A$497,$B4,'Rework Log'!$D$2:$D$497,"DB Dev"),_xlpm.expfix,_xlfn.MAXIFS('Rework Log'!$I$2:$I$497,'Rework Log'!$A$2:$A$497,$B4,'Rework Log'!$D$2:$D$497,"DB Dev",'Rework Log'!$B$2:$B$497,_xlpm.sent),_xlpm.tgt,IF(_xlpm.expfix>0,_xlpm.expfix,IF(L4<>"",L4,K4)),_xlpm.act,IF(AND(M4<>"",M4>=_xlpm.sent),M4,""),IF(_xlpm.tgt="","No target set",IF(AND(_xlpm.tgt<TODAY(),_xlpm.act=""),"Overdue","On track"))),IF(C4="PBI Dev",_xlfn.LET(_xlpm.sent,_xlfn.MAXIFS('Rework Log'!$B$2:$B$497,'Rework Log'!$A$2:$A$497,$B4,'Rework Log'!$D$2:$D$497,"PBI Dev"),_xlpm.expfix,_xlfn.MAXIFS('Rework Log'!$I$2:$I$497,'Rework Log'!$A$2:$A$497,$B4,'Rework Log'!$D$2:$D$497,"PBI Dev",'Rework Log'!$B$2:$B$497,_xlpm.sent),_xlpm.tgt,IF(_xlpm.expfix>0,_xlpm.expfix,IF(R4<>"",R4,Q4)),_xlpm.act,IF(AND(S4<>"",S4>=_xlpm.sent),S4,""),IF(_xlpm.tgt="","No target set",IF(AND(_xlpm.tgt<TODAY(),_xlpm.act=""),"Overdue","On track"))),IF(C4="QA",_xlfn.LET(_xlpm.tgt,IF(AM4<>"",AM4,IF(W4<>"",W4,V4)),_xlpm.sent,_xlfn.MAXIFS('Rework Log'!$B$2:$B$497,'Rework Log'!$A$2:$A$497,$B4,'Rework Log'!$C$2:$C$497,"QA"),_xlpm.act,IF(AND(Y4<>"",Y4>=_xlpm.sent),Y4,""),IF(_xlpm.tgt="","No target set",IF(AND(_xlpm.tgt<TODAY(),_xlpm.act=""),"Overdue","On track"))),IF(C4="DPO Approval",_xlfn.LET(_xlpm.tgt,IF(AN4<>"",AN4,IF(AB4<>"",AB4,AA4)),_xlpm.sent,_xlfn.MAXIFS('Rework Log'!$B$2:$B$497,'Rework Log'!$A$2:$A$497,$B4,'Rework Log'!$C$2:$C$497,"DPO*"),_xlpm.act,IF(AND(AC4<>"",AC4>=_xlpm.sent),AC4,""),IF(_xlpm.tgt="","No target set",IF(AND(_xlpm.tgt<TODAY(),_xlpm.act=""),"Overdue","On track"))),IF(C4="RELEASED IN PROD","Delivered","")))))))))} -> Delivered | E4: 3 | H4: 46142 | I4: April | J4: Siva | K4: 46122 | M4: 46115 | N4: Curated | P4: Navya | Q4: 46129 | S4: 46126 | U4: Preety | V4: 46136 | Y4: 46122 | AA4: 46140 | AD4: Kelvin Hu | AE4: compliance | AF4: Yes | AG4: 46122 | AH4: https://app.powerbi.com/groups/me/apps/eedba83d-be9a-45f9-9504-7bfa41e6051a/reports/8b9ae445-3a30-4ae6-a3fa-7a6d8e7ef349/d97da6159d0c87677529?experience=power-bi | AI4: https://app.powerbi.com/groups/me/apps/2c7180b1-0d3d-45be-979e-f7dc86b3557d/reports/848ce65a-4e47-422b-aae5-7ea9e7d68a5f/d97da6159d0c87677529?ctid=f98a6a53-25f3-4212-901c-c7787fcd3495&experience=power-bi | AJ4: No | AK4: {=IF($B4="","",_xlfn.LET(_xlpm.nm,$B4,_xlpm.st,$C4,_xlpm.ou,SUMPRODUCT(('Rework Log'!$A$2:$A$497=_xlpm.nm)*('Rework Log'!$G$2:$G$497<>"Yes")*('Rework Log'!$G$2:$G$497<>"Did not pass re-test")*('Rework Log'!$J$2:$J$497="")),_xlpm.ob,SUMPRODUCT(('Rework Log'!$A$2:$A$497=_xlpm.nm)*('Rework Log'!$G$2:$G$497<>"Yes")*('Rework Log'!$G$2:$G$497<>"Did not pass re-test")),_xlpm.oto,IF(SUMPRODUCT(('Rework Log'!$A$2:$A$497=_xlpm.nm)*('Rework Log'!$G$2:$G$497<>"Yes")*('Rework Log'!$G$2:$G$497<>"Did not pass re-test")*('Rework Log'!$J$2:$J$497=""))=0,"",INDEX('Rework Log'!$D$2:$D$497,MATCH(1,('Rework Log'!$A$2:$A$497=_xlpm.nm)*('Rework Log'!$G$2:$G$497<>"Yes")*('Rework Log'!$G$2:$G$497<>"Did not pass re-test")*('Rework Log'!$J$2:$J$497=""),0))),_xlpm.sent,_xlfn.MAXIFS('Rework Log'!$B$2:$B$497,'Rework Log'!$A$2:$A$497,_xlpm.nm),_xlpm.act,_xlfn.IFS(_xlpm.st="NOT STARTED",$M4,_xlpm.st="DB Dev",$M4,_xlpm.st="PBI Dev",$S4,_xlpm.st="QA",$Y4,_xlpm.st="DPO Approval",$AC4,_xlpm.st="Ready for Release in Prod",$AG4,TRUE,""),_xlpm.nxt,_xlfn.IFS(_xlpm.st="NOT STARTED","PBI Dev",_xlpm.st="DB Dev","PBI Dev",_xlpm.st="PBI Dev","QA",_xlpm.st="QA","DPO Approval",_xlpm.st="DPO Approval","Ready for Release in Prod",_xlpm.st="Ready for Release in Prod","RELEASED IN PROD",TRUE,""),IF(AND(_xlpm.ou>0,_xlpm.st<>_xlpm.oto),"Move status back to "&_xlpm.oto,IF(AND(_xlpm.ob=0,LEFT($AJ4,3)="Yes"),"Blocked - log it on Rework Log",IF(AND(_xlpm.ob>0,LEFT($AJ4,3)<>"Yes"),"Open rework row - mark Blocked or close it",IF(AND(_xlpm.ob=0,_xlpm.act<>"",_xlpm.act>=_xlpm.sent,_xlpm.nxt<>""),"Move status to "&_xlpm.nxt,IF(COUNTIF($B$2:$B$528,$B4)>1,"Duplicate name - check row",IF(COUNTIF('Rework Log'!$A$2:$A$497,$B4)>0,"",IF(AND($V4<>"",$K4<>"",$V4<$K4),"QA target is before DB Dev target",IF(AND($V4<>"",$Q4<>"",$V4<$Q4),"QA target is before PBI Dev target",IF(AND($AA4<>"",$V4<>"",$AA4<$V4),"DPO Approval target is before QA target",IF(AND($AG4<>"",$AA4<>"",$AG4<$AA4),"Confirmed Deployed date is before DPO Approval target",""))))))))))))} -> Confirmed Deployed date is before DPO Approval target | AL4: 16/04 - Testing completed in QA and created defect https://jira.prod.nationalgrid.com/browse/GDMP-2186; ETA -04/24 | AM4: {=_xlfn.LET(_xlpm.rep,$B4,_xlpm.sent,_xlfn.MAXIFS('Rework Log'!$B$2:$B$497,'Rework Log'!$A$2:$A$497,_xlpm.rep,'Rework Log'!$C$2:$C$497,"QA"),_xlpm.fixdate,_xlfn.MAXIFS('Rework Log'!$J$2:$J$497,'Rework Log'!$A$2:$A$497,_xlpm.rep,'Rework Log'!$C$2:$C$497,"QA",'Rework Log'!$B$2:$B$497,_xlpm.sent),_xlpm.expfix,_xlfn.MAXIFS('Rework Log'!$I$2:$I$497,'Rework Log'!$A$2:$A$497,_xlpm.rep,'Rework Log'!$C$2:$C$497,"QA",'Rework Log'!$B$2:$B$497,_xlpm.sent),_xlpm.base,IF(_xlpm.fixdate>0,_xlpm.fixdate,_xlpm.expfix),IF(OR(_xlpm.rep="",_xlpm.sent=0,_xlpm.base=0),"",WORKDAY(_xlpm.base,3)))} | AN4: {=_xlfn.LET(_xlpm.rep,$B4,_xlpm.sent,_xlfn.MAXIFS('Rework Log'!$B$2:$B$497,'Rework Log'!$A$2:$A$497,_xlpm.rep,'Rework Log'!$C$2:$C$497,"DPO*"),_xlpm.fixdate,_xlfn.MAXIFS('Rework Log'!$J$2:$J$497,'Rework Log'!$A$2:$A$497,_xlpm.rep,'Rework Log'!$C$2:$C$497,"DPO*",'Rework Log'!$B$2:$B$497,_xlpm.sent),_xlpm.expfix,_xlfn.MAXIFS('Rework Log'!$I$2:$I$497,'Rework Log'!$A$2:$A$497,_xlpm.rep,'Rework Log'!$C$2:$C$497,"DPO*",'Rework Log'!$B$2:$B$497,_xlpm.sent),_xlpm.base,IF(_xlpm.fixdate>0,_xlpm.fixdate,_xlpm.expfix),IF(OR(_xlpm.rep="",_xlpm.sent=0,_xlpm.base=0),"",WORKDAY(_xlpm.base,7)))}
A5: Leaks | B5: RPT_04_Cleared Leaks | C5: RELEASED IN PROD | D5: {=IF(AND(C5="Ready for Release in Prod",LEFT($AJ5,3)<>"Yes"),IF(AG5<>"","Delivered","On track"),IF($B5="","",IF(LEFT($AJ5,3)="Yes","Blocked - "&MID($AJ5,7,100)&IF(SUMPRODUCT(('Rework Log'!$A$2:$A$497=$B5)*('Rework Log'!$G$2:$G$497<>"Yes")*('Rework Log'!$G$2:$G$497<>"Did not pass re-test"))=0,"",IF(SUMPRODUCT(MAX((('Rework Log'!$A$2:$A$497=$B5)*('Rework Log'!$G$2:$G$497<>"Yes")*('Rework Log'!$G$2:$G$497<>"Did not pass re-test"))*'Rework Log'!$I$2:$I$497))=0," - unclaimed"," - promised "&TEXT(SUMPRODUCT(MAX((('Rework Log'!$A$2:$A$497=$B5)*('Rework Log'!$G$2:$G$497<>"Yes")*('Rework Log'!$G$2:$G$497<>"Did not pass re-test"))*'Rework Log'!$I$2:$I$497)),"m/d"))),IF(C5="NOT STARTED",IF(H5="","No plan date set",IF(H5<TODAY(),"Review - planned start passed","On track")),IF(C5="DB Dev",_xlfn.LET(_xlpm.sent,_xlfn.MAXIFS('Rework Log'!$B$2:$B$497,'Rework Log'!$A$2:$A$497,$B5,'Rework Log'!$D$2:$D$497,"DB Dev"),_xlpm.expfix,_xlfn.MAXIFS('Rework Log'!$I$2:$I$497,'Rework Log'!$A$2:$A$497,$B5,'Rework Log'!$D$2:$D$497,"DB Dev",'Rework Log'!$B$2:$B$497,_xlpm.sent),_xlpm.tgt,IF(_xlpm.expfix>0,_xlpm.expfix,IF(L5<>"",L5,K5)),_xlpm.act,IF(AND(M5<>"",M5>=_xlpm.sent),M5,""),IF(_xlpm.tgt="","No target set",IF(AND(_xlpm.tgt<TODAY(),_xlpm.act=""),"Overdue","On track"))),IF(C5="PBI Dev",_xlfn.LET(_xlpm.sent,_xlfn.MAXIFS('Rework Log'!$B$2:$B$497,'Rework Log'!$A$2:$A$497,$B5,'Rework Log'!$D$2:$D$497,"PBI Dev"),_xlpm.expfix,_xlfn.MAXIFS('Rework Log'!$I$2:$I$497,'Rework Log'!$A$2:$A$497,$B5,'Rework Log'!$D$2:$D$497,"PBI Dev",'Rework Log'!$B$2:$B$497,_xlpm.sent),_xlpm.tgt,IF(_xlpm.expfix>0,_xlpm.expfix,IF(R5<>"",R5,Q5)),_xlpm.act,IF(AND(S5<>"",S5>=_xlpm.sent),S5,""),IF(_xlpm.tgt="","No target set",IF(AND(_xlpm.tgt<TODAY(),_xlpm.act=""),"Overdue","On track"))),IF(C5="QA",_xlfn.LET(_xlpm.tgt,IF(AM5<>"",AM5,IF(W5<>"",W5,V5)),_xlpm.sent,_xlfn.MAXIFS('Rework Log'!$B$2:$B$497,'Rework Log'!$A$2:$A$497,$B5,'Rework Log'!$C$2:$C$497,"QA"),_xlpm.act,IF(AND(Y5<>"",Y5>=_xlpm.sent),Y5,""),IF(_xlpm.tgt="","No target set",IF(AND(_xlpm.tgt<TODAY(),_xlpm.act=""),"Overdue","On track"))),IF(C5="DPO Approval",_xlfn.LET(_xlpm.tgt,IF(AN5<>"",AN5,IF(AB5<>"",AB5,AA5)),_xlpm.sent,_xlfn.MAXIFS('Rework Log'!$B$2:$B$497,'Rework Log'!$A$2:$A$497,$B5,'Rework Log'!$C$2:$C$497,"DPO*"),_xlpm.act,IF(AND(AC5<>"",AC5>=_xlpm.sent),AC5,""),IF(_xlpm.tgt="","No target set",IF(AND(_xlpm.tgt<TODAY(),_xlpm.act=""),"Overdue","On track"))),IF(C5="RELEASED IN PROD","Delivered","")))))))))} -> Delivered | E5: 4 | H5: 46142 | I5: April | J5: Sree | K5: 46122 | M5: 46115 | N5: Curated | P5: Sarath | Q5: 46129 | S5: 46120 | U5: Preety | V5: 46136 | Y5: 46122 | AA5: 46140 | AD5: Kelvin Hu | AE5: compliance | AF5: Yes | AG5: 46122 | AH5: https://app.powerbi.com/groups/me/apps/eedba83d-be9a-45f9-9504-7bfa41e6051a/reports/938a9ba1-8138-440e-842a-d9a679933d8c/44bb4fce98fafb2cace2?experience=power-bi | AI5: https://app.powerbi.com/groups/me/apps/2c7180b1-0d3d-45be-979e-f7dc86b3557d/reports/677c6418-6db8-4ebf-9323-65be4cb2c960/ea184ec020032ecbdd43?ctid=f98a6a53-25f3-4212-901c-c7787fcd3495&experience=power-bi | AJ5: No | AK5: {=IF($B5="","",_xlfn.LET(_xlpm.nm,$B5,_xlpm.st,$C5,_xlpm.ou,SUMPRODUCT(('Rework Log'!$A$2:$A$497=_xlpm.nm)*('Rework Log'!$G$2:$G$497<>"Yes")*('Rework Log'!$G$2:$G$497<>"Did not pass re-test")*('Rework Log'!$J$2:$J$497="")),_xlpm.ob,SUMPRODUCT(('Rework Log'!$A$2:$A$497=_xlpm.nm)*('Rework Log'!$G$2:$G$497<>"Yes")*('Rework Log'!$G$2:$G$497<>"Did not pass re-test")),_xlpm.oto,IF(SUMPRODUCT(('Rework Log'!$A$2:$A$497=_xlpm.nm)*('Rework Log'!$G$2:$G$497<>"Yes")*('Rework Log'!$G$2:$G$497<>"Did not pass re-test")*('Rework Log'!$J$2:$J$497=""))=0,"",INDEX('Rework Log'!$D$2:$D$497,MATCH(1,('Rework Log'!$A$2:$A$497=_xlpm.nm)*('Rework Log'!$G$2:$G$497<>"Yes")*('Rework Log'!$G$2:$G$497<>"Did not pass re-test")*('Rework Log'!$J$2:$J$497=""),0))),_xlpm.sent,_xlfn.MAXIFS('Rework Log'!$B$2:$B$497,'Rework Log'!$A$2:$A$497,_xlpm.nm),_xlpm.act,_xlfn.IFS(_xlpm.st="NOT STARTED",$M5,_xlpm.st="DB Dev",$M5,_xlpm.st="PBI Dev",$S5,_xlpm.st="QA",$Y5,_xlpm.st="DPO Approval",$AC5,_xlpm.st="Ready for Release in Prod",$AG5,TRUE,""),_xlpm.nxt,_xlfn.IFS(_xlpm.st="NOT STARTED","PBI Dev",_xlpm.st="DB Dev","PBI Dev",_xlpm.st="PBI Dev","QA",_xlpm.st="QA","DPO Approval",_xlpm.st="DPO Approval","Ready for Release in Prod",_xlpm.st="Ready for Release in Prod","RELEASED IN PROD",TRUE,""),IF(AND(_xlpm.ou>0,_xlpm.st<>_xlpm.oto),"Move status back to "&_xlpm.oto,IF(AND(_xlpm.ob=0,LEFT($AJ5,3)="Yes"),"Blocked - log it on Rework Log",IF(AND(_xlpm.ob>0,LEFT($AJ5,3)<>"Yes"),"Open rework row - mark Blocked or close it",IF(AND(_xlpm.ob=0,_xlpm.act<>"",_xlpm.act>=_xlpm.sent,_xlpm.nxt<>""),"Move status to "&_xlpm.nxt,IF(COUNTIF($B$2:$B$528,$B5)>1,"Duplicate name - check row",IF(COUNTIF('Rework Log'!$A$2:$A$497,$B5)>0,"",IF(AND($V5<>"",$K5<>"",$V5<$K5),"QA target is before DB Dev target",IF(AND($V5<>"",$Q5<>"",$V5<$Q5),"QA target is before PBI Dev target",IF(AND($AA5<>"",$V5<>"",$AA5<$V5),"DPO Approval target is before QA target",IF(AND($AG5<>"",$AA5<>"",$AG5<$AA5),"Confirmed Deployed date is before DPO Approval target",""))))))))))))} -> Confirmed Deployed date is before DPO Approval target | AL5: [Historical, April 2026]: L_GRO_NUMBER columns had an issue in QA - DB team assigned to fix. | AM5: {=_xlfn.LET(_xlpm.rep,$B5,_xlpm.sent,_xlfn.MAXIFS('Rework Log'!$B$2:$B$497,'Rework Log'!$A$2:$A$497,_xlpm.rep,'Rework Log'!$C$2:$C$497,"QA"),_xlpm.fixdate,_xlfn.MAXIFS('Rework Log'!$J$2:$J$497,'Rework Log'!$A$2:$A$497,_xlpm.rep,'Rework Log'!$C$2:$C$497,"QA",'Rework Log'!$B$2:$B$497,_xlpm.sent),_xlpm.expfix,_xlfn.MAXIFS('Rework Log'!$I$2:$I$497,'Rework Log'!$A$2:$A$497,_xlpm.rep,'Rework Log'!$C$2:$C$497,"QA",'Rework Log'!$B$2:$B$497,_xlpm.sent),_xlpm.base,IF(_xlpm.fixdate>0,_xlpm.fixdate,_xlpm.expfix),IF(OR(_xlpm.rep="",_xlpm.sent=0,_xlpm.base=0),"",WORKDAY(_xlpm.base,3)))} | AN5: {=_xlfn.LET(_xlpm.rep,$B5,_xlpm.sent,_xlfn.MAXIFS('Rework Log'!$B$2:$B$497,'Rework Log'!$A$2:$A$497,_xlpm.rep,'Rework Log'!$C$2:$C$497,"DPO*"),_xlpm.fixdate,_xlfn.MAXIFS('Rework Log'!$J$2:$J$497,'Rework Log'!$A$2:$A$497,_xlpm.rep,'Rework Log'!$C$2:$C$497,"DPO*",'Rework Log'!$B$2:$B$497,_xlpm.sent),_xlpm.expfix,_xlfn.MAXIFS('Rework Log'!$I$2:$I$497,'Rework Log'!$A$2:$A$497,_xlpm.rep,'Rework Log'!$C$2:$C$497,"DPO*",'Rework Log'!$B$2:$B$497,_xlpm.sent),_xlpm.base,IF(_xlpm.fixdate>0,_xlpm.fixdate,_xlpm.expfix),IF(OR(_xlpm.rep="",_xlpm.sent=0,_xlpm.base=0),"",WORKDAY(_xlpm.base,7)))}
A6: Leaks | B6: RPT_04_Leaks Repaired Detail | C6: RELEASED IN PROD | D6: {=IF(AND(C6="Ready for Release in Prod",LEFT($AJ6,3)<>"Yes"),IF(AG6<>"","Delivered","On track"),IF($B6="","",IF(LEFT($AJ6,3)="Yes","Blocked - "&MID($AJ6,7,100)&IF(SUMPRODUCT(('Rework Log'!$A$2:$A$497=$B6)*('Rework Log'!$G$2:$G$497<>"Yes")*('Rework Log'!$G$2:$G$497<>"Did not pass re-test"))=0,"",IF(SUMPRODUCT(MAX((('Rework Log'!$A$2:$A$497=$B6)*('Rework Log'!$G$2:$G$497<>"Yes")*('Rework Log'!$G$2:$G$497<>"Did not pass re-test"))*'Rework Log'!$I$2:$I$497))=0," - unclaimed"," - promised "&TEXT(SUMPRODUCT(MAX((('Rework Log'!$A$2:$A$497=$B6)*('Rework Log'!$G$2:$G$497<>"Yes")*('Rework Log'!$G$2:$G$497<>"Did not pass re-test"))*'Rework Log'!$I$2:$I$497)),"m/d"))),IF(C6="NOT STARTED",IF(H6="","No plan date set",IF(H6<TODAY(),"Review - planned start passed","On track")),IF(C6="DB Dev",_xlfn.LET(_xlpm.sent,_xlfn.MAXIFS('Rework Log'!$B$2:$B$497,'Rework Log'!$A$2:$A$497,$B6,'Rework Log'!$D$2:$D$497,"DB Dev"),_xlpm.expfix,_xlfn.MAXIFS('Rework Log'!$I$2:$I$497,'Rework Log'!$A$2:$A$497,$B6,'Rework Log'!$D$2:$D$497,"DB Dev",'Rework Log'!$B$2:$B$497,_xlpm.sent),_xlpm.tgt,IF(_xlpm.expfix>0,_xlpm.expfix,IF(L6<>"",L6,K6)),_xlpm.act,IF(AND(M6<>"",M6>=_xlpm.sent),M6,""),IF(_xlpm.tgt="","No target set",IF(AND(_xlpm.tgt<TODAY(),_xlpm.act=""),"Overdue","On track"))),IF(C6="PBI Dev",_xlfn.LET(_xlpm.sent,_xlfn.MAXIFS('Rework Log'!$B$2:$B$497,'Rework Log'!$A$2:$A$497,$B6,'Rework Log'!$D$2:$D$497,"PBI Dev"),_xlpm.expfix,_xlfn.MAXIFS('Rework Log'!$I$2:$I$497,'Rework Log'!$A$2:$A$497,$B6,'Rework Log'!$D$2:$D$497,"PBI Dev",'Rework Log'!$B$2:$B$497,_xlpm.sent),_xlpm.tgt,IF(_xlpm.expfix>0,_xlpm.expfix,IF(R6<>"",R6,Q6)),_xlpm.act,IF(AND(S6<>"",S6>=_xlpm.sent),S6,""),IF(_xlpm.tgt="","No target set",IF(AND(_xlpm.tgt<TODAY(),_xlpm.act=""),"Overdue","On track"))),IF(C6="QA",_xlfn.LET(_xlpm.tgt,IF(AM6<>"",AM6,IF(W6<>"",W6,V6)),_xlpm.sent,_xlfn.MAXIFS('Rework Log'!$B$2:$B$497,'Rework Log'!$A$2:$A$497,$B6,'Rework Log'!$C$2:$C$497,"QA"),_xlpm.act,IF(AND(Y6<>"",Y6>=_xlpm.sent),Y6,""),IF(_xlpm.tgt="","No target set",IF(AND(_xlpm.tgt<TODAY(),_xlpm.act=""),"Overdue","On track"))),IF(C6="DPO Approval",_xlfn.LET(_xlpm.tgt,IF(AN6<>"",AN6,IF(AB6<>"",AB6,AA6)),_xlpm.sent,_xlfn.MAXIFS('Rework Log'!$B$2:$B$497,'Rework Log'!$A$2:$A$497,$B6,'Rework Log'!$C$2:$C$497,"DPO*"),_xlpm.act,IF(AND(AC6<>"",AC6>=_xlpm.sent),AC6,""),IF(_xlpm.tgt="","No target set",IF(AND(_xlpm.tgt<TODAY(),_xlpm.act=""),"Overdue","On track"))),IF(C6="RELEASED IN PROD","Delivered","")))))))))} -> Delivered | E6: 5 | H6: 46142 | I6: April | N6: Curated | AD6: Kelvin Hu | AE6: compliance | AF6: Yes | AG6: 46142 | AK6: {=IF($B6="","",_xlfn.LET(_xlpm.nm,$B6,_xlpm.st,$C6,_xlpm.ou,SUMPRODUCT(('Rework Log'!$A$2:$A$497=_xlpm.nm)*('Rework Log'!$G$2:$G$497<>"Yes")*('Rework Log'!$G$2:$G$497<>"Did not pass re-test")*('Rework Log'!$J$2:$J$497="")),_xlpm.ob,SUMPRODUCT(('Rework Log'!$A$2:$A$497=_xlpm.nm)*('Rework Log'!$G$2:$G$497<>"Yes")*('Rework Log'!$G$2:$G$497<>"Did not pass re-test")),_xlpm.oto,IF(SUMPRODUCT(('Rework Log'!$A$2:$A$497=_xlpm.nm)*('Rework Log'!$G$2:$G$497<>"Yes")*('Rework Log'!$G$2:$G$497<>"Did not pass re-test")*('Rework Log'!$J$2:$J$497=""))=0,"",INDEX('Rework Log'!$D$2:$D$497,MATCH(1,('Rework Log'!$A$2:$A$497=_xlpm.nm)*('Rework Log'!$G$2:$G$497<>"Yes")*('Rework Log'!$G$2:$G$497<>"Did not pass re-test")*('Rework Log'!$J$2:$J$497=""),0))),_xlpm.sent,_xlfn.MAXIFS('Rework Log'!$B$2:$B$497,'Rework Log'!$A$2:$A$497,_xlpm.nm),_xlpm.act,_xlfn.IFS(_xlpm.st="NOT STARTED",$M6,_xlpm.st="DB Dev",$M6,_xlpm.st="PBI Dev",$S6,_xlpm.st="QA",$Y6,_xlpm.st="DPO Approval",$AC6,_xlpm.st="Ready for Release in Prod",$AG6,TRUE,""),_xlpm.nxt,_xlfn.IFS(_xlpm.st="NOT STARTED","PBI Dev",_xlpm.st="DB Dev","PBI Dev",_xlpm.st="PBI Dev","QA",_xlpm.st="QA","DPO Approval",_xlpm.st="DPO Approval","Ready for Release in Prod",_xlpm.st="Ready for Release in Prod","RELEASED IN PROD",TRUE,""),IF(AND(_xlpm.ou>0,_xlpm.st<>_xlpm.oto),"Move status back to "&_xlpm.oto,IF(AND(_xlpm.ob=0,LEFT($AJ6,3)="Yes"),"Blocked - log it on Rework Log",IF(AND(_xlpm.ob>0,LEFT($AJ6,3)<>"Yes"),"Open rework row - mark Blocked or close it",IF(AND(_xlpm.ob=0,_xlpm.act<>"",_xlpm.act>=_xlpm.sent,_xlpm.nxt<>""),"Move status to "&_xlpm.nxt,IF(COUNTIF($B$2:$B$528,$B6)>1,"Duplicate name - check row",IF(COUNTIF('Rework Log'!$A$2:$A$497,$B6)>0,"",IF(AND($V6<>"",$K6<>"",$V6<$K6),"QA target is before DB Dev target",IF(AND($V6<>"",$Q6<>"",$V6<$Q6),"QA target is before PBI Dev target",IF(AND($AA6<>"",$V6<>"",$AA6<$V6),"DPO Approval target is before QA target",IF(AND($AG6<>"",$AA6<>"",$AG6<$AA6),"Confirmed Deployed date is before DPO Approval target",""))))))))))))} | AM6: {=_xlfn.LET(_xlpm.rep,$B6,_xlpm.sent,_xlfn.MAXIFS('Rework Log'!$B$2:$B$497,'Rework Log'!$A$2:$A$497,_xlpm.rep,'Rework Log'!$C$2:$C$497,"QA"),_xlpm.fixdate,_xlfn.MAXIFS('Rework Log'!$J$2:$J$497,'Rework Log'!$A$2:$A$497,_xlpm.rep,'Rework Log'!$C$2:$C$497,"QA",'Rework Log'!$B$2:$B$497,_xlpm.sent),_xlpm.expfix,_xlfn.MAXIFS('Rework Log'!$I$2:$I$497,'Rework Log'!$A$2:$A$497,_xlpm.rep,'Rework Log'!$C$2:$C$497,"QA",'Rework Log'!$B$2:$B$497,_xlpm.sent),_xlpm.base,IF(_xlpm.fixdate>0,_xlpm.fixdate,_xlpm.expfix),IF(OR(_xlpm.rep="",_xlpm.sent=0,_xlpm.base=0),"",WORKDAY(_xlpm.base,3)))} | AN6: {=_xlfn.LET(_xlpm.rep,$B6,_xlpm.sent,_xlfn.MAXIFS('Rework Log'!$B$2:$B$497,'Rework Log'!$A$2:$A$497,_xlpm.rep,'Rework Log'!$C$2:$C$497,"DPO*"),_xlpm.fixdate,_xlfn.MAXIFS('Rework Log'!$J$2:$J$497,'Rework Log'!$A$2:$A$497,_xlpm.rep,'Rework Log'!$C$2:$C$497,"DPO*",'Rework Log'!$B$2:$B$497,_xlpm.sent),_xlpm.expfix,_xlfn.MAXIFS('Rework Log'!$I$2:$I$497,'Rework Log'!$A$2:$A$497,_xlpm.rep,'Rework Log'!$C$2:$C$497,"DPO*",'Rework Log'!$B$2:$B$497,_xlpm.sent),_xlpm.base,IF(_xlpm.fixdate>0,_xlpm.fixdate,_xlpm.expfix),IF(OR(_xlpm.rep="",_xlpm.sent=0,_xlpm.base=0),"",WORKDAY(_xlpm.base,7)))}
A7: Leaks | B7: RPT_04_Leaks Aging | C7: RELEASED IN PROD | D7: {=IF(AND(C7="Ready for Release in Prod",LEFT($AJ7,3)<>"Yes"),IF(AG7<>"","Delivered","On track"),IF($B7="","",IF(LEFT($AJ7,3)="Yes","Blocked - "&MID($AJ7,7,100)&IF(SUMPRODUCT(('Rework Log'!$A$2:$A$497=$B7)*('Rework Log'!$G$2:$G$497<>"Yes")*('Rework Log'!$G$2:$G$497<>"Did not pass re-test"))=0,"",IF(SUMPRODUCT(MAX((('Rework Log'!$A$2:$A$497=$B7)*('Rework Log'!$G$2:$G$497<>"Yes")*('Rework Log'!$G$2:$G$497<>"Did not pass re-test"))*'Rework Log'!$I$2:$I$497))=0," - unclaimed"," - promised "&TEXT(SUMPRODUCT(MAX((('Rework Log'!$A$2:$A$497=$B7)*('Rework Log'!$G$2:$G$497<>"Yes")*('Rework Log'!$G$2:$G$497<>"Did not pass re-test"))*'Rework Log'!$I$2:$I$497)),"m/d"))),IF(C7="NOT STARTED",IF(H7="","No plan date set",IF(H7<TODAY(),"Review - planned start passed","On track")),IF(C7="DB Dev",_xlfn.LET(_xlpm.sent,_xlfn.MAXIFS('Rework Log'!$B$2:$B$497,'Rework Log'!$A$2:$A$497,$B7,'Rework Log'!$D$2:$D$497,"DB Dev"),_xlpm.expfix,_xlfn.MAXIFS('Rework Log'!$I$2:$I$497,'Rework Log'!$A$2:$A$497,$B7,'Rework Log'!$D$2:$D$497,"DB Dev",'Rework Log'!$B$2:$B$497,_xlpm.sent),_xlpm.tgt,IF(_xlpm.expfix>0,_xlpm.expfix,IF(L7<>"",L7,K7)),_xlpm.act,IF(AND(M7<>"",M7>=_xlpm.sent),M7,""),IF(_xlpm.tgt="","No target set",IF(AND(_xlpm.tgt<TODAY(),_xlpm.act=""),"Overdue","On track"))),IF(C7="PBI Dev",_xlfn.LET(_xlpm.sent,_xlfn.MAXIFS('Rework Log'!$B$2:$B$497,'Rework Log'!$A$2:$A$497,$B7,'Rework Log'!$D$2:$D$497,"PBI Dev"),_xlpm.expfix,_xlfn.MAXIFS('Rework Log'!$I$2:$I$497,'Rework Log'!$A$2:$A$497,$B7,'Rework Log'!$D$2:$D$497,"PBI Dev",'Rework Log'!$B$2:$B$497,_xlpm.sent),_xlpm.tgt,IF(_xlpm.expfix>0,_xlpm.expfix,IF(R7<>"",R7,Q7)),_xlpm.act,IF(AND(S7<>"",S7>=_xlpm.sent),S7,""),IF(_xlpm.tgt="","No target set",IF(AND(_xlpm.tgt<TODAY(),_xlpm.act=""),"Overdue","On track"))),IF(C7="QA",_xlfn.LET(_xlpm.tgt,IF(AM7<>"",AM7,IF(W7<>"",W7,V7)),_xlpm.sent,_xlfn.MAXIFS('Rework Log'!$B$2:$B$497,'Rework Log'!$A$2:$A$497,$B7,'Rework Log'!$C$2:$C$497,"QA"),_xlpm.act,IF(AND(Y7<>"",Y7>=_xlpm.sent),Y7,""),IF(_xlpm.tgt="","No target set",IF(AND(_xlpm.tgt<TODAY(),_xlpm.act=""),"Overdue","On track"))),IF(C7="DPO Approval",_xlfn.LET(_xlpm.tgt,IF(AN7<>"",AN7,IF(AB7<>"",AB7,AA7)),_xlpm.sent,_xlfn.MAXIFS('Rework Log'!$B$2:$B$497,'Rework Log'!$A$2:$A$497,$B7,'Rework Log'!$C$2:$C$497,"DPO*"),_xlpm.act,IF(AND(AC7<>"",AC7>=_xlpm.sent),AC7,""),IF(_xlpm.tgt="","No target set",IF(AND(_xlpm.tgt<TODAY(),_xlpm.act=""),"Overdue","On track"))),IF(C7="RELEASED IN PROD","Delivered","")))))))))} -> Delivered | E7: 6 | H7: 46142 | I7: April | N7: Curated | AD7: Kelvin Hu | AE7: compliance | AF7: Yes | AG7: 46142 | AK7: {=IF($B7="","",_xlfn.LET(_xlpm.nm,$B7,_xlpm.st,$C7,_xlpm.ou,SUMPRODUCT(('Rework Log'!$A$2:$A$497=_xlpm.nm)*('Rework Log'!$G$2:$G$497<>"Yes")*('Rework Log'!$G$2:$G$497<>"Did not pass re-test")*('Rework Log'!$J$2:$J$497="")),_xlpm.ob,SUMPRODUCT(('Rework Log'!$A$2:$A$497=_xlpm.nm)*('Rework Log'!$G$2:$G$497<>"Yes")*('Rework Log'!$G$2:$G$497<>"Did not pass re-test")),_xlpm.oto,IF(SUMPRODUCT(('Rework Log'!$A$2:$A$497=_xlpm.nm)*('Rework Log'!$G$2:$G$497<>"Yes")*('Rework Log'!$G$2:$G$497<>"Did not pass re-test")*('Rework Log'!$J$2:$J$497=""))=0,"",INDEX('Rework Log'!$D$2:$D$497,MATCH(1,('Rework Log'!$A$2:$A$497=_xlpm.nm)*('Rework Log'!$G$2:$G$497<>"Yes")*('Rework Log'!$G$2:$G$497<>"Did not pass re-test")*('Rework Log'!$J$2:$J$497=""),0))),_xlpm.sent,_xlfn.MAXIFS('Rework Log'!$B$2:$B$497,'Rework Log'!$A$2:$A$497,_xlpm.nm),_xlpm.act,_xlfn.IFS(_xlpm.st="NOT STARTED",$M7,_xlpm.st="DB Dev",$M7,_xlpm.st="PBI Dev",$S7,_xlpm.st="QA",$Y7,_xlpm.st="DPO Approval",$AC7,_xlpm.st="Ready for Release in Prod",$AG7,TRUE,""),_xlpm.nxt,_xlfn.IFS(_xlpm.st="NOT STARTED","PBI Dev",_xlpm.st="DB Dev","PBI Dev",_xlpm.st="PBI Dev","QA",_xlpm.st="QA","DPO Approval",_xlpm.st="DPO Approval","Ready for Release in Prod",_xlpm.st="Ready for Release in Prod","RELEASED IN PROD",TRUE,""),IF(AND(_xlpm.ou>0,_xlpm.st<>_xlpm.oto),"Move status back to "&_xlpm.oto,IF(AND(_xlpm.ob=0,LEFT($AJ7,3)="Yes"),"Blocked - log it on Rework Log",IF(AND(_xlpm.ob>0,LEFT($AJ7,3)<>"Yes"),"Open rework row - mark Blocked or close it",IF(AND(_xlpm.ob=0,_xlpm.act<>"",_xlpm.act>=_xlpm.sent,_xlpm.nxt<>""),"Move status to "&_xlpm.nxt,IF(COUNTIF($B$2:$B$528,$B7)>1,"Duplicate name - check row",IF(COUNTIF('Rework Log'!$A$2:$A$497,$B7)>0,"",IF(AND($V7<>"",$K7<>"",$V7<$K7),"QA target is before DB Dev target",IF(AND($V7<>"",$Q7<>"",$V7<$Q7),"QA target is before PBI Dev target",IF(AND($AA7<>"",$V7<>"",$AA7<$V7),"DPO Approval target is before QA target",IF(AND($AG7<>"",$AA7<>"",$AG7<$AA7),"Confirmed Deployed date is before DPO Approval target",""))))))))))))} | AM7: {=_xlfn.LET(_xlpm.rep,$B7,_xlpm.sent,_xlfn.MAXIFS('Rework Log'!$B$2:$B$497,'Rework Log'!$A$2:$A$497,_xlpm.rep,'Rework Log'!$C$2:$C$497,"QA"),_xlpm.fixdate,_xlfn.MAXIFS('Rework Log'!$J$2:$J$497,'Rework Log'!$A$2:$A$497,_xlpm.rep,'Rework Log'!$C$2:$C$497,"QA",'Rework Log'!$B$2:$B$497,_xlpm.sent),_xlpm.expfix,_xlfn.MAXIFS('Rework Log'!$I$2:$I$497,'Rework Log'!$A$2:$A$497,_xlpm.rep,'Rework Log'!$C$2:$C$497,"QA",'Rework Log'!$B$2:$B$497,_xlpm.sent),_xlpm.base,IF(_xlpm.fixdate>0,_xlpm.fixdate,_xlpm.expfix),IF(OR(_xlpm.rep="",_xlpm.sent=0,_xlpm.base=0),"",WORKDAY(_xlpm.base,3)))} | AN7: {=_xlfn.LET(_xlpm.rep,$B7,_xlpm.sent,_xlfn.MAXIFS('Rework Log'!$B$2:$B$497,'Rework Log'!$A$2:$A$497,_xlpm.rep,'Rework Log'!$C$2:$C$497,"DPO*"),_xlpm.fixdate,_xlfn.MAXIFS('Rework Log'!$J$2:$J$497,'Rework Log'!$A$2:$A$497,_xlpm.rep,'Rework Log'!$C$2:$C$497,"DPO*",'Rework Log'!$B$2:$B$497,_xlpm.sent),_xlpm.expfix,_xlfn.MAXIFS('Rework Log'!$I$2:$I$497,'Rework Log'!$A$2:$A$497,_xlpm.rep,'Rework Log'!$C$2:$C$497,"DPO*",'Rework Log'!$B$2:$B$497,_xlpm.sent),_xlpm.base,IF(_xlpm.fixdate>0,_xlpm.fixdate,_xlpm.expfix),IF(OR(_xlpm.rep="",_xlpm.sent=0,_xlpm.base=0),"",WORKDAY(_xlpm.base,7)))}
A8: Leaks | B8: RPT_04_Prior Leak Readings | C8: RELEASED IN PROD | D8: {=IF(AND(C8="Ready for Release in Prod",LEFT($AJ8,3)<>"Yes"),IF(AG8<>"","Delivered","On track"),IF($B8="","",IF(LEFT($AJ8,3)="Yes","Blocked - "&MID($AJ8,7,100)&IF(SUMPRODUCT(('Rework Log'!$A$2:$A$497=$B8)*('Rework Log'!$G$2:$G$497<>"Yes")*('Rework Log'!$G$2:$G$497<>"Did not pass re-test"))=0,"",IF(SUMPRODUCT(MAX((('Rework Log'!$A$2:$A$497=$B8)*('Rework Log'!$G$2:$G$497<>"Yes")*('Rework Log'!$G$2:$G$497<>"Did not pass re-test"))*'Rework Log'!$I$2:$I$497))=0," - unclaimed"," - promised "&TEXT(SUMPRODUCT(MAX((('Rework Log'!$A$2:$A$497=$B8)*('Rework Log'!$G$2:$G$497<>"Yes")*('Rework Log'!$G$2:$G$497<>"Did not pass re-test"))*'Rework Log'!$I$2:$I$497)),"m/d"))),IF(C8="NOT STARTED",IF(H8="","No plan date set",IF(H8<TODAY(),"Review - planned start passed","On track")),IF(C8="DB Dev",_xlfn.LET(_xlpm.sent,_xlfn.MAXIFS('Rework Log'!$B$2:$B$497,'Rework Log'!$A$2:$A$497,$B8,'Rework Log'!$D$2:$D$497,"DB Dev"),_xlpm.expfix,_xlfn.MAXIFS('Rework Log'!$I$2:$I$497,'Rework Log'!$A$2:$A$497,$B8,'Rework Log'!$D$2:$D$497,"DB Dev",'Rework Log'!$B$2:$B$497,_xlpm.sent),_xlpm.tgt,IF(_xlpm.expfix>0,_xlpm.expfix,IF(L8<>"",L8,K8)),_xlpm.act,IF(AND(M8<>"",M8>=_xlpm.sent),M8,""),IF(_xlpm.tgt="","No target set",IF(AND(_xlpm.tgt<TODAY(),_xlpm.act=""),"Overdue","On track"))),IF(C8="PBI Dev",_xlfn.LET(_xlpm.sent,_xlfn.MAXIFS('Rework Log'!$B$2:$B$497,'Rework Log'!$A$2:$A$497,$B8,'Rework Log'!$D$2:$D$497,"PBI Dev"),_xlpm.expfix,_xlfn.MAXIFS('Rework Log'!$I$2:$I$497,'Rework Log'!$A$2:$A$497,$B8,'Rework Log'!$D$2:$D$497,"PBI Dev",'Rework Log'!$B$2:$B$497,_xlpm.sent),_xlpm.tgt,IF(_xlpm.expfix>0,_xlpm.expfix,IF(R8<>"",R8,Q8)),_xlpm.act,IF(AND(S8<>"",S8>=_xlpm.sent),S8,""),IF(_xlpm.tgt="","No target set",IF(AND(_xlpm.tgt<TODAY(),_xlpm.act=""),"Overdue","On track"))),IF(C8="QA",_xlfn.LET(_xlpm.tgt,IF(AM8<>"",AM8,IF(W8<>"",W8,V8)),_xlpm.sent,_xlfn.MAXIFS('Rework Log'!$B$2:$B$497,'Rework Log'!$A$2:$A$497,$B8,'Rework Log'!$C$2:$C$497,"QA"),_xlpm.act,IF(AND(Y8<>"",Y8>=_xlpm.sent),Y8,""),IF(_xlpm.tgt="","No target set",IF(AND(_xlpm.tgt<TODAY(),_xlpm.act=""),"Overdue","On track"))),IF(C8="DPO Approval",_xlfn.LET(_xlpm.tgt,IF(AN8<>"",AN8,IF(AB8<>"",AB8,AA8)),_xlpm.sent,_xlfn.MAXIFS('Rework Log'!$B$2:$B$497,'Rework Log'!$A$2:$A$497,$B8,'Rework Log'!$C$2:$C$497,"DPO*"),_xlpm.act,IF(AND(AC8<>"",AC8>=_xlpm.sent),AC8,""),IF(_xlpm.tgt="","No target set",IF(AND(_xlpm.tgt<TODAY(),_xlpm.act=""),"Overdue","On track"))),IF(C8="RELEASED IN PROD","Delivered","")))))))))} -> Delivered | E8: 7 | H8: 46142 | I8: April | N8: Curated | AD8: Kelvin Hu | AE8: Ops | AF8: Yes | AG8: 46142 | AK8: {=IF($B8="","",_xlfn.LET(_xlpm.nm,$B8,_xlpm.st,$C8,_xlpm.ou,SUMPRODUCT(('Rework Log'!$A$2:$A$497=_xlpm.nm)*('Rework Log'!$G$2:$G$497<>"Yes")*('Rework Log'!$G$2:$G$497<>"Did not pass re-test")*('Rework Log'!$J$2:$J$497="")),_xlpm.ob,SUMPRODUCT(('Rework Log'!$A$2:$A$497=_xlpm.nm)*('Rework Log'!$G$2:$G$497<>"Yes")*('Rework Log'!$G$2:$G$497<>"Did not pass re-test")),_xlpm.oto,IF(SUMPRODUCT(('Rework Log'!$A$2:$A$497=_xlpm.nm)*('Rework Log'!$G$2:$G$497<>"Yes")*('Rework Log'!$G$2:$G$497<>"Did not pass re-test")*('Rework Log'!$J$2:$J$497=""))=0,"",INDEX('Rework Log'!$D$2:$D$497,MATCH(1,('Rework Log'!$A$2:$A$497=_xlpm.nm)*('Rework Log'!$G$2:$G$497<>"Yes")*('Rework Log'!$G$2:$G$497<>"Did not pass re-test")*('Rework Log'!$J$2:$J$497=""),0))),_xlpm.sent,_xlfn.MAXIFS('Rework Log'!$B$2:$B$497,'Rework Log'!$A$2:$A$497,_xlpm.nm),_xlpm.act,_xlfn.IFS(_xlpm.st="NOT STARTED",$M8,_xlpm.st="DB Dev",$M8,_xlpm.st="PBI Dev",$S8,_xlpm.st="QA",$Y8,_xlpm.st="DPO Approval",$AC8,_xlpm.st="Ready for Release in Prod",$AG8,TRUE,""),_xlpm.nxt,_xlfn.IFS(_xlpm.st="NOT STARTED","PBI Dev",_xlpm.st="DB Dev","PBI Dev",_xlpm.st="PBI Dev","QA",_xlpm.st="QA","DPO Approval",_xlpm.st="DPO Approval","Ready for Release in Prod",_xlpm.st="Ready for Release in Prod","RELEASED IN PROD",TRUE,""),IF(AND(_xlpm.ou>0,_xlpm.st<>_xlpm.oto),"Move status back to "&_xlpm.oto,IF(AND(_xlpm.ob=0,LEFT($AJ8,3)="Yes"),"Blocked - log it on Rework Log",IF(AND(_xlpm.ob>0,LEFT($AJ8,3)<>"Yes"),"Open rework row - mark Blocked or close it",IF(AND(_xlpm.ob=0,_xlpm.act<>"",_xlpm.act>=_xlpm.sent,_xlpm.nxt<>""),"Move status to "&_xlpm.nxt,IF(COUNTIF($B$2:$B$528,$B8)>1,"Duplicate name - check row",IF(COUNTIF('Rework Log'!$A$2:$A$497,$B8)>0,"",IF(AND($V8<>"",$K8<>"",$V8<$K8),"QA target is before DB Dev target",IF(AND($V8<>"",$Q8<>"",$V8<$Q8),"QA target is before PBI Dev target",IF(AND($AA8<>"",$V8<>"",$AA8<$V8),"DPO Approval target is before QA target",IF(AND($AG8<>"",$AA8<>"",$AG8<$AA8),"Confirmed Deployed date is before DPO Approval target",""))))))))))))} | AM8: {=_xlfn.LET(_xlpm.rep,$B8,_xlpm.sent,_xlfn.MAXIFS('Rework Log'!$B$2:$B$497,'Rework Log'!$A$2:$A$497,_xlpm.rep,'Rework Log'!$C$2:$C$497,"QA"),_xlpm.fixdate,_xlfn.MAXIFS('Rework Log'!$J$2:$J$497,'Rework Log'!$A$2:$A$497,_xlpm.rep,'Rework Log'!$C$2:$C$497,"QA",'Rework Log'!$B$2:$B$497,_xlpm.sent),_xlpm.expfix,_xlfn.MAXIFS('Rework Log'!$I$2:$I$497,'Rework Log'!$A$2:$A$497,_xlpm.rep,'Rework Log'!$C$2:$C$497,"QA",'Rework Log'!$B$2:$B$497,_xlpm.sent),_xlpm.base,IF(_xlpm.fixdate>0,_xlpm.fixdate,_xlpm.expfix),IF(OR(_xlpm.rep="",_xlpm.sent=0,_xlpm.base=0),"",WORKDAY(_xlpm.base,3)))} | AN8: {=_xlfn.LET(_xlpm.rep,$B8,_xlpm.sent,_xlfn.MAXIFS('Rework Log'!$B$2:$B$497,'Rework Log'!$A$2:$A$497,_xlpm.rep,'Rework Log'!$C$2:$C$497,"DPO*"),_xlpm.fixdate,_xlfn.MAXIFS('Rework Log'!$J$2:$J$497,'Rework Log'!$A$2:$A$497,_xlpm.rep,'Rework Log'!$C$2:$C$497,"DPO*",'Rework Log'!$B$2:$B$497,_xlpm.sent),_xlpm.expfix,_xlfn.MAXIFS('Rework Log'!$I$2:$I$497,'Rework Log'!$A$2:$A$497,_xlpm.rep,'Rework Log'!$C$2:$C$497,"DPO*",'Rework Log'!$B$2:$B$497,_xlpm.sent),_xlpm.base,IF(_xlpm.fixdate>0,_xlpm.fixdate,_xlpm.expfix),IF(OR(_xlpm.rep="",_xlpm.sent=0,_xlpm.base=0),"",WORKDAY(_xlpm.base,7)))}
A9: Leaks | B9: RSS_04_Leak Grade Change History | C9: RELEASED IN PROD | D9: {=IF(AND(C9="Ready for Release in Prod",LEFT($AJ9,3)<>"Yes"),IF(AG9<>"","Delivered","On track"),IF($B9="","",IF(LEFT($AJ9,3)="Yes","Blocked - "&MID($AJ9,7,100)&IF(SUMPRODUCT(('Rework Log'!$A$2:$A$497=$B9)*('Rework Log'!$G$2:$G$497<>"Yes")*('Rework Log'!$G$2:$G$497<>"Did not pass re-test"))=0,"",IF(SUMPRODUCT(MAX((('Rework Log'!$A$2:$A$497=$B9)*('Rework Log'!$G$2:$G$497<>"Yes")*('Rework Log'!$G$2:$G$497<>"Did not pass re-test"))*'Rework Log'!$I$2:$I$497))=0," - unclaimed"," - promised "&TEXT(SUMPRODUCT(MAX((('Rework Log'!$A$2:$A$497=$B9)*('Rework Log'!$G$2:$G$497<>"Yes")*('Rework Log'!$G$2:$G$497<>"Did not pass re-test"))*'Rework Log'!$I$2:$I$497)),"m/d"))),IF(C9="NOT STARTED",IF(H9="","No plan date set",IF(H9<TODAY(),"Review - planned start passed","On track")),IF(C9="DB Dev",_xlfn.LET(_xlpm.sent,_xlfn.MAXIFS('Rework Log'!$B$2:$B$497,'Rework Log'!$A$2:$A$497,$B9,'Rework Log'!$D$2:$D$497,"DB Dev"),_xlpm.expfix,_xlfn.MAXIFS('Rework Log'!$I$2:$I$497,'Rework Log'!$A$2:$A$497,$B9,'Rework Log'!$D$2:$D$497,"DB Dev",'Rework Log'!$B$2:$B$497,_xlpm.sent),_xlpm.tgt,IF(_xlpm.expfix>0,_xlpm.expfix,IF(L9<>"",L9,K9)),_xlpm.act,IF(AND(M9<>"",M9>=_xlpm.sent),M9,""),IF(_xlpm.tgt="","No target set",IF(AND(_xlpm.tgt<TODAY(),_xlpm.act=""),"Overdue","On track"))),IF(C9="PBI Dev",_xlfn.LET(_xlpm.sent,_xlfn.MAXIFS('Rework Log'!$B$2:$B$497,'Rework Log'!$A$2:$A$497,$B9,'Rework Log'!$D$2:$D$497,"PBI Dev"),_xlpm.expfix,_xlfn.MAXIFS('Rework Log'!$I$2:$I$497,'Rework Log'!$A$2:$A$497,$B9,'Rework Log'!$D$2:$D$497,"PBI Dev",'Rework Log'!$B$2:$B$497,_xlpm.sent),_xlpm.tgt,IF(_xlpm.expfix>0,_xlpm.expfix,IF(R9<>"",R9,Q9)),_xlpm.act,IF(AND(S9<>"",S9>=_xlpm.sent),S9,""),IF(_xlpm.tgt="","No target set",IF(AND(_xlpm.tgt<TODAY(),_xlpm.act=""),"Overdue","On track"))),IF(C9="QA",_xlfn.LET(_xlpm.tgt,IF(AM9<>"",AM9,IF(W9<>"",W9,V9)),_xlpm.sent,_xlfn.MAXIFS('Rework Log'!$B$2:$B$497,'Rework Log'!$A$2:$A$497,$B9,'Rework Log'!$C$2:$C$497,"QA"),_xlpm.act,IF(AND(Y9<>"",Y9>=_xlpm.sent),Y9,""),IF(_xlpm.tgt="","No target set",IF(AND(_xlpm.tgt<TODAY(),_xlpm.act=""),"Overdue","On track"))),IF(C9="DPO Approval",_xlfn.LET(_xlpm.tgt,IF(AN9<>"",AN9,IF(AB9<>"",AB9,AA9)),_xlpm.sent,_xlfn.MAXIFS('Rework Log'!$B$2:$B$497,'Rework Log'!$A$2:$A$497,$B9,'Rework Log'!$C$2:$C$497,"DPO*"),_xlpm.act,IF(AND(AC9<>"",AC9>=_xlpm.sent),AC9,""),IF(_xlpm.tgt="","No target set",IF(AND(_xlpm.tgt<TODAY(),_xlpm.act=""),"Overdue","On track"))),IF(C9="RELEASED IN PROD","Delivered","")))))))))} -> Delivered | E9: 8 | H9: 46142 | I9: April | N9: Curated | AD9: Kelvin Hu | AE9: Ops | AF9: Yes | AG9: 46142 | AK9: {=IF($B9="","",_xlfn.LET(_xlpm.nm,$B9,_xlpm.st,$C9,_xlpm.ou,SUMPRODUCT(('Rework Log'!$A$2:$A$497=_xlpm.nm)*('Rework Log'!$G$2:$G$497<>"Yes")*('Rework Log'!$G$2:$G$497<>"Did not pass re-test")*('Rework Log'!$J$2:$J$497="")),_xlpm.ob,SUMPRODUCT(('Rework Log'!$A$2:$A$497=_xlpm.nm)*('Rework Log'!$G$2:$G$497<>"Yes")*('Rework Log'!$G$2:$G$497<>"Did not pass re-test")),_xlpm.oto,IF(SUMPRODUCT(('Rework Log'!$A$2:$A$497=_xlpm.nm)*('Rework Log'!$G$2:$G$497<>"Yes")*('Rework Log'!$G$2:$G$497<>"Did not pass re-test")*('Rework Log'!$J$2:$J$497=""))=0,"",INDEX('Rework Log'!$D$2:$D$497,MATCH(1,('Rework Log'!$A$2:$A$497=_xlpm.nm)*('Rework Log'!$G$2:$G$497<>"Yes")*('Rework Log'!$G$2:$G$497<>"Did not pass re-test")*('Rework Log'!$J$2:$J$497=""),0))),_xlpm.sent,_xlfn.MAXIFS('Rework Log'!$B$2:$B$497,'Rework Log'!$A$2:$A$497,_xlpm.nm),_xlpm.act,_xlfn.IFS(_xlpm.st="NOT STARTED",$M9,_xlpm.st="DB Dev",$M9,_xlpm.st="PBI Dev",$S9,_xlpm.st="QA",$Y9,_xlpm.st="DPO Approval",$AC9,_xlpm.st="Ready for Release in Prod",$AG9,TRUE,""),_xlpm.nxt,_xlfn.IFS(_xlpm.st="NOT STARTED","PBI Dev",_xlpm.st="DB Dev","PBI Dev",_xlpm.st="PBI Dev","QA",_xlpm.st="QA","DPO Approval",_xlpm.st="DPO Approval","Ready for Release in Prod",_xlpm.st="Ready for Release in Prod","RELEASED IN PROD",TRUE,""),IF(AND(_xlpm.ou>0,_xlpm.st<>_xlpm.oto),"Move status back to "&_xlpm.oto,IF(AND(_xlpm.ob=0,LEFT($AJ9,3)="Yes"),"Blocked - log it on Rework Log",IF(AND(_xlpm.ob>0,LEFT($AJ9,3)<>"Yes"),"Open rework row - mark Blocked or close it",IF(AND(_xlpm.ob=0,_xlpm.act<>"",_xlpm.act>=_xlpm.sent,_xlpm.nxt<>""),"Move status to "&_xlpm.nxt,IF(COUNTIF($B$2:$B$528,$B9)>1,"Duplicate name - check row",IF(COUNTIF('Rework Log'!$A$2:$A$497,$B9)>0,"",IF(AND($V9<>"",$K9<>"",$V9<$K9),"QA target is before DB Dev target",IF(AND($V9<>"",$Q9<>"",$V9<$Q9),"QA target is before PBI Dev target",IF(AND($AA9<>"",$V9<>"",$AA9<$V9),"DPO Approval target is before QA target",IF(AND($AG9<>"",$AA9<>"",$AG9<$AA9),"Confirmed Deployed date is before DPO Approval target",""))))))))))))} | AM9: {=_xlfn.LET(_xlpm.rep,$B9,_xlpm.sent,_xlfn.MAXIFS('Rework Log'!$B$2:$B$497,'Rework Log'!$A$2:$A$497,_xlpm.rep,'Rework Log'!$C$2:$C$497,"QA"),_xlpm.fixdate,_xlfn.MAXIFS('Rework Log'!$J$2:$J$497,'Rework Log'!$A$2:$A$497,_xlpm.rep,'Rework Log'!$C$2:$C$497,"QA",'Rework Log'!$B$2:$B$497,_xlpm.sent),_xlpm.expfix,_xlfn.MAXIFS('Rework Log'!$I$2:$I$497,'Rework Log'!$A$2:$A$497,_xlpm.rep,'Rework Log'!$C$2:$C$497,"QA",'Rework Log'!$B$2:$B$497,_xlpm.sent),_xlpm.base,IF(_xlpm.fixdate>0,_xlpm.fixdate,_xlpm.expfix),IF(OR(_xlpm.rep="",_xlpm.sent=0,_xlpm.base=0),"",WORKDAY(_xlpm.base,3)))} | AN9: {=_xlfn.LET(_xlpm.rep,$B9,_xlpm.sent,_xlfn.MAXIFS('Rework Log'!$B$2:$B$497,'Rework Log'!$A$2:$A$497,_xlpm.rep,'Rework Log'!$C$2:$C$497,"DPO*"),_xlpm.fixdate,_xlfn.MAXIFS('Rework Log'!$J$2:$J$497,'Rework Log'!$A$2:$A$497,_xlpm.rep,'Rework Log'!$C$2:$C$497,"DPO*",'Rework Log'!$B$2:$B$497,_xlpm.sent),_xlpm.expfix,_xlfn.MAXIFS('Rework Log'!$I$2:$I$497,'Rework Log'!$A$2:$A$497,_xlpm.rep,'Rework Log'!$C$2:$C$497,"DPO*",'Rework Log'!$B$2:$B$497,_xlpm.sent),_xlpm.base,IF(_xlpm.fixdate>0,_xlpm.fixdate,_xlpm.expfix),IF(OR(_xlpm.rep="",_xlpm.sent=0,_xlpm.base=0),"",WORKDAY(_xlpm.base,7)))}
A10: Leaks | B10: RPT_04_Rechecks Completed less than 14 days | C10: RELEASED IN PROD | D10: {=IF(AND(C10="Ready for Release in Prod",LEFT($AJ10,3)<>"Yes"),IF(AG10<>"","Delivered","On track"),IF($B10="","",IF(LEFT($AJ10,3)="Yes","Blocked - "&MID($AJ10,7,100)&IF(SUMPRODUCT(('Rework Log'!$A$2:$A$497=$B10)*('Rework Log'!$G$2:$G$497<>"Yes")*('Rework Log'!$G$2:$G$497<>"Did not pass re-test"))=0,"",IF(SUMPRODUCT(MAX((('Rework Log'!$A$2:$A$497=$B10)*('Rework Log'!$G$2:$G$497<>"Yes")*('Rework Log'!$G$2:$G$497<>"Did not pass re-test"))*'Rework Log'!$I$2:$I$497))=0," - unclaimed"," - promised "&TEXT(SUMPRODUCT(MAX((('Rework Log'!$A$2:$A$497=$B10)*('Rework Log'!$G$2:$G$497<>"Yes")*('Rework Log'!$G$2:$G$497<>"Did not pass re-test"))*'Rework Log'!$I$2:$I$497)),"m/d"))),IF(C10="NOT STARTED",IF(H10="","No plan date set",IF(H10<TODAY(),"Review - planned start passed","On track")),IF(C10="DB Dev",_xlfn.LET(_xlpm.sent,_xlfn.MAXIFS('Rework Log'!$B$2:$B$497,'Rework Log'!$A$2:$A$497,$B10,'Rework Log'!$D$2:$D$497,"DB Dev"),_xlpm.expfix,_xlfn.MAXIFS('Rework Log'!$I$2:$I$497,'Rework Log'!$A$2:$A$497,$B10,'Rework Log'!$D$2:$D$497,"DB Dev",'Rework Log'!$B$2:$B$497,_xlpm.sent),_xlpm.tgt,IF(_xlpm.expfix>0,_xlpm.expfix,IF(L10<>"",L10,K10)),_xlpm.act,IF(AND(M10<>"",M10>=_xlpm.sent),M10,""),IF(_xlpm.tgt="","No target set",IF(AND(_xlpm.tgt<TODAY(),_xlpm.act=""),"Overdue","On track"))),IF(C10="PBI Dev",_xlfn.LET(_xlpm.sent,_xlfn.MAXIFS('Rework Log'!$B$2:$B$497,'Rework Log'!$A$2:$A$497,$B10,'Rework Log'!$D$2:$D$497,"PBI Dev"),_xlpm.expfix,_xlfn.MAXIFS('Rework Log'!$I$2:$I$497,'Rework Log'!$A$2:$A$497,$B10,'Rework Log'!$D$2:$D$497,"PBI Dev",'Rework Log'!$B$2:$B$497,_xlpm.sent),_xlpm.tgt,IF(_xlpm.expfix>0,_xlpm.expfix,IF(R10<>"",R10,Q10)),_xlpm.act,IF(AND(S10<>"",S10>=_xlpm.sent),S10,""),IF(_xlpm.tgt="","No target set",IF(AND(_xlpm.tgt<TODAY(),_xlpm.act=""),"Overdue","On track"))),IF(C10="QA",_xlfn.LET(_xlpm.tgt,IF(AM10<>"",AM10,IF(W10<>"",W10,V10)),_xlpm.sent,_xlfn.MAXIFS('Rework Log'!$B$2:$B$497,'Rework Log'!$A$2:$A$497,$B10,'Rework Log'!$C$2:$C$497,"QA"),_xlpm.act,IF(AND(Y10<>"",Y10>=_xlpm.sent),Y10,""),IF(_xlpm.tgt="","No target set",IF(AND(_xlpm.tgt<TODAY(),_xlpm.act=""),"Overdue","On track"))),IF(C10="DPO Approval",_xlfn.LET(_xlpm.tgt,IF(AN10<>"",AN10,IF(AB10<>"",AB10,AA10)),_xlpm.sent,_xlfn.MAXIFS('Rework Log'!$B$2:$B$497,'Rework Log'!$A$2:$A$497,$B10,'Rework Log'!$C$2:$C$497,"DPO*"),_xlpm.act,IF(AND(AC10<>"",AC10>=_xlpm.sent),AC10,""),IF(_xlpm.tgt="","No target set",IF(AND(_xlpm.tgt<TODAY(),_xlpm.act=""),"Overdue","On track"))),IF(C10="RELEASED IN PROD","Delivered","")))))))))} -> Delivered | E10: 9 | H10: 46173 | I10: May | J10: Rupa | K10: 46150 | M10: 46157 | N10: Curated | P10: Shraddha | Q10: 46157 | S10: 46134 | U10: Preety | V10: 46164 | Y10: 46134 | AA10: 46169 | AD10: Kelvin Hu | AE10: Ops | AF10: Yes | AG10: 46134 | AH10: https://app.powerbi.com/groups/me/apps/7767030c-f4c8-4488-b3cb-36a860cb6ff2/reports/de1ad11f-021b-4cc1-b465-67efd542031c/3122b8024291693794eb?ctid=f98a6a53-25f3-4212-901c-c7787fcd3495&experience=power-bi | AI10: https://app.powerbi.com/groups/me/apps/5b29b0dd-a398-4801-84ce-f3a7d8435827/reports/0e063b20-0b38-4000-b436-fcbec11daa46/3122b8024291693794eb?experience=power-bi | AJ10: No | AK10: {=IF($B10="","",_xlfn.LET(_xlpm.nm,$B10,_xlpm.st,$C10,_xlpm.ou,SUMPRODUCT(('Rework Log'!$A$2:$A$497=_xlpm.nm)*('Rework Log'!$G$2:$G$497<>"Yes")*('Rework Log'!$G$2:$G$497<>"Did not pass re-test")*('Rework Log'!$J$2:$J$497="")),_xlpm.ob,SUMPRODUCT(('Rework Log'!$A$2:$A$497=_xlpm.nm)*('Rework Log'!$G$2:$G$497<>"Yes")*('Rework Log'!$G$2:$G$497<>"Did not pass re-test")),_xlpm.oto,IF(SUMPRODUCT(('Rework Log'!$A$2:$A$497=_xlpm.nm)*('Rework Log'!$G$2:$G$497<>"Yes")*('Rework Log'!$G$2:$G$497<>"Did not pass re-test")*('Rework Log'!$J$2:$J$497=""))=0,"",INDEX('Rework Log'!$D$2:$D$497,MATCH(1,('Rework Log'!$A$2:$A$497=_xlpm.nm)*('Rework Log'!$G$2:$G$497<>"Yes")*('Rework Log'!$G$2:$G$497<>"Did not pass re-test")*('Rework Log'!$J$2:$J$497=""),0))),_xlpm.sent,_xlfn.MAXIFS('Rework Log'!$B$2:$B$497,'Rework Log'!$A$2:$A$497,_xlpm.nm),_xlpm.act,_xlfn.IFS(_xlpm.st="NOT STARTED",$M10,_xlpm.st="DB Dev",$M10,_xlpm.st="PBI Dev",$S10,_xlpm.st="QA",$Y10,_xlpm.st="DPO Approval",$AC10,_xlpm.st="Ready for Release in Prod",$AG10,TRUE,""),_xlpm.nxt,_xlfn.IFS(_xlpm.st="NOT STARTED","PBI Dev",_xlpm.st="DB Dev","PBI Dev",_xlpm.st="PBI Dev","QA",_xlpm.st="QA","DPO Approval",_xlpm.st="DPO Approval","Ready for Release in Prod",_xlpm.st="Ready for Release in Prod","RELEASED IN PROD",TRUE,""),IF(AND(_xlpm.ou>0,_xlpm.st<>_xlpm.oto),"Move status back to "&_xlpm.oto,IF(AND(_xlpm.ob=0,LEFT($AJ10,3)="Yes"),"Blocked - log it on Rework Log",IF(AND(_xlpm.ob>0,LEFT($AJ10,3)<>"Yes"),"Open rework row - mark Blocked or close it",IF(AND(_xlpm.ob=0,_xlpm.act<>"",_xlpm.act>=_xlpm.sent,_xlpm.nxt<>""),"Move status to "&_xlpm.nxt,IF(COUNTIF($B$2:$B$528,$B10)>1,"Duplicate name - check row",IF(COUNTIF('Rework Log'!$A$2:$A$497,$B10)>0,"",IF(AND($V10<>"",$K10<>"",$V10<$K10),"QA target is before DB Dev target",IF(AND($V10<>"",$Q10<>"",$V10<$Q10),"QA target is before PBI Dev target",IF(AND($AA10<>"",$V10<>"",$AA10<$V10),"DPO Approval target is before QA target",IF(AND($AG10<>"",$AA10<>"",$AG10<$AA10),"Confirmed Deployed date is before DPO Approval target",""))))))))))))} -> Confirmed Deployed date is before DPO Approval target | AM10: {=_xlfn.LET(_xlpm.rep,$B10,_xlpm.sent,_xlfn.MAXIFS('Rework Log'!$B$2:$B$497,'Rework Log'!$A$2:$A$497,_xlpm.rep,'Rework Log'!$C$2:$C$497,"QA"),_xlpm.fixdate,_xlfn.MAXIFS('Rework Log'!$J$2:$J$497,'Rework Log'!$A$2:$A$497,_xlpm.rep,'Rework Log'!$C$2:$C$497,"QA",'Rework Log'!$B$2:$B$497,_xlpm.sent),_xlpm.expfix,_xlfn.MAXIFS('Rework Log'!$I$2:$I$497,'Rework Log'!$A$2:$A$497,_xlpm.rep,'Rework Log'!$C$2:$C$497,"QA",'Rework Log'!$B$2:$B$497,_xlpm.sent),_xlpm.base,IF(_xlpm.fixdate>0,_xlpm.fixdate,_xlpm.expfix),IF(OR(_xlpm.rep="",_xlpm.sent=0,_xlpm.base=0),"",WORKDAY(_xlpm.base,3)))} | AN10: {=_xlfn.LET(_xlpm.rep,$B10,_xlpm.sent,_xlfn.MAXIFS('Rework Log'!$B$2:$B$497,'Rework Log'!$A$2:$A$497,_xlpm.rep,'Rework Log'!$C$2:$C$497,"DPO*"),_xlpm.fixdate,_xlfn.MAXIFS('Rework Log'!$J$2:$J$497,'Rework Log'!$A$2:$A$497,_xlpm.rep,'Rework Log'!$C$2:$C$497,"DPO*",'Rework Log'!$B$2:$B$497,_xlpm.sent),_xlpm.expfix,_xlfn.MAXIFS('Rework Log'!$I$2:$I$497,'Rework Log'!$A$2:$A$497,_xlpm.rep,'Rework Log'!$C$2:$C$497,"DPO*",'Rework Log'!$B$2:$B$497,_xlpm.sent),_xlpm.base,IF(_xlpm.fixdate>0,_xlpm.fixdate,_xlpm.expfix),IF(OR(_xlpm.rep="",_xlpm.sent=0,_xlpm.base=0),"",WORKDAY(_xlpm.base,7)))}
