Workbook
Name DB_Dev_List: 'Data Validation'!$B$3:$B$10
Name DPO_Approval_List: 'Data Validation'!$K$3:$K$6
Name PBI_Dev_List: 'Data Validation'!$C$3:$C$5
Name QA_List: 'Data Validation'!$H$3:$H$6

Sheet READ ME FIRST
B1: GDM REPORT DELIVERY TRACKER
B3: THE TWO TABS
B4: Combined Delivery Data = what is true RIGHT NOW. One row per report, latest dates only - built for a 10-second executive read. Rework Log = everything that ever went wrong. One row per bounce-back, kept forever. AMBER columns belong to the sender, BLUE to the fixer, PURPLE is automatic.
B6: COLORS
B7: RED = needs action now (blocked, overdue, late, unclaimed, or a red instruction in Data Check). AMBER = open or waiting. GREEN = good. If nothing is red on your rows, you owe nothing. PURPLE headers and purple-tinted cells = the sheet computes these and they are locked - you never type in purple. Everything else is yours to fill.
B9: NORMAL DAY - A STAGE FINISHES
B10: Two cells on Combined Delivery Data: your stage's Actual Completion Date, and Current Status to the next stage. Done.
B12: SOMETHING IS WRONG - SENDER (usually QA), about 30 seconds
B13: 1. Main tab: Blocked? -> "Yes - needs [stage] to fix", and Current Status -> back to that stage 2. Rework Log, the AMBER columns of one new row: report (dropdown), Ctrl+; for today, From/To stage, your name, what was wrong You never touch completion dates. The row now shows UNCLAIMED in red until the fixer commits.
B15: THE FIXER - AT PICKUP (two cells, both yours)
B16: 1. Expected Fix Date: your promise. The main tab instantly shows everyone "Blocked - needs DB Dev to fix - promised 8/5", and your row starts counting "N d LATE" if you miss it 2. CUT your old completion date from the main tab, PASTE it into "First Completed On" - one motion. History saved forever; the main tab correctly shows no completion date while you redo the work. A red note in Data Check reminds you until it's done.
B18: THE FIXER - WHEN DONE
... B28: Blocked but not logged -> red "Blocked - log it on Rework Log". Picked up but old completion date still on main tab -> red "Move old [stage] completion date...". Row open but not marked blocked -> red instruction. Missing sent-back date -> red in Aging. Duplicates and impossible date orders -> flagged. Hover any dropdown for guidance.

Sheet Combined Delivery Data
A1: Domain | B1: Report Name | C1: Current Status | D1: Status Flag (auto) | E1: Business Value Rank | F1: PO | G1: DB Developer | H1: PBI Developer | I1: QA Tester | J1: Schema | K1: Plan Delivery Date | L1: Plan Delivery Month | M1: DB Dev Baseline Completion Date | N1: DB Dev Reforecast Completion Date | O1: DB Dev Actual Completion Date | P1: PBI Dev Baseline Completion Date | Q1: PBI Dev Reforecast Completion Date | R1: PBI Dev Actual Completion Date | S1: QA Baseline Completion Date | T1: QA Reforecast Completion Date | U1: QA Actual Completion Date | V1: DPO Approval Baseline Completion Date | W1: DPO Approval Reforecast Completion Date | X1: DPO Approval Reviewer | Y1: Confirmed Deployed? | Z1: Confirmed Deployed Date | AA1: UAT Report URL | AB1: Production URL | AC1: Blocked? | AD1: Data Check (auto) | AE1: Comments
A2: Leaks | B2: RPT_04_Active Leaks | C2: RELEASED IN PROD | D2: =IF($B2="","",IF(LEFT($AC2,3)="Yes",IF(LEN($AC2)>5,"Blocked - "&MID($AC2,7,100),"Blocked")&IF(SUMPRODUCT((TRIM('Rework Log'!$A$3:$A$500)=TRIM($B2))*('Rework Log'!$G$3:$G$500<>"Yes")*('Rework Log'!$G$3:$G$500<>"Did not pass re-test"))=0,"",IF(SUMPRODUCT(((TRIM('Rework Log'!$A$3:$A$500)=TRIM($B2))*('Rework Log'!$G$3:$G$500<>"Yes")*('Rework Log'!$G$3:$G$500<>"Did not pass re-test"))*ISNUMBER('Rework Log'!$J$3:$J$500))>0," - fixed, awaiting re-test",IF(SUMPRODUCT(MAX(((TRIM('Rework Log'!$A$3:$A$500)=TRIM($B2))*('Rework Log'!$G$3:$G$500<>"Yes")*('Rework Log'!$G$3:$G$500<>"Did not pass re-test"))*IFERROR('Rework Log'!$I$3:$I$500*1,0)))=0," - unclaimed"," - promised "&TEXT(SUMPRODUCT(MAX(((TRIM('Rework Log'!$A$3:$A$500)=TRIM($B2))*('Rework Log'!$G$3:$G$500<>"Yes")*('Rework Log'!$G$3:$G$500<>"Did not pass re-test"))*IFERROR('Rework Log'!$I$3:$I$500*1,0))),"m/d")))),IF(TRIM(C2)="NOT STARTED",IF(K2="","No plan date set",IF(K2<TODAY(),"Review - planned start passed","On track")),IF(TRIM(C2)="DB Dev",IF(M2="","No target set",IF(AND(M2<TODAY(),O2=""),"Overdue","On track")),IF(TRIM(C2)="PBI Dev",IF(P2="","No target set",IF(AND(P2<TODAY(),R2=""),"Overdue","On track")),IF(TRIM(C2)="QA",IF(S2="","No target set",IF(AND(S2<TODAY(),U2=""),"Overdue","On track")),IF(TRIM(C2)="DPO Approval",IF(V2="","No target set",IF(V2<TODAY(),"Overdue","On track")),IF(TRIM(C2)="RELEASED IN PROD","Delivered","")))))))) -> Delivered | E2: 1 | G2: Fetwi | H2: Sarath | I2: Preety | K2: 46142 | L2: April | M2: 46115 | O2: 46115 | P2: 46114 | R2: 46114 | S2: 46122 | U2: 46122 | X2: Kelvin Hu | Y2: Yes | Z2: 46122 | AA2: https://app.powerbi.com/groups/me/apps/eedba83d-be9a-45f9-9504-7bfa41e6051a/reports/62307ec4-3158-4457-8dcc-4acc2150cdc3/ccfe9e7f0a40d49acb85?experience=power-bi | AB2: https://app.powerbi.com/groups/me/apps/2c7180b1-0d3d-45be-979e-f7dc86b3557d/reports/8cd4a21d-3abe-4e55-a99e-3af846ab1c67/ccfe9e7f0a40d49acb85?ctid=f98a6a53-25f3-4212-901c-c7787fcd3495&experience=power-bi | AC2: No | AD2: =IF($B2="","",IF(AND(LEFT($AC2,3)="Yes",SUMPRODUCT((TRIM('Rework Log'!$A$3:$A$500)=TRIM($B2))*('Rework Log'!$G$3:$G$500<>"Yes")*('Rework Log'!$G$3:$G$500<>"Did not pass re-test"))=0),"Blocked - log it on Rework Log",IF(AND(LEFT($AC2,3)<>"Yes",SUMPRODUCT((TRIM('Rework Log'!$A$3:$A$500)=TRIM($B2))*('Rework Log'!$G$3:$G$500<>"Yes")*('Rework Log'!$G$3:$G$500<>"Did not pass re-test"))>0),"Open rework row - mark Blocked? or close it",IF(AND(LEFT($AC2,3)<>"Yes",SUMPRODUCT((TRIM('Rework Log'!$A$3:$A$500)=TRIM($B2))*('Rework Log'!$G$3:$G$500<>"Yes")*('Rework Log'!$G$3:$G$500<>"Did not pass re-test"))=0,COUNTIF('Rework Log'!$A$3:$A$500,$B2)>0,IFERROR(INDEX('Rework Log'!$G:$G,SUMPRODUCT(MAX((TRIM('Rework Log'!$A$3:$A$500)=TRIM($B2))*ROW('Rework Log'!$A$3:$A$500)))),"")="Did not pass re-test"),"Last fix rejected - re-block or log next attempt",IF(AND(LEFT($AC2,3)="Yes",ISNUMBER(SEARCH("needs DB Dev",$AC2)),O2<>"",SUMPRODUCT(MAX(((TRIM('Rework Log'!$A$3:$A$500)=TRIM($B2))*('Rework Log'!$G$3:$G$500<>"Yes")*('Rework Log'!$G$3:$G$500<>"Did not pass re-test"))*IFERROR('Rework Log'!$I$3:$I$500*1,0)))>0),"Move old DB Dev completion date to Rework Log (col H)",IF(AND(LEFT($AC2,3)="Yes",ISNUMBER(SEARCH("needs PBI Dev",$AC2)),R2<>"",SUMPRODUCT(MAX(((TRIM('Rework Log'!$A$3:$A$500)=TRIM($B2))*('Rework Log'!$G$3:$G$500<>"Yes")*('Rework Log'!$G$3:$G$500<>"Did not pass re-test"))*IFERROR('Rework Log'!$I$3:$I$500*1,0)))>0),"Move old PBI Dev completion date to Rework Log (col H)",IF(AND(LEFT($AC2,3)="Yes",ISNUMBER(SEARCH("needs QA",$AC2)),U2<>"",SUMPRODUCT(MAX(((TRIM('Rework Log'!$A$3:$A$500)=TRIM($B2))*('Rework Log'!$G$3:$G$500<>"Yes")*('Rework Log'!$G$3:$G$500<>"Did not pass re-test"))*IFERROR('Rework Log'!$I$3:$I$500*1,0)))>0),"Move old QA completion date to Rework Log (col H)",IF(AND(LEFT($AC2,3)="Yes",ISNUMBER(SEARCH("needs DB Dev",$AC2)),TRIM(C2)<>"DB Dev"),"Set Current Status back to DB Dev",IF(AND(LEFT($AC2,3)="Yes",ISNUMBER(SEARCH("needs PBI Dev",$AC2)),TRIM(C2)<>"PBI Dev"),"Set Current Status back to PBI Dev",IF(AND(LEFT($AC2,3)="Yes",ISNUMBER(SEARCH("needs QA",$AC2)),TRIM(C2)<>"QA"),"Set Current Status back to QA",IF(COUNTIF($B$2:$B$500,$B2)>1,"Duplicate name - check row",IF(AND(TRIM(C2)="RELEASED IN PROD",Y2<>"Yes"),"Released but Confirmed Deployed? is not Yes",IF(COUNTIF('Rework Log'!$A$3:$A$500,$B2)>0,"",IF(AND(S2<>"",M2<>"",S2<M2),"QA target is before DB Dev target",IF(AND(S2<>"",P2<>"",S2<P2),"QA target is before PBI Dev target",IF(AND(V2<>"",S2<>"",V2<S2),"DPO Approval target is before QA target",IF(AND(Z2<>"",V2<>"",Z2<V2),"Confirmed Deployed date is before DPO Approval target",""))))))))))))))))) -> #VALUE! | AE2: [Historical, April 2026]: QA found an issue - date calendar dimension broken. Fetwi assigned to fix.
A3: Leaks | B3: RPT_04_Count of Active Leaks On Hand | C3: RELEASED IN PROD | D3: =IF($B3="","",IF(LEFT($AC3,3)="Yes",IF(LEN($AC3)>5,"Blocked - "&MID($AC3,7,100),"Blocked")&IF(SUMPRODUCT((TRIM('Rework Log'!$A$3:$A$500)=TRIM($B3))*('Rework Log'!$G$3:$G$500<>"Yes")*('Rework Log'!$G$3:$G$500<>"Did not pass re-test"))=0,"",IF(SUMPRODUCT(((TRIM('Rework Log'!$A$3:$A$500)=TRIM($B3))*('Rework Log'!$G$3:$G$500<>"Yes")*('Rework Log'!$G$3:$G$500<>"Did not pass re-test"))*ISNUMBER('Rework Log'!$J$3:$J$500))>0," - fixed, awaiting re-test",IF(SUMPRODUCT(MAX(((TRIM('Rework Log'!$A$3:$A$500)=TRIM($B3))*('Rework Log'!$G$3:$G$500<>"Yes")*('Rework Log'!$G$3:$G$500<>"Did not pass re-test"))*IFERROR('Rework Log'!$I$3:$I$500*1,0)))=0," - unclaimed"," - promised "&TEXT(SUMPRODUCT(MAX(((TRIM('Rework Log'!$A$3:$A$500)=TRIM($B3))*('Rework Log'!$G$3:$G$500<>"Yes")*('Rework Log'!$G$3:$G$500<>"Did not pass re-test"))*IFERROR('Rework Log'!$I$3:$I$500*1,0))),"m/d")))),IF(TRIM(C3)="NOT STARTED",IF(K3="","No plan date set",IF(K3<TODAY(),"Review - planned start passed","On track")),IF(TRIM(C3)="DB Dev",IF(M3="","No target set",IF(AND(M3<TODAY(),O3=""),"Overdue","On track")),IF(TRIM(C3)="PBI Dev",IF(P3="","No target set",IF(AND(P3<TODAY(),R3=""),"Overdue","On track")),IF(TRIM(C3)="QA",IF(S3="","No target set",IF(AND(S3<TODAY(),U3=""),"Overdue","On track")),IF(TRIM(C3)="DPO Approval",IF(V3="","No target set",IF(V3<TODAY(),"Overdue","On track")),IF(TRIM(C3)="RELEASED IN PROD","Delivered","")))))))) -> Delivered | E3: 2 | G3: Fetwi | H3: Sarath | I3: Preety | K3: 46142 | L3: April | M3: 46115 | O3: 46115 | P3: 46114 | R3: 46114 | S3: 46122 | U3: 46122 | X3: Kelvin Hu | Y3: Yes | Z3: 46122 | AA3: https://app.powerbi.com/groups/me/apps/eedba83d-be9a-45f9-9504-7bfa41e6051a/reports/c0b3f0ae-dedd-485b-8bbc-aa0e5f3fd077/24a66431d0637282f4b7?experience=power-bi | AB3: https://app.powerbi.com/groups/me/apps/2c7180b1-0d3d-45be-979e-f7dc86b3557d/reports/5ffd546f-ad77-4a7f-8e6d-94dc08bef796/24a66431d0637282f4b7?ctid=f98a6a53-25f3-4212-901c-c7787fcd3495&experience=power-bi | AC3: No | AD3: =IF($B3="","",IF(AND(LEFT($AC3,3)="Yes",SUMPRODUCT((TRIM('Rework Log'!$A$3:$A$500)=TRIM($B3))*('Rework Log'!$G$3:$G$500<>"Yes")*('Rework Log'!$G$3:$G$500<>"Did not pass re-test"))=0),"Blocked - log it on Rework Log",IF(AND(LEFT($AC3,3)<>"Yes",SUMPRODUCT((TRIM('Rework Log'!$A$3:$A$500)=TRIM($B3))*('Rework Log'!$G$3:$G$500<>"Yes")*('Rework Log'!$G$3:$G$500<>"Did not pass re-test"))>0),"Open rework row - mark Blocked? or close it",IF(AND(LEFT($AC3,3)<>"Yes",SUMPRODUCT((TRIM('Rework Log'!$A$3:$A$500)=TRIM($B3))*('Rework Log'!$G$3:$G$500<>"Yes")*('Rework Log'!$G$3:$G$500<>"Did not pass re-test"))=0,COUNTIF('Rework Log'!$A$3:$A$500,$B3)>0,IFERROR(INDEX('Rework Log'!$G:$G,SUMPRODUCT(MAX((TRIM('Rework Log'!$A$3:$A$500)=TRIM($B3))*ROW('Rework Log'!$A$3:$A$500)))),"")="Did not pass re-test"),"Last fix rejected - re-block or log next attempt",IF(AND(LEFT($AC3,3)="Yes",ISNUMBER(SEARCH("needs DB Dev",$AC3)),O3<>"",SUMPRODUCT(MAX(((TRIM('Rework Log'!$A$3:$A$500)=TRIM($B3))*('Rework Log'!$G$3:$G$500<>"Yes")*('Rework Log'!$G$3:$G$500<>"Did not pass re-test"))*IFERROR('Rework Log'!$I$3:$I$500*1,0)))>0),"Move old DB Dev completion date to Rework Log (col H)",IF(AND(LEFT($AC3,3)="Yes",ISNUMBER(SEARCH("needs PBI Dev",$AC3)),R3<>"",SUMPRODUCT(MAX(((TRIM('Rework Log'!$A$3:$A$500)=TRIM($B3))*('Rework Log'!$G$3:$G$500<>"Yes")*('Rework Log'!$G$3:$G$500<>"Did not pass re-test"))*IFERROR('Rework Log'!$I$3:$I$500*1,0)))>0),"Move old PBI Dev completion date to Rework Log (col H)",IF(AND(LEFT($AC3,3)="Yes",ISNUMBER(SEARCH("needs QA",$AC3)),U3<>"",SUMPRODUCT(MAX(((TRIM('Rework Log'!$A$3:$A$500)=TRIM($B3))*('Rework Log'!$G$3:$G$500<>"Yes")*('Rework Log'!$G$3:$G$500<>"Did not pass re-test"))*IFERROR('Rework Log'!$I$3:$I$500*1,0)))>0),"Move old QA completion date to Rework Log (col H)",IF(AND(LEFT($AC3,3)="Yes",ISNUMBER(SEARCH("needs DB Dev",$AC3)),TRIM(C3)<>"DB Dev"),"Set Current Status back to DB Dev",IF(AND(LEFT($AC3,3)="Yes",ISNUMBER(SEARCH("needs PBI Dev",$AC3)),TRIM(C3)<>"PBI Dev"),"Set Current Status back to PBI Dev",IF(AND(LEFT($AC3,3)="Yes",ISNUMBER(SEARCH("needs QA",$AC3)),TRIM(C3)<>"QA"),"Set Current Status back to QA",IF(COUNTIF($B$2:$B$500,$B3)>1,"Duplicate name - check row",IF(AND(TRIM(C3)="RELEASED IN PROD",Y3<>"Yes"),"Released but Confirmed Deployed? is not Yes",IF(COUNTIF('Rework Log'!$A$3:$A$500,$B3)>0,"",IF(AND(S3<>"",M3<>"",S3<M3),"QA target is before DB Dev target",IF(AND(S3<>"",P3<>"",S3<P3),"QA target is before PBI Dev target",IF(AND(V3<>"",S3<>"",V3<S3),"DPO Approval target is before QA target",IF(AND(Z3<>"",V3<>"",Z3<V3),"Confirmed Deployed date is before DPO Approval target",""))))))))))))))))) | AE3: [Historical, April 2026]: QA found an issue - date calendar dimension broken. Fetwi assigned to fix.
A4: Leaks | B4: RPT_04_Leak Scheduling | C4: RELEASED IN PROD | D4: =IF($B4="","",IF(LEFT($AC4,3)="Yes",IF(LEN($AC4)>5,"Blocked - "&MID($AC4,7,100),"Blocked")&IF(SUMPRODUCT((TRIM('Rework Log'!$A$3:$A$500)=TRIM($B4))*('Rework Log'!$G$3:$G$500<>"Yes")*('Rework Log'!$G$3:$G$500<>"Did not pass re-test"))=0,"",IF(SUMPRODUCT(((TRIM('Rework Log'!$A$3:$A$500)=TRIM($B4))*('Rework Log'!$G$3:$G$500<>"Yes")*('Rework Log'!$G$3:$G$500<>"Did not pass re-test"))*ISNUMBER('Rework Log'!$J$3:$J$500))>0," - fixed, awaiting re-test",IF(SUMPRODUCT(MAX(((TRIM('Rework Log'!$A$3:$A$500)=TRIM($B4))*('Rework Log'!$G$3:$G$500<>"Yes")*('Rework Log'!$G$3:$G$500<>"Did not pass re-test"))*IFERROR('Rework Log'!$I$3:$I$500*1,0)))=0," - unclaimed"," - promised "&TEXT(SUMPRODUCT(MAX(((TRIM('Rework Log'!$A$3:$A$500)=TRIM($B4))*('Rework Log'!$G$3:$G$500<>"Yes")*('Rework Log'!$G$3:$G$500<>"Did not pass re-test"))*IFERROR('Rework Log'!$I$3:$I$500*1,0))),"m/d")))),IF(TRIM(C4)="NOT STARTED",IF(K4="","No plan date set",IF(K4<TODAY(),"Review - planned start passed","On track")),IF(TRIM(C4)="DB Dev",IF(M4="","No target set",IF(AND(M4<TODAY(),O4=""),"Overdue","On track")),IF(TRIM(C4)="PBI Dev",IF(P4="","No target set",IF(AND(P4<TODAY(),R4=""),"Overdue","On track")),IF(TRIM(C4)="QA",IF(S4="","No target set",IF(AND(S4<TODAY(),U4=""),"Overdue","On track")),IF(TRIM(C4)="DPO Approval",IF(V4="","No target set",IF(V4<TODAY(),"Overdue","On track")),IF(TRIM(C4)="RELEASED IN PROD","Delivered","")))))))) -> Delivered | E4: 4 | G4: Sreevarsha | H4: Sarath | I4: Preety | K4: 46142 | L4: April | M4: 46115 | O4: 46115 | P4: 46120 | R4: 46120 | S4: 46122 | U4: 46122 | X4: Kelvin Hu | Y4: Yes | Z4: 46122 | AC4: No | AD4: =IF($B4="","",IF(AND(LEFT($AC4,3)="Yes",SUMPRODUCT((TRIM('Rework Log'!$A$3:$A$500)=TRIM($B4))*('Rework Log'!$G$3:$G$500<>"Yes")*('Rework Log'!$G$3:$G$500<>"Did not pass re-test"))=0),"Blocked - log it on Rework Log",IF(AND(LEFT($AC4,3)<>"Yes",SUMPRODUCT((TRIM('Rework Log'!$A$3:$A$500)=TRIM($B4))*('Rework Log'!$G$3:$G$500<>"Yes")*('Rework Log'!$G$3:$G$500<>"Did not pass re-test"))>0),"Open rework row - mark Blocked? or close it",IF(AND(LEFT($AC4,3)<>"Yes",SUMPRODUCT((TRIM('Rework Log'!$A$3:$A$500)=TRIM($B4))*('Rework Log'!$G$3:$G$500<>"Yes")*('Rework Log'!$G$3:$G$500<>"Did not pass re-test"))=0,COUNTIF('Rework Log'!$A$3:$A$500,$B4)>0,IFERROR(INDEX('Rework Log'!$G:$G,SUMPRODUCT(MAX((TRIM('Rework Log'!$A$3:$A$500)=TRIM($B4))*ROW('Rework Log'!$A$3:$A$500)))),"")="Did not pass re-test"),"Last fix rejected - re-block or log next attempt",IF(AND(LEFT($AC4,3)="Yes",ISNUMBER(SEARCH("needs DB Dev",$AC4)),O4<>"",SUMPRODUCT(MAX(((TRIM('Rework Log'!$A$3:$A$500)=TRIM($B4))*('Rework Log'!$G$3:$G$500<>"Yes")*('Rework Log'!$G$3:$G$500<>"Did not pass re-test"))*IFERROR('Rework Log'!$I$3:$I$500*1,0)))>0),"Move old DB Dev completion date to Rework Log (col H)",IF(AND(LEFT($AC4,3)="Yes",ISNUMBER(SEARCH("needs PBI Dev",$AC4)),R4<>"",SUMPRODUCT(MAX(((TRIM('Rework Log'!$A$3:$A$500)=TRIM($B4))*('Rework Log'!$G$3:$G$500<>"Yes")*('Rework Log'!$G$3:$G$500<>"Did not pass re-test"))*IFERROR('Rework Log'!$I$3:$I$500*1,0)))>0),"Move old PBI Dev completion date to Rework Log (col H)",IF(AND(LEFT($AC4,3)="Yes",ISNUMBER(SEARCH("needs QA",$AC4)),U4<>"",SUMPRODUCT(MAX(((TRIM('Rework Log'!$A$3:$A$500)=TRIM($B4))*('Rework Log'!$G$3:$G$500<>"Yes")*('Rework Log'!$G$3:$G$500<>"Did not pass re-test"))*IFERROR('Rework Log'!$I$3:$I$500*1,0)))>0),"Move old QA completion date to Rework Log (col H)",IF(AND(LEFT($AC4,3)="Yes",ISNUMBER(SEARCH("needs DB Dev",$AC4)),TRIM(C4)<>"DB Dev"),"Set Current Status back to DB Dev",IF(AND(LEFT($AC4,3)="Yes",ISNUMBER(SEARCH("needs PBI Dev",$AC4)),TRIM(C4)<>"PBI Dev"),"Set Current Status back to PBI Dev",IF(AND(LEFT($AC4,3)="Yes",ISNUMBER(SEARCH("needs QA",$AC4)),TRIM(C4)<>"QA"),"Set Current Status back to QA",IF(COUNTIF($B$2:$B$500,$B4)>1,"Duplicate name - check row",IF(AND(TRIM(C4)="RELEASED IN PROD",Y4<>"Yes"),"Released but Confirmed Deployed? is not Yes",IF(COUNTIF('Rework Log'!$A$3:$A$500,$B4)>0,"",IF(AND(S4<>"",M4<>"",S4<M4),"QA target is before DB Dev target",IF(AND(S4<>"",P4<>"",S4<P4),"QA target is before PBI Dev target",IF(AND(V4<>"",S4<>"",V4<S4),"DPO Approval target is before QA target",IF(AND(Z4<>"",V4<>"",Z4<V4),"Confirmed Deployed date is before DPO Approval target","")))))))))))))))))
A5: Leaks | B5: RPT_04_Leak Days Remaining | C5: RELEASED IN PROD | D5: =IF($B5="","",IF(LEFT($AC5,3)="Yes",IF(LEN($AC5)>5,"Blocked - "&MID($AC5,7,100),"Blocked")&IF(SUMPRODUCT((TRIM('Rework Log'!$A$3:$A$500)=TRIM($B5))*('Rework Log'!$G$3:$G$500<>"Yes")*('Rework Log'!$G$3:$G$500<>"Did not pass re-test"))=0,"",IF(SUMPRODUCT(((TRIM('Rework Log'!$A$3:$A$500)=TRIM($B5))*('Rework Log'!$G$3:$G$500<>"Yes")*('Rework Log'!$G$3:$G$500<>"Did not pass re-test"))*ISNUMBER('Rework Log'!$J$3:$J$500))>0," - fixed, awaiting re-test",IF(SUMPRODUCT(MAX(((TRIM('Rework Log'!$A$3:$A$500)=TRIM($B5))*('Rework Log'!$G$3:$G$500<>"Yes")*('Rework Log'!$G$3:$G$500<>"Did not pass re-test"))*IFERROR('Rework Log'!$I$3:$I$500*1,0)))=0," - unclaimed"," - promised "&TEXT(SUMPRODUCT(MAX(((TRIM('Rework Log'!$A$3:$A$500)=TRIM($B5))*('Rework Log'!$G$3:$G$500<>"Yes")*('Rework Log'!$G$3:$G$500<>"Did not pass re-test"))*IFERROR('Rework Log'!$I$3:$I$500*1,0))),"m/d")))),IF(TRIM(C5)="NOT STARTED",IF(K5="","No plan date set",IF(K5<TODAY(),"Review - planned start passed","On track")),IF(TRIM(C5)="DB Dev",IF(M5="","No target set",IF(AND(M5<TODAY(),O5=""),"Overdue","On track")),IF(TRIM(C5)="PBI Dev",IF(P5="","No target set",IF(AND(P5<TODAY(),R5=""),"Overdue","On track")),IF(TRIM(C5)="QA",IF(S5="","No target set",IF(AND(S5<TODAY(),U5=""),"Overdue","On track")),IF(TRIM(C5)="DPO Approval",IF(V5="","No target set",IF(V5<TODAY(),"Overdue","On track")),IF(TRIM(C5)="RELEASED IN PROD","Delivered","")))))))) -> Delivered | E5: 5 | G5: Siva | H5: Navya | I5: Preety | K5: 46142 | L5: April | M5: 46115 | O5: 46115 | P5: 46126 | R5: 46126 | S5: 46122 | U5: 46122 | X5: Kelvin Hu | Y5: Yes | Z5: 46122 | AA5: https://app.powerbi.com/groups/me/apps/eedba83d-be9a-45f9-9504-7bfa41e6051a/reports/8b9ae445-3a30-4ae6-a3fa-7a6d8e7ef349/d97da6159d0c87677529?experience=power-bi | AB5: https://app.powerbi.com/groups/me/apps/2c7180b1-0d3d-45be-979e-f7dc86b3557d/reports/848ce65a-4e47-422b-aae5-7ea9e7d68a5f/d97da6159d0c87677529?ctid=f98a6a53-25f3-4212-901c-c7787fcd3495&experience=power-bi | AC5: No | AD5: =IF($B5="","",IF(AND(LEFT($AC5,3)="Yes",SUMPRODUCT((TRIM('Rework Log'!$A$3:$A$500)=TRIM($B5))*('Rework Log'!$G$3:$G$500<>"Yes")*('Rework Log'!$G$3:$G$500<>"Did not pass re-test"))=0),"Blocked - log it on Rework Log",IF(AND(LEFT($AC5,3)<>"Yes",SUMPRODUCT((TRIM('Rework Log'!$A$3:$A$500)=TRIM($B5))*('Rework Log'!$G$3:$G$500<>"Yes")*('Rework Log'!$G$3:$G$500<>"Did not pass re-test"))>0),"Open rework row - mark Blocked? or close it",IF(AND(LEFT($AC5,3)<>"Yes",SUMPRODUCT((TRIM('Rework Log'!$A$3:$A$500)=TRIM($B5))*('Rework Log'!$G$3:$G$500<>"Yes")*('Rework Log'!$G$3:$G$500<>"Did not pass re-test"))=0,COUNTIF('Rework Log'!$A$3:$A$500,$B5)>0,IFERROR(INDEX('Rework Log'!$G:$G,SUMPRODUCT(MAX((TRIM('Rework Log'!$A$3:$A$500)=TRIM($B5))*ROW('Rework Log'!$A$3:$A$500)))),"")="Did not pass re-test"),"Last fix rejected - re-block or log next attempt",IF(AND(LEFT($AC5,3)="Yes",ISNUMBER(SEARCH("needs DB Dev",$AC5)),O5<>"",SUMPRODUCT(MAX(((TRIM('Rework Log'!$A$3:$A$500)=TRIM($B5))*('Rework Log'!$G$3:$G$500<>"Yes")*('Rework Log'!$G$3:$G$500<>"Did not pass re-test"))*IFERROR('Rework Log'!$I$3:$I$500*1,0)))>0),"Move old DB Dev completion date to Rework Log (col H)",IF(AND(LEFT($AC5,3)="Yes",ISNUMBER(SEARCH("needs PBI Dev",$AC5)),R5<>"",SUMPRODUCT(MAX(((TRIM('Rework Log'!$A$3:$A$500)=TRIM($B5))*('Rework Log'!$G$3:$G$500<>"Yes")*('Rework Log'!$G$3:$G$500<>"Did not pass re-test"))*IFERROR('Rework Log'!$I$3:$I$500*1,0)))>0),"Move old PBI Dev completion date to Rework Log (col H)",IF(AND(LEFT($AC5,3)="Yes",ISNUMBER(SEARCH("needs QA",$AC5)),U5<>"",SUMPRODUCT(MAX(((TRIM('Rework Log'!$A$3:$A$500)=TRIM($B5))*('Rework Log'!$G$3:$G$500<>"Yes")*('Rework Log'!$G$3:$G$500<>"Did not pass re-test"))*IFERROR('Rework Log'!$I$3:$I$500*1,0)))>0),"Move old QA completion date to Rework Log (col H)",IF(AND(LEFT($AC5,3)="Yes",ISNUMBER(SEARCH("needs DB Dev",$AC5)),TRIM(C5)<>"DB Dev"),"Set Current Status back to DB Dev",IF(AND(LEFT($AC5,3)="Yes",ISNUMBER(SEARCH("needs PBI Dev",$AC5)),TRIM(C5)<>"PBI Dev"),"Set Current Status back to PBI Dev",IF(AND(LEFT($AC5,3)="Yes",ISNUMBER(SEARCH("needs QA",$AC5)),TRIM(C5)<>"QA"),"Set Current Status back to QA",IF(COUNTIF($B$2:$B$500,$B5)>1,"Duplicate name - check row",IF(AND(TRIM(C5)="RELEASED IN PROD",Y5<>"Yes"),"Released but Confirmed Deployed? is not Yes",IF(COUNTIF('Rework Log'!$A$3:$A$500,$B5)>0,"",IF(AND(S5<>"",M5<>"",S5<M5),"QA target is before DB Dev target",IF(AND(S5<>"",P5<>"",S5<P5),"QA target is before PBI Dev target",IF(AND(V5<>"",S5<>"",V5<S5),"DPO Approval target is before QA target",IF(AND(Z5<>"",V5<>"",Z5<V5),"Confirmed Deployed date is before DPO Approval target",""))))))))))))))))) -> QA target is before PBI Dev target | AE5: 16/04 - Testing completed in QA and created defect https://jira.prod.nationalgrid.com/browse/GDMP-2186; ETA -04/24
A6: Leaks | B6: RPT_04_Cleared Leaks | C6: RELEASED IN PROD | D6: =IF($B6="","",IF(LEFT($AC6,3)="Yes",IF(LEN($AC6)>5,"Blocked - "&MID($AC6,7,100),"Blocked")&IF(SUMPRODUCT((TRIM('Rework Log'!$A$3:$A$500)=TRIM($B6))*('Rework Log'!$G$3:$G$500<>"Yes")*('Rework Log'!$G$3:$G$500<>"Did not pass re-test"))=0,"",IF(SUMPRODUCT(((TRIM('Rework Log'!$A$3:$A$500)=TRIM($B6))*('Rework Log'!$G$3:$G$500<>"Yes")*('Rework Log'!$G$3:$G$500<>"Did not pass re-test"))*ISNUMBER('Rework Log'!$J$3:$J$500))>0," - fixed, awaiting re-test",IF(SUMPRODUCT(MAX(((TRIM('Rework Log'!$A$3:$A$500)=TRIM($B6))*('Rework Log'!$G$3:$G$500<>"Yes")*('Rework Log'!$G$3:$G$500<>"Did not pass re-test"))*IFERROR('Rework Log'!$I$3:$I$500*1,0)))=0," - unclaimed"," - promised "&TEXT(SUMPRODUCT(MAX(((TRIM('Rework Log'!$A$3:$A$500)=TRIM($B6))*('Rework Log'!$G$3:$G$500<>"Yes")*('Rework Log'!$G$3:$G$500<>"Did not pass re-test"))*IFERROR('Rework Log'!$I$3:$I$500*1,0))),"m/d")))),IF(TRIM(C6)="NOT STARTED",IF(K6="","No plan date set",IF(K6<TODAY(),"Review - planned start passed","On track")),IF(TRIM(C6)="DB Dev",IF(M6="","No target set",IF(AND(M6<TODAY(),O6=""),"Overdue","On track")),IF(TRIM(C6)="PBI Dev",IF(P6="","No target set",IF(AND(P6<TODAY(),R6=""),"Overdue","On track")),IF(TRIM(C6)="QA",IF(S6="","No target set",IF(AND(S6<TODAY(),U6=""),"Overdue","On track")),IF(TRIM(C6)="DPO Approval",IF(V6="","No target set",IF(V6<TODAY(),"Overdue","On track")),IF(TRIM(C6)="RELEASED IN PROD","Delivered","")))))))) -> Delivered | E6: 3 | G6: Sreevarsha | H6: Sarath | I6: Preety | K6: 46142 | L6: April | M6: 46115 | O6: 46115 | P6: 46120 | R6: 46120 | S6: 46122 | U6: 46122 | X6: Kelvin Hu | Y6: Yes | Z6: 46122 | AA6: https://app.powerbi.com/groups/me/apps/eedba83d-be9a-45f9-9504-7bfa41e6051a/reports/938a9ba1-8138-440e-842a-d9a679933d8c/44bb4fce98fafb2cace2?experience=power-bi | AB6: https://app.powerbi.com/groups/me/apps/2c7180b1-0d3d-45be-979e-f7dc86b3557d/reports/677c6418-6db8-4ebf-9323-65be4cb2c960/ea184ec020032ecbdd43?ctid=f98a6a53-25f3-4212-901c-c7787fcd3495&experience=power-bi | AC6: No | AD6: =IF($B6="","",IF(AND(LEFT($AC6,3)="Yes",SUMPRODUCT((TRIM('Rework Log'!$A$3:$A$500)=TRIM($B6))*('Rework Log'!$G$3:$G$500<>"Yes")*('Rework Log'!$G$3:$G$500<>"Did not pass re-test"))=0),"Blocked - log it on Rework Log",IF(AND(LEFT($AC6,3)<>"Yes",SUMPRODUCT((TRIM('Rework Log'!$A$3:$A$500)=TRIM($B6))*('Rework Log'!$G$3:$G$500<>"Yes")*('Rework Log'!$G$3:$G$500<>"Did not pass re-test"))>0),"Open rework row - mark Blocked? or close it",IF(AND(LEFT($AC6,3)<>"Yes",SUMPRODUCT((TRIM('Rework Log'!$A$3:$A$500)=TRIM($B6))*('Rework Log'!$G$3:$G$500<>"Yes")*('Rework Log'!$G$3:$G$500<>"Did not pass re-test"))=0,COUNTIF('Rework Log'!$A$3:$A$500,$B6)>0,IFERROR(INDEX('Rework Log'!$G:$G,SUMPRODUCT(MAX((TRIM('Rework Log'!$A$3:$A$500)=TRIM($B6))*ROW('Rework Log'!$A$3:$A$500)))),"")="Did not pass re-test"),"Last fix rejected - re-block or log next attempt",IF(AND(LEFT($AC6,3)="Yes",ISNUMBER(SEARCH("needs DB Dev",$AC6)),O6<>"",SUMPRODUCT(MAX(((TRIM('Rework Log'!$A$3:$A$500)=TRIM($B6))*('Rework Log'!$G$3:$G$500<>"Yes")*('Rework Log'!$G$3:$G$500<>"Did not pass re-test"))*IFERROR('Rework Log'!$I$3:$I$500*1,0)))>0),"Move old DB Dev completion date to Rework Log (col H)",IF(AND(LEFT($AC6,3)="Yes",ISNUMBER(SEARCH("needs PBI Dev",$AC6)),R6<>"",SUMPRODUCT(MAX(((TRIM('Rework Log'!$A$3:$A$500)=TRIM($B6))*('Rework Log'!$G$3:$G$500<>"Yes")*('Rework Log'!$G$3:$G$500<>"Did not pass re-test"))*IFERROR('Rework Log'!$I$3:$I$500*1,0)))>0),"Move old PBI Dev completion date to Rework Log (col H)",IF(AND(LEFT($AC6,3)="Yes",ISNUMBER(SEARCH("needs QA",$AC6)),U6<>"",SUMPRODUCT(MAX(((TRIM('Rework Log'!$A$3:$A$500)=TRIM($B6))*('Rework Log'!$G$3:$G$500<>"Yes")*('Rework Log'!$G$3:$G$500<>"Did not pass re-test"))*IFERROR('Rework Log'!$I$3:$I$500*1,0)))>0),"Move old QA completion date to Rework Log (col H)",IF(AND(LEFT($AC6,3)="Yes",ISNUMBER(SEARCH("needs DB Dev",$AC6)),TRIM(C6)<>"DB Dev"),"Set Current Status back to DB Dev",IF(AND(LEFT($AC6,3)="Yes",ISNUMBER(SEARCH("needs PBI Dev",$AC6)),TRIM(C6)<>"PBI Dev"),"Set Current Status back to PBI Dev",IF(AND(LEFT($AC6,3)="Yes",ISNUMBER(SEARCH("needs QA",$AC6)),TRIM(C6)<>"QA"),"Set Current Status back to QA",IF(COUNTIF($B$2:$B$500,$B6)>1,"Duplicate name - check row",IF(AND(TRIM(C6)="RELEASED IN PROD",Y6<>"Yes"),"Released but Confirmed Deployed? is not Yes",IF(COUNTIF('Rework Log'!$A$3:$A$500,$B6)>0,"",IF(AND(S6<>"",M6<>"",S6<M6),"QA target is before DB Dev target",IF(AND(S6<>"",P6<>"",S6<P6),"QA target is before PBI Dev target",IF(AND(V6<>"",S6<>"",V6<S6),"DPO Approval target is before QA target",IF(AND(Z6<>"",V6<>"",Z6<V6),"Confirmed Deployed date is before DPO Approval target",""))))))))))))))))) | AE6: [Historical, April 2026]: L_GRO_NUMBER columns had an issue in QA - DB team assigned to fix.
A7: Leaks | B7: RPT_04_Leaks Repaired Detail | C7: RELEASED IN PROD | D7: =IF($B7="","",IF(LEFT($AC7,3)="Yes",IF(LEN($AC7)>5,"Blocked - "&MID($AC7,7,100),"Blocked")&IF(SUMPRODUCT((TRIM('Rework Log'!$A$3:$A$500)=TRIM($B7))*('Rework Log'!$G$3:$G$500<>"Yes")*('Rework Log'!$G$3:$G$500<>"Did not pass re-test"))=0,"",IF(SUMPRODUCT(((TRIM('Rework Log'!$A$3:$A$500)=TRIM($B7))*('Rework Log'!$G$3:$G$500<>"Yes")*('Rework Log'!$G$3:$G$500<>"Did not pass re-test"))*ISNUMBER('Rework Log'!$J$3:$J$500))>0," - fixed, awaiting re-test",IF(SUMPRODUCT(MAX(((TRIM('Rework Log'!$A$3:$A$500)=TRIM($B7))*('Rework Log'!$G$3:$G$500<>"Yes")*('Rework Log'!$G$3:$G$500<>"Did not pass re-test"))*IFERROR('Rework Log'!$I$3:$I$500*1,0)))=0," - unclaimed"," - promised "&TEXT(SUMPRODUCT(MAX(((TRIM('Rework Log'!$A$3:$A$500)=TRIM($B7))*('Rework Log'!$G$3:$G$500<>"Yes")*('Rework Log'!$G$3:$G$500<>"Did not pass re-test"))*IFERROR('Rework Log'!$I$3:$I$500*1,0))),"m/d")))),IF(TRIM(C7)="NOT STARTED",IF(K7="","No plan date set",IF(K7<TODAY(),"Review - planned start passed","On track")),IF(TRIM(C7)="DB Dev",IF(M7="","No target set",IF(AND(M7<TODAY(),O7=""),"Overdue","On track")),IF(TRIM(C7)="PBI Dev",IF(P7="","No target set",IF(AND(P7<TODAY(),R7=""),"Overdue","On track")),IF(TRIM(C7)="QA",IF(S7="","No target set",IF(AND(S7<TODAY(),U7=""),"Overdue","On track")),IF(TRIM(C7)="DPO Approval",IF(V7="","No target set",IF(V7<TODAY(),"Overdue","On track")),IF(TRIM(C7)="RELEASED IN PROD","Delivered","")))))))) -> Delivered | E7: 6 | G7: Rupa | H7: Navya | I7: Preety | K7: 46142 | L7: April | M7: 46115 | O7: 46115 | P7: 46126 | R7: 46126 | S7: 46122 | U7: 46122 | X7: Kelvin Hu | Y7: Yes | Z7: 46122 | AA7: https://app.powerbi.com/groups/me/apps/eedba83d-be9a-45f9-9504-7bfa41e6051a/reports/cbaf2155-2cf3-4377-8af2-7e07a896e887/ea184ec020032ecbdd43?experience=power-bi | AB7: https://app.powerbi.com/groups/me/apps/2c7180b1-0d3d-45be-979e-f7dc86b3557d/reports/9c6d5e21-4e57-4a64-9973-61ff3717468e/ea184ec020032ecbdd43?ctid=f98a6a53-25f3-4212-901c-c7787fcd3495&experience=power-bi | AC7: No | AD7: =IF($B7="","",IF(AND(LEFT($AC7,3)="Yes",SUMPRODUCT((TRIM('Rework Log'!$A$3:$A$500)=TRIM($B7))*('Rework Log'!$G$3:$G$500<>"Yes")*('Rework Log'!$G$3:$G$500<>"Did not pass re-test"))=0),"Blocked - log it on Rework Log",IF(AND(LEFT($AC7,3)<>"Yes",SUMPRODUCT((TRIM('Rework Log'!$A$3:$A$500)=TRIM($B7))*('Rework Log'!$G$3:$G$500<>"Yes")*('Rework Log'!$G$3:$G$500<>"Did not pass re-test"))>0),"Open rework row - mark Blocked? or close it",IF(AND(LEFT($AC7,3)<>"Yes",SUMPRODUCT((TRIM('Rework Log'!$A$3:$A$500)=TRIM($B7))*('Rework Log'!$G$3:$G$500<>"Yes")*('Rework Log'!$G$3:$G$500<>"Did not pass re-test"))=0,COUNTIF('Rework Log'!$A$3:$A$500,$B7)>0,IFERROR(INDEX('Rework Log'!$G:$G,SUMPRODUCT(MAX((TRIM('Rework Log'!$A$3:$A$500)=TRIM($B7))*ROW('Rework Log'!$A$3:$A$500)))),"")="Did not pass re-test"),"Last fix rejected - re-block or log next attempt",IF(AND(LEFT($AC7,3)="Yes",ISNUMBER(SEARCH("needs DB Dev",$AC7)),O7<>"",SUMPRODUCT(MAX(((TRIM('Rework Log'!$A$3:$A$500)=TRIM($B7))*('Rework Log'!$G$3:$G$500<>"Yes")*('Rework Log'!$G$3:$G$500<>"Did not pass re-test"))*IFERROR('Rework Log'!$I$3:$I$500*1,0)))>0),"Move old DB Dev completion date to Rework Log (col H)",IF(AND(LEFT($AC7,3)="Yes",ISNUMBER(SEARCH("needs PBI Dev",$AC7)),R7<>"",SUMPRODUCT(MAX(((TRIM('Rework Log'!$A$3:$A$500)=TRIM($B7))*('Rework Log'!$G$3:$G$500<>"Yes")*('Rework Log'!$G$3:$G$500<>"Did not pass re-test"))*IFERROR('Rework Log'!$I$3:$I$500*1,0)))>0),"Move old PBI Dev completion date to Rework Log (col H)",IF(AND(LEFT($AC7,3)="Yes",ISNUMBER(SEARCH("needs QA",$AC7)),U7<>"",SUMPRODUCT(MAX(((TRIM('Rework Log'!$A$3:$A$500)=TRIM($B7))*('Rework Log'!$G$3:$G$500<>"Yes")*('Rework Log'!$G$3:$G$500<>"Did not pass re-test"))*IFERROR('Rework Log'!$I$3:$I$500*1,0)))>0),"Move old QA completion date to Rework Log (col H)",IF(AND(LEFT($AC7,3)="Yes",ISNUMBER(SEARCH("needs DB Dev",$AC7)),TRIM(C7)<>"DB Dev"),"Set Current Status back to DB Dev",IF(AND(LEFT($AC7,3)="Yes",ISNUMBER(SEARCH("needs PBI Dev",$AC7)),TRIM(C7)<>"PBI Dev"),"Set Current Status back to PBI Dev",IF(AND(LEFT($AC7,3)="Yes",ISNUMBER(SEARCH("needs QA",$AC7)),TRIM(C7)<>"QA"),"Set Current Status back to QA",IF(COUNTIF($B$2:$B$500,$B7)>1,"Duplicate name - check row",IF(AND(TRIM(C7)="RELEASED IN PROD",Y7<>"Yes"),"Released but Confirmed Deployed? is not Yes",IF(COUNTIF('Rework Log'!$A$3:$A$500,$B7)>0,"",IF(AND(S7<>"",M7<>"",S7<M7),"QA target is before DB Dev target",IF(AND(S7<>"",P7<>"",S7<P7),"QA target is before PBI Dev target",IF(AND(V7<>"",S7<>"",V7<S7),"DPO Approval target is before QA target",IF(AND(Z7<>"",V7<>"",Z7<V7),"Confirmed Deployed date is before DPO Approval target",""))))))))))))))))) -> QA target is before PBI Dev target | AE7: 21/4 Testing completed in QA and defect raised https://jira.prod.nationalgrid.com/browse/GDMP-2190; Report ready for testing 04/23/2026
A8: Leaks | B8: RPT_04_Leaks Aging | C8: RELEASED IN PROD | D8: =IF($B8="","",IF(LEFT($AC8,3)="Yes",IF(LEN($AC8)>5,"Blocked - "&MID($AC8,7,100),"Blocked")&IF(SUMPRODUCT((TRIM('Rework Log'!$A$3:$A$500)=TRIM($B8))*('Rework Log'!$G$3:$G$500<>"Yes")*('Rework Log'!$G$3:$G$500<>"Did not pass re-test"))=0,"",IF(SUMPRODUCT(((TRIM('Rework Log'!$A$3:$A$500)=TRIM($B8))*('Rework Log'!$G$3:$G$500<>"Yes")*('Rework Log'!$G$3:$G$500<>"Did not pass re-test"))*ISNUMBER('Rework Log'!$J$3:$J$500))>0," - fixed, awaiting re-test",IF(SUMPRODUCT(MAX(((TRIM('Rework Log'!$A$3:$A$500)=TRIM($B8))*('Rework Log'!$G$3:$G$500<>"Yes")*('Rework Log'!$G$3:$G$500<>"Did not pass re-test"))*IFERROR('Rework Log'!$I$3:$I$500*1,0)))=0," - unclaimed"," - promised "&TEXT(SUMPRODUCT(MAX(((TRIM('Rework Log'!$A$3:$A$500)=TRIM($B8))*('Rework Log'!$G$3:$G$500<>"Yes")*('Rework Log'!$G$3:$G$500<>"Did not pass re-test"))*IFERROR('Rework Log'!$I$3:$I$500*1,0))),"m/d")))),IF(TRIM(C8)="NOT STARTED",IF(K8="","No plan date set",IF(K8<TODAY(),"Review - planned start passed","On track")),IF(TRIM(C8)="DB Dev",IF(M8="","No target set",IF(AND(M8<TODAY(),O8=""),"Overdue","On track")),IF(TRIM(C8)="PBI Dev",IF(P8="","No target set",IF(AND(P8<TODAY(),R8=""),"Overdue","On track")),IF(TRIM(C8)="QA",IF(S8="","No target set",IF(AND(S8<TODAY(),U8=""),"Overdue","On track")),IF(TRIM(C8)="DPO Approval",IF(V8="","No target set",IF(V8<TODAY(),"Overdue","On track")),IF(TRIM(C8)="RELEASED IN PROD","Delivered","")))))))) -> Delivered | E8: 7 | G8: Sreevarsha | H8: Navya | I8: Preety | K8: 46142 | L8: April | M8: 46122 | O8: 46122 | P8: 46126 | R8: 46126 | S8: 46122 | U8: 46122 | X8: Kelvin Hu | Y8: Yes | Z8: 46122 | AA8: https://app.powerbi.com/groups/me/apps/eedba83d-be9a-45f9-9504-7bfa41e6051a/reports/383c1502-9c3c-4fa0-a321-321cfed3b4a1/ReportSection1e63b8fbeb9ea54074e1?experience=power-bi | AB8: https://app.powerbi.com/groups/me/apps/2c7180b1-0d3d-45be-979e-f7dc86b3557d/reports/b7f15195-22d6-4ac4-8982-a8cadb215cbf/ReportSection1e63b8fbeb9ea54074e1?ctid=f98a6a53-25f3-4212-901c-c7787fcd3495&experience=power-bi | AC8: No | AD8: =IF($B8="","",IF(AND(LEFT($AC8,3)="Yes",SUMPRODUCT((TRIM('Rework Log'!$A$3:$A$500)=TRIM($B8))*('Rework Log'!$G$3:$G$500<>"Yes")*('Rework Log'!$G$3:$G$500<>"Did not pass re-test"))=0),"Blocked - log it on Rework Log",IF(AND(LEFT($AC8,3)<>"Yes",SUMPRODUCT((TRIM('Rework Log'!$A$3:$A$500)=TRIM($B8))*('Rework Log'!$G$3:$G$500<>"Yes")*('Rework Log'!$G$3:$G$500<>"Did not pass re-test"))>0),"Open rework row - mark Blocked? or close it",IF(AND(LEFT($AC8,3)<>"Yes",SUMPRODUCT((TRIM('Rework Log'!$A$3:$A$500)=TRIM($B8))*('Rework Log'!$G$3:$G$500<>"Yes")*('Rework Log'!$G$3:$G$500<>"Did not pass re-test"))=0,COUNTIF('Rework Log'!$A$3:$A$500,$B8)>0,IFERROR(INDEX('Rework Log'!$G:$G,SUMPRODUCT(MAX((TRIM('Rework Log'!$A$3:$A$500)=TRIM($B8))*ROW('Rework Log'!$A$3:$A$500)))),"")="Did not pass re-test"),"Last fix rejected - re-block or log next attempt",IF(AND(LEFT($AC8,3)="Yes",ISNUMBER(SEARCH("needs DB Dev",$AC8)),O8<>"",SUMPRODUCT(MAX(((TRIM('Rework Log'!$A$3:$A$500)=TRIM($B8))*('Rework Log'!$G$3:$G$500<>"Yes")*('Rework Log'!$G$3:$G$500<>"Did not pass re-test"))*IFERROR('Rework Log'!$I$3:$I$500*1,0)))>0),"Move old DB Dev completion date to Rework Log (col H)",IF(AND(LEFT($AC8,3)="Yes",ISNUMBER(SEARCH("needs PBI Dev",$AC8)),R8<>"",SUMPRODUCT(MAX(((TRIM('Rework Log'!$A$3:$A$500)=TRIM($B8))*('Rework Log'!$G$3:$G$500<>"Yes")*('Rework Log'!$G$3:$G$500<>"Did not pass re-test"))*IFERROR('Rework Log'!$I$3:$I$500*1,0)))>0),"Move old PBI Dev completion date to Rework Log (col H)",IF(AND(LEFT($AC8,3)="Yes",ISNUMBER(SEARCH("needs QA",$AC8)),U8<>"",SUMPRODUCT(MAX(((TRIM('Rework Log'!$A$3:$A$500)=TRIM($B8))*('Rework Log'!$G$3:$G$500<>"Yes")*('Rework Log'!$G$3:$G$500<>"Did not pass re-test"))*IFERROR('Rework Log'!$I$3:$I$500*1,0)))>0),"Move old QA completion date to Rework Log (col H)",IF(AND(LEFT($AC8,3)="Yes",ISNUMBER(SEARCH("needs DB Dev",$AC8)),TRIM(C8)<>"DB Dev"),"Set Current Status back to DB Dev",IF(AND(LEFT($AC8,3)="Yes",ISNUMBER(SEARCH("needs PBI Dev",$AC8)),TRIM(C8)<>"PBI Dev"),"Set Current Status back to PBI Dev",IF(AND(LEFT($AC8,3)="Yes",ISNUMBER(SEARCH("needs QA",$AC8)),TRIM(C8)<>"QA"),"Set Current Status back to QA",IF(COUNTIF($B$2:$B$500,$B8)>1,"Duplicate name - check row",IF(AND(TRIM(C8)="RELEASED IN PROD",Y8<>"Yes"),"Released but Confirmed Deployed? is not Yes",IF(COUNTIF('Rework Log'!$A$3:$A$500,$B8)>0,"",IF(AND(S8<>"",M8<>"",S8<M8),"QA target is before DB Dev target",IF(AND(S8<>"",P8<>"",S8<P8),"QA target is before PBI Dev target",IF(AND(V8<>"",S8<>"",V8<S8),"DPO Approval target is before QA target",IF(AND(Z8<>"",V8<>"",Z8<V8),"Confirmed Deployed date is before DPO Approval target",""))))))))))))))))) -> QA target is before PBI Dev target
A9: Leaks | B9: RPT_04_Prior Leak Readings | C9: RELEASED IN PROD | D9: =IF($B9="","",IF(LEFT($AC9,3)="Yes",IF(LEN($AC9)>5,"Blocked - "&MID($AC9,7,100),"Blocked")&IF(SUMPRODUCT((TRIM('Rework Log'!$A$3:$A$500)=TRIM($B9))*('Rework Log'!$G$3:$G$500<>"Yes")*('Rework Log'!$G$3:$G$500<>"Did not pass re-test"))=0,"",IF(SUMPRODUCT(((TRIM('Rework Log'!$A$3:$A$500)=TRIM($B9))*('Rework Log'!$G$3:$G$500<>"Yes")*('Rework Log'!$G$3:$G$500<>"Did not pass re-test"))*ISNUMBER('Rework Log'!$J$3:$J$500))>0," - fixed, awaiting re-test",IF(SUMPRODUCT(MAX(((TRIM('Rework Log'!$A$3:$A$500)=TRIM($B9))*('Rework Log'!$G$3:$G$500<>"Yes")*('Rework Log'!$G$3:$G$500<>"Did not pass re-test"))*IFERROR('Rework Log'!$I$3:$I$500*1,0)))=0," - unclaimed"," - promised "&TEXT(SUMPRODUCT(MAX(((TRIM('Rework Log'!$A$3:$A$500)=TRIM($B9))*('Rework Log'!$G$3:$G$500<>"Yes")*('Rework Log'!$G$3:$G$500<>"Did not pass re-test"))*IFERROR('Rework Log'!$I$3:$I$500*1,0))),"m/d")))),IF(TRIM(C9)="NOT STARTED",IF(K9="","No plan date set",IF(K9<TODAY(),"Review - planned start passed","On track")),IF(TRIM(C9)="DB Dev",IF(M9="","No target set",IF(AND(M9<TODAY(),O9=""),"Overdue","On track")),IF(TRIM(C9)="PBI Dev",IF(P9="","No target set",IF(AND(P9<TODAY(),R9=""),"Overdue","On track")),IF(TRIM(C9)="QA",IF(S9="","No target set",IF(AND(S9<TODAY(),U9=""),"Overdue","On track")),IF(TRIM(C9)="DPO Approval",IF(V9="","No target set",IF(V9<TODAY(),"Overdue","On track")),IF(TRIM(C9)="RELEASED IN PROD","Delivered","")))))))) -> Delivered | E9: 9 | G9: Siddu | H9: Navya | I9: Preety | K9: 46142 | L9: April | M9: 46122 | O9: 46122 | P9: 46126 | R9: 46126 | S9: 46122 | U9: 46122 | X9: Kelvin Hu | Y9: Yes | Z9: 46122 | AA9: https://app.powerbi.com/groups/me/apps/7767030c-f4c8-4488-b3cb-36a860cb6ff2/reports/acc74ccc-08b7-420d-b64e-5e4d786ac711/ReportSection6d915001f68ea4805272?experience=power-bi | AB9: https://app.powerbi.com/groups/me/apps/5b29b0dd-a398-4801-84ce-f3a7d8435827/reports/5a06a5bd-88fb-4024-8841-570da23785ad/ReportSection6d915001f68ea4805272?ctid=f98a6a53-25f3-4212-901c-c7787fcd3495&experience=power-bi | AC9: No | AD9: =IF($B9="","",IF(AND(LEFT($AC9,3)="Yes",SUMPRODUCT((TRIM('Rework Log'!$A$3:$A$500)=TRIM($B9))*('Rework Log'!$G$3:$G$500<>"Yes")*('Rework Log'!$G$3:$G$500<>"Did not pass re-test"))=0),"Blocked - log it on Rework Log",IF(AND(LEFT($AC9,3)<>"Yes",SUMPRODUCT((TRIM('Rework Log'!$A$3:$A$500)=TRIM($B9))*('Rework Log'!$G$3:$G$500<>"Yes")*('Rework Log'!$G$3:$G$500<>"Did not pass re-test"))>0),"Open rework row - mark Blocked? or close it",IF(AND(LEFT($AC9,3)<>"Yes",SUMPRODUCT((TRIM('Rework Log'!$A$3:$A$500)=TRIM($B9))*('Rework Log'!$G$3:$G$500<>"Yes")*('Rework Log'!$G$3:$G$500<>"Did not pass re-test"))=0,COUNTIF('Rework Log'!$A$3:$A$500,$B9)>0,IFERROR(INDEX('Rework Log'!$G:$G,SUMPRODUCT(MAX((TRIM('Rework Log'!$A$3:$A$500)=TRIM($B9))*ROW('Rework Log'!$A$3:$A$500)))),"")="Did not pass re-test"),"Last fix rejected - re-block or log next attempt",IF(AND(LEFT($AC9,3)="Yes",ISNUMBER(SEARCH("needs DB Dev",$AC9)),O9<>"",SUMPRODUCT(MAX(((TRIM('Rework Log'!$A$3:$A$500)=TRIM($B9))*('Rework Log'!$G$3:$G$500<>"Yes")*('Rework Log'!$G$3:$G$500<>"Did not pass re-test"))*IFERROR('Rework Log'!$I$3:$I$500*1,0)))>0),"Move old DB Dev completion date to Rework Log (col H)",IF(AND(LEFT($AC9,3)="Yes",ISNUMBER(SEARCH("needs PBI Dev",$AC9)),R9<>"",SUMPRODUCT(MAX(((TRIM('Rework Log'!$A$3:$A$500)=TRIM($B9))*('Rework Log'!$G$3:$G$500<>"Yes")*('Rework Log'!$G$3:$G$500<>"Did not pass re-test"))*IFERROR('Rework Log'!$I$3:$I$500*1,0)))>0),"Move old PBI Dev completion date to Rework Log (col H)",IF(AND(LEFT($AC9,3)="Yes",ISNUMBER(SEARCH("needs QA",$AC9)),U9<>"",SUMPRODUCT(MAX(((TRIM('Rework Log'!$A$3:$A$500)=TRIM($B9))*('Rework Log'!$G$3:$G$500<>"Yes")*('Rework Log'!$G$3:$G$500<>"Did not pass re-test"))*IFERROR('Rework Log'!$I$3:$I$500*1,0)))>0),"Move old QA completion date to Rework Log (col H)",IF(AND(LEFT($AC9,3)="Yes",ISNUMBER(SEARCH("needs DB Dev",$AC9)),TRIM(C9)<>"DB Dev"),"Set Current Status back to DB Dev",IF(AND(LEFT($AC9,3)="Yes",ISNUMBER(SEARCH("needs PBI Dev",$AC9)),TRIM(C9)<>"PBI Dev"),"Set Current Status back to PBI Dev",IF(AND(LEFT($AC9,3)="Yes",ISNUMBER(SEARCH("needs QA",$AC9)),TRIM(C9)<>"QA"),"Set Current Status back to QA",IF(COUNTIF($B$2:$B$500,$B9)>1,"Duplicate name - check row",IF(AND(TRIM(C9)="RELEASED IN PROD",Y9<>"Yes"),"Released but Confirmed Deployed? is not Yes",IF(COUNTIF('Rework Log'!$A$3:$A$500,$B9)>0,"",IF(AND(S9<>"",M9<>"",S9<M9),"QA target is before DB Dev target",IF(AND(S9<>"",P9<>"",S9<P9),"QA target is before PBI Dev target",IF(AND(V9<>"",S9<>"",V9<S9),"DPO Approval target is before QA target",IF(AND(Z9<>"",V9<>"",Z9<V9),"Confirmed Deployed date is before DPO Approval target",""))))))))))))))))) -> QA target is before PBI Dev target
A10: Leaks | B10: RSS_04_Leak Grade Change History | C10: RELEASED IN PROD | D10: =IF($B10="","",IF(LEFT($AC10,3)="Yes",IF(LEN($AC10)>5,"Blocked - "&MID($AC10,7,100),"Blocked")&IF(SUMPRODUCT((TRIM('Rework Log'!$A$3:$A$500)=TRIM($B10))*('Rework Log'!$G$3:$G$500<>"Yes")*('Rework Log'!$G$3:$G$500<>"Did not pass re-test"))=0,"",IF(SUMPRODUCT(((TRIM('Rework Log'!$A$3:$A$500)=TRIM($B10))*('Rework Log'!$G$3:$G$500<>"Yes")*('Rework Log'!$G$3:$G$500<>"Did not pass re-test"))*ISNUMBER('Rework Log'!$J$3:$J$500))>0," - fixed, awaiting re-test",IF(SUMPRODUCT(MAX(((TRIM('Rework Log'!$A$3:$A$500)=TRIM($B10))*('Rework Log'!$G$3:$G$500<>"Yes")*('Rework Log'!$G$3:$G$500<>"Did not pass re-test"))*IFERROR('Rework Log'!$I$3:$I$500*1,0)))=0," - unclaimed"," - promised "&TEXT(SUMPRODUCT(MAX(((TRIM('Rework Log'!$A$3:$A$500)=TRIM($B10))*('Rework Log'!$G$3:$G$500<>"Yes")*('Rework Log'!$G$3:$G$500<>"Did not pass re-test"))*IFERROR('Rework Log'!$I$3:$I$500*1,0))),"m/d")))),IF(TRIM(C10)="NOT STARTED",IF(K10="","No plan date set",IF(K10<TODAY(),"Review - planned start passed","On track")),IF(TRIM(C10)="DB Dev",IF(M10="","No target set",IF(AND(M10<TODAY(),O10=""),"Overdue","On track")),IF(TRIM(C10)="PBI Dev",IF(P10="","No target set",IF(AND(P10<TODAY(),R10=""),"Overdue","On track")),IF(TRIM(C10)="QA",IF(S10="","No target set",IF(AND(S10<TODAY(),U10=""),"Overdue","On track")),IF(TRIM(C10)="DPO Approval",IF(V10="","No target set",IF(V10<TODAY(),"Overdue","On track")),IF(TRIM(C10)="RELEASED IN PROD","Delivered","")))))))) -> Delivered | E10: 8 | G10: Siva | H10: Navya | I10: Preety | K10: 46142 | L10: April | M10: 46127 | O10: 46127 | P10: 46126 | R10: 46126 | S10: 46122 | U10: 46122 | X10: Kelvin Hu | Y10: Yes | Z10: 46122 | AA10: https://app.powerbi.com/groups/me/apps/7767030c-f4c8-4488-b3cb-36a860cb6ff2/reports/6fe40f7b-3dfe-45ee-9f81-cb977321242d/9d7e292e8fb40cfee194?experience=power-bi | AB10: https://app.powerbi.com/groups/me/apps/5b29b0dd-a398-4801-84ce-f3a7d8435827/reports/4268caf5-dcbd-4b00-8518-baf8239fff69/9d7e292e8fb40cfee194?experience=power-bi | AC10: No | AD10: =IF($B10="","",IF(AND(LEFT($AC10,3)="Yes",SUMPRODUCT((TRIM('Rework Log'!$A$3:$A$500)=TRIM($B10))*('Rework Log'!$G$3:$G$500<>"Yes")*('Rework Log'!$G$3:$G$500<>"Did not pass re-test"))=0),"Blocked - log it on Rework Log",IF(AND(LEFT($AC10,3)<>"Yes",SUMPRODUCT((TRIM('Rework Log'!$A$3:$A$500)=TRIM($B10))*('Rework Log'!$G$3:$G$500<>"Yes")*('Rework Log'!$G$3:$G$500<>"Did not pass re-test"))>0),"Open rework row - mark Blocked? or close it",IF(AND(LEFT($AC10,3)<>"Yes",SUMPRODUCT((TRIM('Rework Log'!$A$3:$A$500)=TRIM($B10))*('Rework Log'!$G$3:$G$500<>"Yes")*('Rework Log'!$G$3:$G$500<>"Did not pass re-test"))=0,COUNTIF('Rework Log'!$A$3:$A$500,$B10)>0,IFERROR(INDEX('Rework Log'!$G:$G,SUMPRODUCT(MAX((TRIM('Rework Log'!$A$3:$A$500)=TRIM($B10))*ROW('Rework Log'!$A$3:$A$500)))),"")="Did not pass re-test"),"Last fix rejected - re-block or log next attempt",IF(AND(LEFT($AC10,3)="Yes",ISNUMBER(SEARCH("needs DB Dev",$AC10)),O10<>"",SUMPRODUCT(MAX(((TRIM('Rework Log'!$A$3:$A$500)=TRIM($B10))*('Rework Log'!$G$3:$G$500<>"Yes")*('Rework Log'!$G$3:$G$500<>"Did not pass re-test"))*IFERROR('Rework Log'!$I$3:$I$500*1,0)))>0),"Move old DB Dev completion date to Rework Log (col H)",IF(AND(LEFT($AC10,3)="Yes",ISNUMBER(SEARCH("needs PBI Dev",$AC10)),R10<>"",SUMPRODUCT(MAX(((TRIM('Rework Log'!$A$3:$A$500)=TRIM($B10))*('Rework Log'!$G$3:$G$500<>"Yes")*('Rework Log'!$G$3:$G$500<>"Did not pass re-test"))*IFERROR('Rework Log'!$I$3:$I$500*1,0)))>0),"Move old PBI Dev completion date to Rework Log (col H)",IF(AND(LEFT($AC10,3)="Yes",ISNUMBER(SEARCH("needs QA",$AC10)),U10<>"",SUMPRODUCT(MAX(((TRIM('Rework Log'!$A$3:$A$500)=TRIM($B10))*('Rework Log'!$G$3:$G$500<>"Yes")*('Rework Log'!$G$3:$G$500<>"Did not pass re-test"))*IFERROR('Rework Log'!$I$3:$I$500*1,0)))>0),"Move old QA completion date to Rework Log (col H)",IF(AND(LEFT($AC10,3)="Yes",ISNUMBER(SEARCH("needs DB Dev",$AC10)),TRIM(C10)<>"DB Dev"),"Set Current Status back to DB Dev",IF(AND(LEFT($AC10,3)="Yes",ISNUMBER(SEARCH("needs PBI Dev",$AC10)),TRIM(C10)<>"PBI Dev"),"Set Current Status back to PBI Dev",IF(AND(LEFT($AC10,3)="Yes",ISNUMBER(SEARCH("needs QA",$AC10)),TRIM(C10)<>"QA"),"Set Current Status back to QA",IF(COUNTIF($B$2:$B$500,$B10)>1,"Duplicate name - check row",IF(AND(TRIM(C10)="RELEASED IN PROD",Y10<>"Yes"),"Released but Confirmed Deployed? is not Yes",IF(COUNTIF('Rework Log'!$A$3:$A$500,$B10)>0,"",IF(AND(S10<>"",M10<>"",S10<M10),"QA target is before DB Dev target",IF(AND(S10<>"",P10<>"",S10<P10),"QA target is before PBI Dev target",IF(AND(V10<>"",S10<>"",V10<S10),"DPO Approval target is before QA target",IF(AND(Z10<>"",V10<>"",Z10<V10),"Confirmed Deployed date is before DPO Approval target",""))))))))))))))))) -> QA target is before DB Dev target | AE10: 23/4 - Testing completed in QA and defect created https://jira.prod.nationalgrid.com/browse/GDMP-2227; Report is ready for testing 04/23/2026
A11: Leaks | B11: RPT_04_Surveillances With Zero Readings | C11: RELEASED IN PROD | D11: =IF($B11="","",IF(LEFT($AC11,3)="Yes",IF(LEN($AC11)>5,"Blocked - "&MID($AC11,7,100),"Blocked")&IF(SUMPRODUCT((TRIM('Rework Log'!$A$3:$A$500)=TRIM($B11))*('Rework Log'!$G$3:$G$500<>"Yes")*('Rework Log'!$G$3:$G$500<>"Did not pass re-test"))=0,"",IF(SUMPRODUCT(((TRIM('Rework Log'!$A$3:$A$500)=TRIM($B11))*('Rework Log'!$G$3:$G$500<>"Yes")*('Rework Log'!$G$3:$G$500<>"Did not pass re-test"))*ISNUMBER('Rework Log'!$J$3:$J$500))>0," - fixed, awaiting re-test",IF(SUMPRODUCT(MAX(((TRIM('Rework Log'!$A$3:$A$500)=TRIM($B11))*('Rework Log'!$G$3:$G$500<>"Yes")*('Rework Log'!$G$3:$G$500<>"Did not pass re-test"))*IFERROR('Rework Log'!$I$3:$I$500*1,0)))=0," - unclaimed"," - promised "&TEXT(SUMPRODUCT(MAX(((TRIM('Rework Log'!$A$3:$A$500)=TRIM($B11))*('Rework Log'!$G$3:$G$500<>"Yes")*('Rework Log'!$G$3:$G$500<>"Did not pass re-test"))*IFERROR('Rework Log'!$I$3:$I$500*1,0))),"m/d")))),IF(TRIM(C11)="NOT STARTED",IF(K11="","No plan date set",IF(K11<TODAY(),"Review - planned start passed","On track")),IF(TRIM(C11)="DB Dev",IF(M11="","No target set",IF(AND(M11<TODAY(),O11=""),"Overdue","On track")),IF(TRIM(C11)="PBI Dev",IF(P11="","No target set",IF(AND(P11<TODAY(),R11=""),"Overdue","On track")),IF(TRIM(C11)="QA",IF(S11="","No target set",IF(AND(S11<TODAY(),U11=""),"Overdue","On track")),IF(TRIM(C11)="DPO Approval",IF(V11="","No target set",IF(V11<TODAY(),"Overdue","On track")),IF(TRIM(C11)="RELEASED IN PROD","Delivered","")))))))) -> Delivered | E11: 10 | G11: Sreevarsha | H11: Navya | I11: Kelvin | K11: 46173 | L11: May | P11: 46139 | R11: 46139 | S11: 46139 | U11: 46139 | X11: Kelvin Hu | Y11: Yes | Z11: 46139 | AA11: https://app.powerbi.com/groups/me/apps/eedba83d-be9a-45f9-9504-7bfa41e6051a/reports/743b79eb-5470-4cd4-ad54-81eb3b409ae8/ea184ec020032ecbdd43?ctid=f98a6a53-25f3-4212-901c-c7787fcd3495&experience=power-bi | AB11: https://app.powerbi.com/groups/me/apps/2c7180b1-0d3d-45be-979e-f7dc86b3557d/reports/c887cd5e-9172-4de3-921e-2c0edd2533bc/ea184ec020032ecbdd43?experience=power-bi | AC11: No | AD11: =IF($B11="","",IF(AND(LEFT($AC11,3)="Yes",SUMPRODUCT((TRIM('Rework Log'!$A$3:$A$500)=TRIM($B11))*('Rework Log'!$G$3:$G$500<>"Yes")*('Rework Log'!$G$3:$G$500<>"Did not pass re-test"))=0),"Blocked - log it on Rework Log",IF(AND(LEFT($AC11,3)<>"Yes",SUMPRODUCT((TRIM('Rework Log'!$A$3:$A$500)=TRIM($B11))*('Rework Log'!$G$3:$G$500<>"Yes")*('Rework Log'!$G$3:$G$500<>"Did not pass re-test"))>0),"Open rework row - mark Blocked? or close it",IF(AND(LEFT($AC11,3)<>"Yes",SUMPRODUCT((TRIM('Rework Log'!$A$3:$A$500)=TRIM($B11))*('Rework Log'!$G$3:$G$500<>"Yes")*('Rework Log'!$G$3:$G$500<>"Did not pass re-test"))=0,COUNTIF('Rework Log'!$A$3:$A$500,$B11)>0,IFERROR(INDEX('Rework Log'!$G:$G,SUMPRODUCT(MAX((TRIM('Rework Log'!$A$3:$A$500)=TRIM($B11))*ROW('Rework Log'!$A$3:$A$500)))),"")="Did not pass re-test"),"Last fix rejected - re-block or log next attempt",IF(AND(LEFT($AC11,3)="Yes",ISNUMBER(SEARCH("needs DB Dev",$AC11)),O11<>"",SUMPRODUCT(MAX(((TRIM('Rework Log'!$A$3:$A$500)=TRIM($B11))*('Rework Log'!$G$3:$G$500<>"Yes")*('Rework Log'!$G$3:$G$500<>"Did not pass re-test"))*IFERROR('Rework Log'!$I$3:$I$500*1,0)))>0),"Move old DB Dev completion date to Rework Log (col H)",IF(AND(LEFT($AC11,3)="Yes",ISNUMBER(SEARCH("needs PBI Dev",$AC11)),R11<>"",SUMPRODUCT(MAX(((TRIM('Rework Log'!$A$3:$A$500)=TRIM($B11))*('Rework Log'!$G$3:$G$500<>"Yes")*('Rework Log'!$G$3:$G$500<>"Did not pass re-test"))*IFERROR('Rework Log'!$I$3:$I$500*1,0)))>0),"Move old PBI Dev completion date to Rework Log (col H)",IF(AND(LEFT($AC11,3)="Yes",ISNUMBER(SEARCH("needs QA",$AC11)),U11<>"",SUMPRODUCT(MAX(((TRIM('Rework Log'!$A$3:$A$500)=TRIM($B11))*('Rework Log'!$G$3:$G$500<>"Yes")*('Rework Log'!$G$3:$G$500<>"Did not pass re-test"))*IFERROR('Rework Log'!$I$3:$I$500*1,0)))>0),"Move old QA completion date to Rework Log (col H)",IF(AND(LEFT($AC11,3)="Yes",ISNUMBER(SEARCH("needs DB Dev",$AC11)),TRIM(C11)<>"DB Dev"),"Set Current Status back to DB Dev",IF(AND(LEFT($AC11,3)="Yes",ISNUMBER(SEARCH("needs PBI Dev",$AC11)),TRIM(C11)<>"PBI Dev"),"Set Current Status back to PBI Dev",IF(AND(LEFT($AC11,3)="Yes",ISNUMBER(SEARCH("needs QA",$AC11)),TRIM(C11)<>"QA"),"Set Current Status back to QA",IF(COUNTIF($B$2:$B$500,$B11)>1,"Duplicate name - check row",IF(AND(TRIM(C11)="RELEASED IN PROD",Y11<>"Yes"),"Released but Confirmed Deployed? is not Yes",IF(COUNTIF('Rework Log'!$A$3:$A$500,$B11)>0,"",IF(AND(S11<>"",M11<>"",S11<M11),"QA target is before DB Dev target",IF(AND(S11<>"",P11<>"",S11<P11),"QA target is before PBI Dev target",IF(AND(V11<>"",S11<>"",V11<S11),"DPO Approval target is before QA target",IF(AND(Z11<>"",V11<>"",Z11<V11),"Confirmed Deployed date is before DPO Approval target","")))))))))))))))))
A12: Leaks | B12: RPT_04 High Emitter leaks | C12: RELEASED IN PROD | D12: =IF($B12="","",IF(LEFT($AC12,3)="Yes",IF(LEN($AC12)>5,"Blocked - "&MID($AC12,7,100),"Blocked")&IF(SUMPRODUCT((TRIM('Rework Log'!$A$3:$A$500)=TRIM($B12))*('Rework Log'!$G$3:$G$500<>"Yes")*('Rework Log'!$G$3:$G$500<>"Did not pass re-test"))=0,"",IF(SUMPRODUCT(((TRIM('Rework Log'!$A$3:$A$500)=TRIM($B12))*('Rework Log'!$G$3:$G$500<>"Yes")*('Rework Log'!$G$3:$G$500<>"Did not pass re-test"))*ISNUMBER('Rework Log'!$J$3:$J$500))>0," - fixed, awaiting re-test",IF(SUMPRODUCT(MAX(((TRIM('Rework Log'!$A$3:$A$500)=TRIM($B12))*('Rework Log'!$G$3:$G$500<>"Yes")*('Rework Log'!$G$3:$G$500<>"Did not pass re-test"))*IFERROR('Rework Log'!$I$3:$I$500*1,0)))=0," - unclaimed"," - promised "&TEXT(SUMPRODUCT(MAX(((TRIM('Rework Log'!$A$3:$A$500)=TRIM($B12))*('Rework Log'!$G$3:$G$500<>"Yes")*('Rework Log'!$G$3:$G$500<>"Did not pass re-test"))*IFERROR('Rework Log'!$I$3:$I$500*1,0))),"m/d")))),IF(TRIM(C12)="NOT STARTED",IF(K12="","No plan date set",IF(K12<TODAY(),"Review - planned start passed","On track")),IF(TRIM(C12)="DB Dev",IF(M12="","No target set",IF(AND(M12<TODAY(),O12=""),"Overdue","On track")),IF(TRIM(C12)="PBI Dev",IF(P12="","No target set",IF(AND(P12<TODAY(),R12=""),"Overdue","On track")),IF(TRIM(C12)="QA",IF(S12="","No target set",IF(AND(S12<TODAY(),U12=""),"Overdue","On track")),IF(TRIM(C12)="DPO Approval",IF(V12="","No target set",IF(V12<TODAY(),"Overdue","On track")),IF(TRIM(C12)="RELEASED IN PROD","Delivered","")))))))) -> Delivered | E12: 11 | G12: Sreevarsha | H12: Navya | I12: Preety | K12: 46173 | L12: May | P12: 46141 | R12: 46141 | S12: 46141 | U12: 46141 | X12: Kelvin Hu | Y12: Yes | Z12: 46141 | AA12: https://app.powerbi.com/groups/me/apps/61b18507-2848-49b9-aacc-32c49ffe1e0b/reports/a44e7124-b1d0-4a09-a5d1-157e2043ba8e/ea184ec020032ecbdd43?ctid=f98a6a53-25f3-4212-901c-c7787fcd3495&experience=power-bi | AB12: https://app.powerbi.com/groups/me/apps/93d01997-58e0-48d8-bcca-ad8377094e64/reports/6d6fe558-e5d6-4a4b-b6fb-8a5f8735d1df/ea184ec020032ecbdd43?experience=power-bi | AC12: No | AD12: =IF($B12="","",IF(AND(LEFT($AC12,3)="Yes",SUMPRODUCT((TRIM('Rework Log'!$A$3:$A$500)=TRIM($B12))*('Rework Log'!$G$3:$G$500<>"Yes")*('Rework Log'!$G$3:$G$500<>"Did not pass re-test"))=0),"Blocked - log it on Rework Log",IF(AND(LEFT($AC12,3)<>"Yes",SUMPRODUCT((TRIM('Rework Log'!$A$3:$A$500)=TRIM($B12))*('Rework Log'!$G$3:$G$500<>"Yes")*('Rework Log'!$G$3:$G$500<>"Did not pass re-test"))>0),"Open rework row - mark Blocked? or close it",IF(AND(LEFT($AC12,3)<>"Yes",SUMPRODUCT((TRIM('Rework Log'!$A$3:$A$500)=TRIM($B12))*('Rework Log'!$G$3:$G$500<>"Yes")*('Rework Log'!$G$3:$G$500<>"Did not pass re-test"))=0,COUNTIF('Rework Log'!$A$3:$A$500,$B12)>0,IFERROR(INDEX('Rework Log'!$G:$G,SUMPRODUCT(MAX((TRIM('Rework Log'!$A$3:$A$500)=TRIM($B12))*ROW('Rework Log'!$A$3:$A$500)))),"")="Did not pass re-test"),"Last fix rejected - re-block or log next attempt",IF(AND(LEFT($AC12,3)="Yes",ISNUMBER(SEARCH("needs DB Dev",$AC12)),O12<>"",SUMPRODUCT(MAX(((TRIM('Rework Log'!$A$3:$A$500)=TRIM($B12))*('Rework Log'!$G$3:$G$500<>"Yes")*('Rework Log'!$G$3:$G$500<>"Did not pass re-test"))*IFERROR('Rework Log'!$I$3:$I$500*1,0)))>0),"Move old DB Dev completion date to Rework Log (col H)",IF(AND(LEFT($AC12,3)="Yes",ISNUMBER(SEARCH("needs PBI Dev",$AC12)),R12<>"",SUMPRODUCT(MAX(((TRIM('Rework Log'!$A$3:$A$500)=TRIM($B12))*('Rework Log'!$G$3:$G$500<>"Yes")*('Rework Log'!$G$3:$G$500<>"Did not pass re-test"))*IFERROR('Rework Log'!$I$3:$I$500*1,0)))>0),"Move old PBI Dev completion date to Rework Log (col H)",IF(AND(LEFT($AC12,3)="Yes",ISNUMBER(SEARCH("needs QA",$AC12)),U12<>"",SUMPRODUCT(MAX(((TRIM('Rework Log'!$A$3:$A$500)=TRIM($B12))*('Rework Log'!$G$3:$G$500<>"Yes")*('Rework Log'!$G$3:$G$500<>"Did not pass re-test"))*IFERROR('Rework Log'!$I$3:$I$500*1,0)))>0),"Move old QA completion date to Rework Log (col H)",IF(AND(LEFT($AC12,3)="Yes",ISNUMBER(SEARCH("needs DB Dev",$AC12)),TRIM(C12)<>"DB Dev"),"Set Current Status back to DB Dev",IF(AND(LEFT($AC12,3)="Yes",ISNUMBER(SEARCH("needs PBI Dev",$AC12)),TRIM(C12)<>"PBI Dev"),"Set Current Status back to PBI Dev",IF(AND(LEFT($AC12,3)="Yes",ISNUMBER(SEARCH("needs QA",$AC12)),TRIM(C12)<>"QA"),"Set Current Status back to QA",IF(COUNTIF($B$2:$B$500,$B12)>1,"Duplicate name - check row",IF(AND(TRIM(C12)="RELEASED IN PROD",Y12<>"Yes"),"Released but Confirmed Deployed? is not Yes",IF(COUNTIF('Rework Log'!$A$3:$A$500,$B12)>0,"",IF(AND(S12<>"",M12<>"",S12<M12),"QA target is before DB Dev target",IF(AND(S12<>"",P12<>"",S12<P12),"QA target is before PBI Dev target",IF(AND(V12<>"",S12<>"",V12<S12),"DPO Approval target is before QA target",IF(AND(Z12<>"",V12<>"",Z12<V12),"Confirmed Deployed date is before DPO Approval target",""))))))))))))))))) | AE12: 05/05- defect raised https://jira.prod.nationalgrid.com/browse/GDMP-2230
