Workbook

Sheet README - Instructions
A1: GDM Tracker
A2: One tracker, built so a Manager, Director, PM, QA tester, or PBI/DB developer can each get what they need without hunting for it.
A4: QUICK GUIDE BY ROLE
A5: Manager / Director - look at: Status Flag (col D, color-coded), Business Value Rank (col E) to see what matters most, Blocked At (col AG) for an instant 'blocked at [stage]' read - plus that stage's own date columns turn red too, so it's visible without even reading the text. Auto Rework Alert (col AM, red = something bounced backward), Confirmed Deployed? (col AB) for real proof of what's actually live. UAT/Prod URLs (cols AD-AE) are clickable.
A7: The pipeline
A8: NOT STARTED -> DB Dev -> PBI Dev -> QA -> DPO Approval -> RELEASED IN PROD. Current Status (col C) is a manual dropdown - set it to wherever the report actually is. Each stage (except Not Started and Released) has its own Status Assigned / Expected / Estimated / Actual date columns, except DPO Approval, which just has Status Assigned, Expected, and a Reviewer name (col AA) - there's no separate Actual for DPO Approval; use Confirmed Deployed? (col AB) instead once it's truly live.
A10: Expected vs. Estimated - the one habit that matters most
A11: Expected Completion Date is the original target - set it once, when a report enters that stage, and don't change it again. Estimated Completion Date is the one that moves - update it whenever a timeline shifts or a rework changes the plan. This way you always know both what was originally promised and what's realistically true now, without losing either. This is guidance, not an enforced rule - nothing is locked, it's on the honor system.
A13: Status Flag (col D) - automatic
A14: Reads Current Status plus that stage's own dates: 'No target set', 'Overdue', 'Review - planned start passed', 'On track', or 'Delivered'. Color-coded. Once a report is Released, Status Flag always just says 'Delivered' - a missing date never downgrades or flags a released report; Confirmed Deployed? is extra evidence on top, never a condition for the status itself.
A16: Rework tracking - three layers now
A17: Layer 1, fully automatic (cols AM-AN): 'Furthest Stage Reached' figures out from the dates already filled in how far a report has actually gotten. 'Auto Rework Alert' flags it in red if Current Status has been moved backward from that point - e.g. QA already has a date, but Current Status now says DB Dev. No logging required for this to work, ever. Layer 2, optional manual detail (Rework Log tab + cols AH-AK here): log who sent it back, why, the Defect/Jira Ticket if there is one, and the new expected fix date. Combined Delivery Data automatically pulls the most recent entry into 'Last Sent Back From', 'Last Defect/Jira Ticket', and 'Rework Est. Fix Date' - maintain history in one place, it shows up here without re-typing it. Rework Count tallies how many times each report appears on the log. Any stage can go back to any previous stage - it's not QA-specific. Layer 3 - Blocked with a known cause (cols AF-AH): Blocked? stays a simple Yes/No. If the block is just something stuck in its current stage (waiting on a normal review, etc.), leave 'Blocked - Needs Return To' blank - Blocked At will say 'Blocked at [stage]'. If a PREVIOUS stage actually needs to fix something (e.g. QA found a bug only DB Dev can resolve), set 'Blocked - Needs Return To' to that stage - Blocked At will instead say 'Blocked - needs DB Dev to fix', and that stage's own date columns light up red too, so whoever owns that stage sees it without reading anything. Rework Log also now has a live summary table (columns J-N) mirroring the same counts per report, so you can see them without switching tabs.
... A42: By specific request, the live dashboard's Fact Table populates its "PO" field from this sheet's QA Tester column, not the real PO column - so the PO name shown in the app's drill-down table, Coming Your Way table, and Stage Progression Gaps table is actually the QA Tester's name. This is a deliberate app-side choice, not a data error: the real PO column here is untouched and still populated normally for everyone's own reference, and any other tool reading this file directly will see the real PO value. Only the dashboard app's own display substitutes QA Tester in that spot.

Sheet Combined Delivery Data
A1: Domain | B1: Report Name | C1: Current Status | D1: Status Flag | E1: Business Value Rank | F1: PO | G1: DB Developer | H1: PBI Developer | I1: QA Tester | J1: Schema | K1: Plan Delivery Date | L1: Plan Delivery Month | M1: DB Dev Status Assigned Date | N1: DB Dev Expected Completion Date | O1: DB Dev Estimated Completion Date | P1: DB Dev Actual Completion Date | Q1: PBI Dev Status Assigned Date | R1: PBI Dev Expected Completion Date | S1: PBI Dev Estimated Completion Date | T1: PBI Dev Actual Completion Date | U1: QA Status Assigned Date | V1: QA Expected Completion Date | W1: QA Estimated Completion Date | X1: QA Actual Completion Date | Y1: DPO Approval Status Assigned Date | Z1: DPO Approval Expected Completion Date | AA1: DPO Approval Reviewer | AB1: Confirmed Deployed? | AC1: Confirmed Deployed Date | AD1: UAT Report URL | AE1: Production URL | AF1: Blocked? | AG1: Blocked - Needs Return To | AH1: Blocked At | AI1: Rework Count | AJ1: Last Sent Back From | AK1: Rework Est. Fix Date | AL1: Last Defect/Jira Ticket | AM1: Furthest Stage Reached | AN1: Auto Rework Alert | AO1: Chronology Check | AP1: Duplicate Name Check | AQ1: Comments | AR1: _Last Rework Row
A2: Leaks | B2: RPT_04_Active Leaks | C2: RELEASED IN PROD | D2: =IF($B2="","",IF(C2="NOT STARTED",IF(K2="","No plan date set",IF(K2<TODAY(),"Review - planned start passed","On track")),IF(C2="DB Dev",IF(N2="","No target set",IF(AND(N2<TODAY(),P2=""),"Overdue","On track")),IF(C2="PBI Dev",IF(R2="","No target set",IF(AND(R2<TODAY(),T2=""),"Overdue","On track")),IF(C2="QA",IF(V2="","No target set",IF(AND(V2<TODAY(),X2=""),"Overdue","On track")),IF(C2="DPO Approval",IF(Z2="","No target set",IF(Z2<TODAY(),"Overdue","On track")),IF(C2="RELEASED IN PROD","Delivered",""))))))) -> Delivered | E2: 1 | G2: Fetwi | H2: Sarath | I2: Preety | K2: 46142 | L2: April | P2: 46115 | T2: 46114 | X2: 46122 | AA2: Kelvin Hu | AB2: Yes | AD2: https://app.powerbi.com/groups/me/apps/eedba83d-be9a-45f9-9504-7bfa41e6051a/reports/62307ec4-3158-4457-8dcc-4acc2150cdc3/ccfe9e7f0a40d49acb85?experience=power-bi | AE2: https://app.powerbi.com/groups/me/apps/2c7180b1-0d3d-45be-979e-f7dc86b3557d/reports/8cd4a21d-3abe-4e55-a99e-3af846ab1c67/ccfe9e7f0a40d49acb85?ctid=f98a6a53-25f3-4212-901c-c7787fcd3495&experience=power-bi | AF2: No | AH2: =IF($AF2="Yes",IF($AG2<>"","Blocked - needs "&$AG2&" to fix","Blocked at "&$C2),"") | AI2: =IF($B2="","",COUNTIF('Rework Log'!$A$3:$A$500,$B2)) -> 0 | AJ2: =IF(OR($B2="",$AR2=0),"",INDEX('Rework Log'!$C:$C,$AR2)) | AK2: =IF(OR($B2="",$AR2=0),"",INDEX('Rework Log'!$H:$H,$AR2)) | AL2: =IF(OR($B2="",$AR2=0),"",INDEX('Rework Log'!$G:$G,$AR2)) | AM2: =IF($B2="","",IF(Z2<>"","DPO Approval",IF(V2<>"","QA",IF(R2<>"","PBI Dev",IF(N2<>"","DB Dev","NOT STARTED"))))) -> NOT STARTED | AN2: =IF($B2="","",IF(IF($C2="NOT STARTED",0,IF($C2="DB Dev",1,IF($C2="PBI Dev",2,IF($C2="QA",3,IF($C2="DPO Approval",4,IF($C2="RELEASED IN PROD",5,-1))))))<IF($AM2="NOT STARTED",0,IF($AM2="DB Dev",1,IF($AM2="PBI Dev",2,IF($AM2="QA",3,IF($AM2="DPO Approval",4,IF($AM2="RELEASED IN PROD",5,-1)))))),"Yes - was already at "&$AM2&", now back at "&$C2,"No")) -> No | AO2: =IF($B2="","",IF(AND(V2<>"",N2<>"",V2<N2),"QA target is before DB Dev target",IF(AND(V2<>"",R2<>"",V2<R2),"QA target is before PBI Dev target",IF(AND(Z2<>"",V2<>"",Z2<V2),"DPO Approval target is before QA target",IF(AND(AC2<>"",Z2<>"",AC2<Z2),"Confirmed Deployed date is before DPO Approval target",""))))) | AP2: =IF($B2="","",IF(COUNTIF($B$2:$B$500,$B2)>1,"Duplicate name - check row","")) | AQ2: [Historical, April 2026]: QA found an issue - date calendar dimension broken. Fetwi assigned to fix. | AR2: =IF($B2="","",SUMPRODUCT(MAX(('Rework Log'!$A$3:$A$500=$B2)*ROW('Rework Log'!$A$3:$A$500)))) -> 0
A3: Leaks | B3: RPT_04_Count of Active Leaks On Hand | C3: RELEASED IN PROD | D3: =IF($B3="","",IF(C3="NOT STARTED",IF(K3="","No plan date set",IF(K3<TODAY(),"Review - planned start passed","On track")),IF(C3="DB Dev",IF(N3="","No target set",IF(AND(N3<TODAY(),P3=""),"Overdue","On track")),IF(C3="PBI Dev",IF(R3="","No target set",IF(AND(R3<TODAY(),T3=""),"Overdue","On track")),IF(C3="QA",IF(V3="","No target set",IF(AND(V3<TODAY(),X3=""),"Overdue","On track")),IF(C3="DPO Approval",IF(Z3="","No target set",IF(Z3<TODAY(),"Overdue","On track")),IF(C3="RELEASED IN PROD","Delivered",""))))))) -> Delivered | E3: 2 | G3: Fetwi | H3: Sarath | I3: Preety | K3: 46142 | L3: April | P3: 46115 | T3: 46114 | X3: 46122 | AA3: Kelvin Hu | AB3: Yes | AD3: https://app.powerbi.com/groups/me/apps/eedba83d-be9a-45f9-9504-7bfa41e6051a/reports/c0b3f0ae-dedd-485b-8bbc-aa0e5f3fd077/24a66431d0637282f4b7?experience=power-bi | AE3: https://app.powerbi.com/groups/me/apps/2c7180b1-0d3d-45be-979e-f7dc86b3557d/reports/5ffd546f-ad77-4a7f-8e6d-94dc08bef796/24a66431d0637282f4b7?ctid=f98a6a53-25f3-4212-901c-c7787fcd3495&experience=power-bi | AF3: No | AH3: =IF($AF3="Yes",IF($AG3<>"","Blocked - needs "&$AG3&" to fix","Blocked at "&$C3),"") | AI3: =IF($B3="","",COUNTIF('Rework Log'!$A$3:$A$500,$B3)) -> 0 | AJ3: =IF(OR($B3="",$AR3=0),"",INDEX('Rework Log'!$C:$C,$AR3)) | AK3: =IF(OR($B3="",$AR3=0),"",INDEX('Rework Log'!$H:$H,$AR3)) | AL3: =IF(OR($B3="",$AR3=0),"",INDEX('Rework Log'!$G:$G,$AR3)) | AM3: =IF($B3="","",IF(Z3<>"","DPO Approval",IF(V3<>"","QA",IF(R3<>"","PBI Dev",IF(N3<>"","DB Dev","NOT STARTED"))))) -> NOT STARTED | AN3: =IF($B3="","",IF(IF($C3="NOT STARTED",0,IF($C3="DB Dev",1,IF($C3="PBI Dev",2,IF($C3="QA",3,IF($C3="DPO Approval",4,IF($C3="RELEASED IN PROD",5,-1))))))<IF($AM3="NOT STARTED",0,IF($AM3="DB Dev",1,IF($AM3="PBI Dev",2,IF($AM3="QA",3,IF($AM3="DPO Approval",4,IF($AM3="RELEASED IN PROD",5,-1)))))),"Yes - was already at "&$AM3&", now back at "&$C3,"No")) -> No | AO3: =IF($B3="","",IF(AND(V3<>"",N3<>"",V3<N3),"QA target is before DB Dev target",IF(AND(V3<>"",R3<>"",V3<R3),"QA target is before PBI Dev target",IF(AND(Z3<>"",V3<>"",Z3<V3),"DPO Approval target is before QA target",IF(AND(AC3<>"",Z3<>"",AC3<Z3),"Confirmed Deployed date is before DPO Approval target",""))))) | AP3: =IF($B3="","",IF(COUNTIF($B$2:$B$500,$B3)>1,"Duplicate name - check row","")) | AQ3: [Historical, April 2026]: QA found an issue - date calendar dimension broken. Fetwi assigned to fix. | AR3: =IF($B3="","",SUMPRODUCT(MAX(('Rework Log'!$A$3:$A$500=$B3)*ROW('Rework Log'!$A$3:$A$500)))) -> 0
A4: Leaks | B4: RPT_04_Leak Scheduling | C4: RELEASED IN PROD | D4: =IF($B4="","",IF(C4="NOT STARTED",IF(K4="","No plan date set",IF(K4<TODAY(),"Review - planned start passed","On track")),IF(C4="DB Dev",IF(N4="","No target set",IF(AND(N4<TODAY(),P4=""),"Overdue","On track")),IF(C4="PBI Dev",IF(R4="","No target set",IF(AND(R4<TODAY(),T4=""),"Overdue","On track")),IF(C4="QA",IF(V4="","No target set",IF(AND(V4<TODAY(),X4=""),"Overdue","On track")),IF(C4="DPO Approval",IF(Z4="","No target set",IF(Z4<TODAY(),"Overdue","On track")),IF(C4="RELEASED IN PROD","Delivered",""))))))) -> Delivered | E4: 4 | G4: Sreevarsha | H4: Sarath | I4: Preety | K4: 46142 | L4: April | P4: 46115 | T4: 46120 | X4: 46122 | AA4: Kelvin Hu | AF4: No | AH4: =IF($AF4="Yes",IF($AG4<>"","Blocked - needs "&$AG4&" to fix","Blocked at "&$C4),"") | AI4: =IF($B4="","",COUNTIF('Rework Log'!$A$3:$A$500,$B4)) -> 0 | AJ4: =IF(OR($B4="",$AR4=0),"",INDEX('Rework Log'!$C:$C,$AR4)) | AK4: =IF(OR($B4="",$AR4=0),"",INDEX('Rework Log'!$H:$H,$AR4)) | AL4: =IF(OR($B4="",$AR4=0),"",INDEX('Rework Log'!$G:$G,$AR4)) | AM4: =IF($B4="","",IF(Z4<>"","DPO Approval",IF(V4<>"","QA",IF(R4<>"","PBI Dev",IF(N4<>"","DB Dev","NOT STARTED"))))) -> NOT STARTED | AN4: =IF($B4="","",IF(IF($C4="NOT STARTED",0,IF($C4="DB Dev",1,IF($C4="PBI Dev",2,IF($C4="QA",3,IF($C4="DPO Approval",4,IF($C4="RELEASED IN PROD",5,-1))))))<IF($AM4="NOT STARTED",0,IF($AM4="DB Dev",1,IF($AM4="PBI Dev",2,IF($AM4="QA",3,IF($AM4="DPO Approval",4,IF($AM4="RELEASED IN PROD",5,-1)))))),"Yes - was already at "&$AM4&", now back at "&$C4,"No")) -> No | AO4: =IF($B4="","",IF(AND(V4<>"",N4<>"",V4<N4),"QA target is before DB Dev target",IF(AND(V4<>"",R4<>"",V4<R4),"QA target is before PBI Dev target",IF(AND(Z4<>"",V4<>"",Z4<V4),"DPO Approval target is before QA target",IF(AND(AC4<>"",Z4<>"",AC4<Z4),"Confirmed Deployed date is before DPO Approval target",""))))) | AP4: =IF($B4="","",IF(COUNTIF($B$2:$B$500,$B4)>1,"Duplicate name - check row","")) | AR4: =IF($B4="","",SUMPRODUCT(MAX(('Rework Log'!$A$3:$A$500=$B4)*ROW('Rework Log'!$A$3:$A$500)))) -> 0
A5: Leaks | B5: RPT_04_Leak Days Remaining | C5: RELEASED IN PROD | D5: =IF($B5="","",IF(C5="NOT STARTED",IF(K5="","No plan date set",IF(K5<TODAY(),"Review - planned start passed","On track")),IF(C5="DB Dev",IF(N5="","No target set",IF(AND(N5<TODAY(),P5=""),"Overdue","On track")),IF(C5="PBI Dev",IF(R5="","No target set",IF(AND(R5<TODAY(),T5=""),"Overdue","On track")),IF(C5="QA",IF(V5="","No target set",IF(AND(V5<TODAY(),X5=""),"Overdue","On track")),IF(C5="DPO Approval",IF(Z5="","No target set",IF(Z5<TODAY(),"Overdue","On track")),IF(C5="RELEASED IN PROD","Delivered",""))))))) -> Delivered | E5: 5 | G5: Siva | H5: Navya | I5: Preety | K5: 46142 | L5: April | P5: 46115 | T5: 46126 | X5: 46122 | AA5: Kelvin Hu | AB5: Yes | AD5: https://app.powerbi.com/groups/me/apps/eedba83d-be9a-45f9-9504-7bfa41e6051a/reports/8b9ae445-3a30-4ae6-a3fa-7a6d8e7ef349/d97da6159d0c87677529?experience=power-bi | AE5: https://app.powerbi.com/groups/me/apps/2c7180b1-0d3d-45be-979e-f7dc86b3557d/reports/848ce65a-4e47-422b-aae5-7ea9e7d68a5f/d97da6159d0c87677529?ctid=f98a6a53-25f3-4212-901c-c7787fcd3495&experience=power-bi | AF5: No | AH5: =IF($AF5="Yes",IF($AG5<>"","Blocked - needs "&$AG5&" to fix","Blocked at "&$C5),"") | AI5: =IF($B5="","",COUNTIF('Rework Log'!$A$3:$A$500,$B5)) -> 0 | AJ5: =IF(OR($B5="",$AR5=0),"",INDEX('Rework Log'!$C:$C,$AR5)) | AK5: =IF(OR($B5="",$AR5=0),"",INDEX('Rework Log'!$H:$H,$AR5)) | AL5: =IF(OR($B5="",$AR5=0),"",INDEX('Rework Log'!$G:$G,$AR5)) | AM5: =IF($B5="","",IF(Z5<>"","DPO Approval",IF(V5<>"","QA",IF(R5<>"","PBI Dev",IF(N5<>"","DB Dev","NOT STARTED"))))) -> NOT STARTED | AN5: =IF($B5="","",IF(IF($C5="NOT STARTED",0,IF($C5="DB Dev",1,IF($C5="PBI Dev",2,IF($C5="QA",3,IF($C5="DPO Approval",4,IF($C5="RELEASED IN PROD",5,-1))))))<IF($AM5="NOT STARTED",0,IF($AM5="DB Dev",1,IF($AM5="PBI Dev",2,IF($AM5="QA",3,IF($AM5="DPO Approval",4,IF($AM5="RELEASED IN PROD",5,-1)))))),"Yes - was already at "&$AM5&", now back at "&$C5,"No")) -> No | AO5: =IF($B5="","",IF(AND(V5<>"",N5<>"",V5<N5),"QA target is before DB Dev target",IF(AND(V5<>"",R5<>"",V5<R5),"QA target is before PBI Dev target",IF(AND(Z5<>"",V5<>"",Z5<V5),"DPO Approval target is before QA target",IF(AND(AC5<>"",Z5<>"",AC5<Z5),"Confirmed Deployed date is before DPO Approval target",""))))) | AP5: =IF($B5="","",IF(COUNTIF($B$2:$B$500,$B5)>1,"Duplicate name - check row","")) | AQ5: 16/04 - Testing completed in QA and created defect https://jira.prod.nationalgrid.com/browse/GDMP-2186; ETA -04/24 | AR5: =IF($B5="","",SUMPRODUCT(MAX(('Rework Log'!$A$3:$A$500=$B5)*ROW('Rework Log'!$A$3:$A$500)))) -> 0
A6: Leaks | B6: RPT_04_Cleared Leaks | C6: RELEASED IN PROD | D6: =IF($B6="","",IF(C6="NOT STARTED",IF(K6="","No plan date set",IF(K6<TODAY(),"Review - planned start passed","On track")),IF(C6="DB Dev",IF(N6="","No target set",IF(AND(N6<TODAY(),P6=""),"Overdue","On track")),IF(C6="PBI Dev",IF(R6="","No target set",IF(AND(R6<TODAY(),T6=""),"Overdue","On track")),IF(C6="QA",IF(V6="","No target set",IF(AND(V6<TODAY(),X6=""),"Overdue","On track")),IF(C6="DPO Approval",IF(Z6="","No target set",IF(Z6<TODAY(),"Overdue","On track")),IF(C6="RELEASED IN PROD","Delivered",""))))))) -> Delivered | E6: 3 | G6: Sreevarsha | H6: Sarath | I6: Preety | K6: 46142 | L6: April | P6: 46115 | T6: 46120 | X6: 46122 | AA6: Kelvin Hu | AB6: Yes | AD6: https://app.powerbi.com/groups/me/apps/eedba83d-be9a-45f9-9504-7bfa41e6051a/reports/938a9ba1-8138-440e-842a-d9a679933d8c/44bb4fce98fafb2cace2?experience=power-bi | AE6: https://app.powerbi.com/groups/me/apps/2c7180b1-0d3d-45be-979e-f7dc86b3557d/reports/677c6418-6db8-4ebf-9323-65be4cb2c960/ea184ec020032ecbdd43?ctid=f98a6a53-25f3-4212-901c-c7787fcd3495&experience=power-bi | AF6: No | AH6: =IF($AF6="Yes",IF($AG6<>"","Blocked - needs "&$AG6&" to fix","Blocked at "&$C6),"") | AI6: =IF($B6="","",COUNTIF('Rework Log'!$A$3:$A$500,$B6)) -> 0 | AJ6: =IF(OR($B6="",$AR6=0),"",INDEX('Rework Log'!$C:$C,$AR6)) | AK6: =IF(OR($B6="",$AR6=0),"",INDEX('Rework Log'!$H:$H,$AR6)) | AL6: =IF(OR($B6="",$AR6=0),"",INDEX('Rework Log'!$G:$G,$AR6)) | AM6: =IF($B6="","",IF(Z6<>"","DPO Approval",IF(V6<>"","QA",IF(R6<>"","PBI Dev",IF(N6<>"","DB Dev","NOT STARTED"))))) -> NOT STARTED | AN6: =IF($B6="","",IF(IF($C6="NOT STARTED",0,IF($C6="DB Dev",1,IF($C6="PBI Dev",2,IF($C6="QA",3,IF($C6="DPO Approval",4,IF($C6="RELEASED IN PROD",5,-1))))))<IF($AM6="NOT STARTED",0,IF($AM6="DB Dev",1,IF($AM6="PBI Dev",2,IF($AM6="QA",3,IF($AM6="DPO Approval",4,IF($AM6="RELEASED IN PROD",5,-1)))))),"Yes - was already at "&$AM6&", now back at "&$C6,"No")) -> No | AO6: =IF($B6="","",IF(AND(V6<>"",N6<>"",V6<N6),"QA target is before DB Dev target",IF(AND(V6<>"",R6<>"",V6<R6),"QA target is before PBI Dev target",IF(AND(Z6<>"",V6<>"",Z6<V6),"DPO Approval target is before QA target",IF(AND(AC6<>"",Z6<>"",AC6<Z6),"Confirmed Deployed date is before DPO Approval target",""))))) | AP6: =IF($B6="","",IF(COUNTIF($B$2:$B$500,$B6)>1,"Duplicate name - check row","")) | AQ6: [Historical, April 2026]: L_GRO_NUMBER columns had an issue in QA - DB team assigned to fix. | AR6: =IF($B6="","",SUMPRODUCT(MAX(('Rework Log'!$A$3:$A$500=$B6)*ROW('Rework Log'!$A$3:$A$500)))) -> 0
A7: Leaks | B7: RPT_04_Leaks Repaired Detail | C7: RELEASED IN PROD | D7: =IF($B7="","",IF(C7="NOT STARTED",IF(K7="","No plan date set",IF(K7<TODAY(),"Review - planned start passed","On track")),IF(C7="DB Dev",IF(N7="","No target set",IF(AND(N7<TODAY(),P7=""),"Overdue","On track")),IF(C7="PBI Dev",IF(R7="","No target set",IF(AND(R7<TODAY(),T7=""),"Overdue","On track")),IF(C7="QA",IF(V7="","No target set",IF(AND(V7<TODAY(),X7=""),"Overdue","On track")),IF(C7="DPO Approval",IF(Z7="","No target set",IF(Z7<TODAY(),"Overdue","On track")),IF(C7="RELEASED IN PROD","Delivered",""))))))) -> Delivered | E7: 6 | G7: Rupa | H7: Navya | I7: Preety | K7: 46142 | L7: April | P7: 46115 | T7: 46126 | X7: 46122 | AA7: Kelvin Hu | AB7: Yes | AD7: https://app.powerbi.com/groups/me/apps/eedba83d-be9a-45f9-9504-7bfa41e6051a/reports/cbaf2155-2cf3-4377-8af2-7e07a896e887/ea184ec020032ecbdd43?experience=power-bi | AE7: https://app.powerbi.com/groups/me/apps/2c7180b1-0d3d-45be-979e-f7dc86b3557d/reports/9c6d5e21-4e57-4a64-9973-61ff3717468e/ea184ec020032ecbdd43?ctid=f98a6a53-25f3-4212-901c-c7787fcd3495&experience=power-bi | AF7: No | AH7: =IF($AF7="Yes",IF($AG7<>"","Blocked - needs "&$AG7&" to fix","Blocked at "&$C7),"") | AI7: =IF($B7="","",COUNTIF('Rework Log'!$A$3:$A$500,$B7)) -> 0 | AJ7: =IF(OR($B7="",$AR7=0),"",INDEX('Rework Log'!$C:$C,$AR7)) | AK7: =IF(OR($B7="",$AR7=0),"",INDEX('Rework Log'!$H:$H,$AR7)) | AL7: =IF(OR($B7="",$AR7=0),"",INDEX('Rework Log'!$G:$G,$AR7)) | AM7: =IF($B7="","",IF(Z7<>"","DPO Approval",IF(V7<>"","QA",IF(R7<>"","PBI Dev",IF(N7<>"","DB Dev","NOT STARTED"))))) -> NOT STARTED | AN7: =IF($B7="","",IF(IF($C7="NOT STARTED",0,IF($C7="DB Dev",1,IF($C7="PBI Dev",2,IF($C7="QA",3,IF($C7="DPO Approval",4,IF($C7="RELEASED IN PROD",5,-1))))))<IF($AM7="NOT STARTED",0,IF($AM7="DB Dev",1,IF($AM7="PBI Dev",2,IF($AM7="QA",3,IF($AM7="DPO Approval",4,IF($AM7="RELEASED IN PROD",5,-1)))))),"Yes - was already at "&$AM7&", now back at "&$C7,"No")) -> No | AO7: =IF($B7="","",IF(AND(V7<>"",N7<>"",V7<N7),"QA target is before DB Dev target",IF(AND(V7<>"",R7<>"",V7<R7),"QA target is before PBI Dev target",IF(AND(Z7<>"",V7<>"",Z7<V7),"DPO Approval target is before QA target",IF(AND(AC7<>"",Z7<>"",AC7<Z7),"Confirmed Deployed date is before DPO Approval target",""))))) | AP7: =IF($B7="","",IF(COUNTIF($B$2:$B$500,$B7)>1,"Duplicate name - check row","")) | AQ7: 21/4 Testing completed in QA and defect raised https://jira.prod.nationalgrid.com/browse/GDMP-2190; Report ready for testing 04/23/2026 | AR7: =IF($B7="","",SUMPRODUCT(MAX(('Rework Log'!$A$3:$A$500=$B7)*ROW('Rework Log'!$A$3:$A$500)))) -> 0
A8: Leaks | B8: RPT_04_Leaks Aging | C8: RELEASED IN PROD | D8: =IF($B8="","",IF(C8="NOT STARTED",IF(K8="","No plan date set",IF(K8<TODAY(),"Review - planned start passed","On track")),IF(C8="DB Dev",IF(N8="","No target set",IF(AND(N8<TODAY(),P8=""),"Overdue","On track")),IF(C8="PBI Dev",IF(R8="","No target set",IF(AND(R8<TODAY(),T8=""),"Overdue","On track")),IF(C8="QA",IF(V8="","No target set",IF(AND(V8<TODAY(),X8=""),"Overdue","On track")),IF(C8="DPO Approval",IF(Z8="","No target set",IF(Z8<TODAY(),"Overdue","On track")),IF(C8="RELEASED IN PROD","Delivered",""))))))) -> Delivered | E8: 7 | G8: Sreevarsha | H8: Navya | I8: Preety | K8: 46142 | L8: April | P8: 46122 | T8: 46126 | X8: 46122 | AA8: Kelvin Hu | AB8: Yes | AD8: https://app.powerbi.com/groups/me/apps/eedba83d-be9a-45f9-9504-7bfa41e6051a/reports/383c1502-9c3c-4fa0-a321-321cfed3b4a1/ReportSection1e63b8fbeb9ea54074e1?experience=power-bi | AE8: https://app.powerbi.com/groups/me/apps/2c7180b1-0d3d-45be-979e-f7dc86b3557d/reports/b7f15195-22d6-4ac4-8982-a8cadb215cbf/ReportSection1e63b8fbeb9ea54074e1?ctid=f98a6a53-25f3-4212-901c-c7787fcd3495&experience=power-bi | AF8: No | AH8: =IF($AF8="Yes",IF($AG8<>"","Blocked - needs "&$AG8&" to fix","Blocked at "&$C8),"") | AI8: =IF($B8="","",COUNTIF('Rework Log'!$A$3:$A$500,$B8)) -> 0 | AJ8: =IF(OR($B8="",$AR8=0),"",INDEX('Rework Log'!$C:$C,$AR8)) | AK8: =IF(OR($B8="",$AR8=0),"",INDEX('Rework Log'!$H:$H,$AR8)) | AL8: =IF(OR($B8="",$AR8=0),"",INDEX('Rework Log'!$G:$G,$AR8)) | AM8: =IF($B8="","",IF(Z8<>"","DPO Approval",IF(V8<>"","QA",IF(R8<>"","PBI Dev",IF(N8<>"","DB Dev","NOT STARTED"))))) -> NOT STARTED | AN8: =IF($B8="","",IF(IF($C8="NOT STARTED",0,IF($C8="DB Dev",1,IF($C8="PBI Dev",2,IF($C8="QA",3,IF($C8="DPO Approval",4,IF($C8="RELEASED IN PROD",5,-1))))))<IF($AM8="NOT STARTED",0,IF($AM8="DB Dev",1,IF($AM8="PBI Dev",2,IF($AM8="QA",3,IF($AM8="DPO Approval",4,IF($AM8="RELEASED IN PROD",5,-1)))))),"Yes - was already at "&$AM8&", now back at "&$C8,"No")) -> No | AO8: =IF($B8="","",IF(AND(V8<>"",N8<>"",V8<N8),"QA target is before DB Dev target",IF(AND(V8<>"",R8<>"",V8<R8),"QA target is before PBI Dev target",IF(AND(Z8<>"",V8<>"",Z8<V8),"DPO Approval target is before QA target",IF(AND(AC8<>"",Z8<>"",AC8<Z8),"Confirmed Deployed date is before DPO Approval target",""))))) | AP8: =IF($B8="","",IF(COUNTIF($B$2:$B$500,$B8)>1,"Duplicate name - check row","")) | AR8: =IF($B8="","",SUMPRODUCT(MAX(('Rework Log'!$A$3:$A$500=$B8)*ROW('Rework Log'!$A$3:$A$500)))) -> 0
A9: Leaks | B9: RPT_04_Prior Leak Readings | C9: RELEASED IN PROD | D9: =IF($B9="","",IF(C9="NOT STARTED",IF(K9="","No plan date set",IF(K9<TODAY(),"Review - planned start passed","On track")),IF(C9="DB Dev",IF(N9="","No target set",IF(AND(N9<TODAY(),P9=""),"Overdue","On track")),IF(C9="PBI Dev",IF(R9="","No target set",IF(AND(R9<TODAY(),T9=""),"Overdue","On track")),IF(C9="QA",IF(V9="","No target set",IF(AND(V9<TODAY(),X9=""),"Overdue","On track")),IF(C9="DPO Approval",IF(Z9="","No target set",IF(Z9<TODAY(),"Overdue","On track")),IF(C9="RELEASED IN PROD","Delivered",""))))))) -> Delivered | E9: 9 | G9: Siddu | H9: Navya | I9: Preety | K9: 46142 | L9: April | P9: 46122 | T9: 46126 | X9: 46122 | AA9: Kelvin Hu | AB9: Yes | AD9: https://app.powerbi.com/groups/me/apps/7767030c-f4c8-4488-b3cb-36a860cb6ff2/reports/acc74ccc-08b7-420d-b64e-5e4d786ac711/ReportSection6d915001f68ea4805272?experience=power-bi | AE9: https://app.powerbi.com/groups/me/apps/5b29b0dd-a398-4801-84ce-f3a7d8435827/reports/5a06a5bd-88fb-4024-8841-570da23785ad/ReportSection6d915001f68ea4805272?ctid=f98a6a53-25f3-4212-901c-c7787fcd3495&experience=power-bi | AF9: No | AH9: =IF($AF9="Yes",IF($AG9<>"","Blocked - needs "&$AG9&" to fix","Blocked at "&$C9),"") | AI9: =IF($B9="","",COUNTIF('Rework Log'!$A$3:$A$500,$B9)) -> 0 | AJ9: =IF(OR($B9="",$AR9=0),"",INDEX('Rework Log'!$C:$C,$AR9)) | AK9: =IF(OR($B9="",$AR9=0),"",INDEX('Rework Log'!$H:$H,$AR9)) | AL9: =IF(OR($B9="",$AR9=0),"",INDEX('Rework Log'!$G:$G,$AR9)) | AM9: =IF($B9="","",IF(Z9<>"","DPO Approval",IF(V9<>"","QA",IF(R9<>"","PBI Dev",IF(N9<>"","DB Dev","NOT STARTED"))))) -> NOT STARTED | AN9: =IF($B9="","",IF(IF($C9="NOT STARTED",0,IF($C9="DB Dev",1,IF($C9="PBI Dev",2,IF($C9="QA",3,IF($C9="DPO Approval",4,IF($C9="RELEASED IN PROD",5,-1))))))<IF($AM9="NOT STARTED",0,IF($AM9="DB Dev",1,IF($AM9="PBI Dev",2,IF($AM9="QA",3,IF($AM9="DPO Approval",4,IF($AM9="RELEASED IN PROD",5,-1)))))),"Yes - was already at "&$AM9&", now back at "&$C9,"No")) -> No | AO9: =IF($B9="","",IF(AND(V9<>"",N9<>"",V9<N9),"QA target is before DB Dev target",IF(AND(V9<>"",R9<>"",V9<R9),"QA target is before PBI Dev target",IF(AND(Z9<>"",V9<>"",Z9<V9),"DPO Approval target is before QA target",IF(AND(AC9<>"",Z9<>"",AC9<Z9),"Confirmed Deployed date is before DPO Approval target",""))))) | AP9: =IF($B9="","",IF(COUNTIF($B$2:$B$500,$B9)>1,"Duplicate name - check row","")) | AR9: =IF($B9="","",SUMPRODUCT(MAX(('Rework Log'!$A$3:$A$500=$B9)*ROW('Rework Log'!$A$3:$A$500)))) -> 0
A10: Leaks | B10: RSS_04_Leak Grade Change History | C10: RELEASED IN PROD | D10: =IF($B10="","",IF(C10="NOT STARTED",IF(K10="","No plan date set",IF(K10<TODAY(),"Review - planned start passed","On track")),IF(C10="DB Dev",IF(N10="","No target set",IF(AND(N10<TODAY(),P10=""),"Overdue","On track")),IF(C10="PBI Dev",IF(R10="","No target set",IF(AND(R10<TODAY(),T10=""),"Overdue","On track")),IF(C10="QA",IF(V10="","No target set",IF(AND(V10<TODAY(),X10=""),"Overdue","On track")),IF(C10="DPO Approval",IF(Z10="","No target set",IF(Z10<TODAY(),"Overdue","On track")),IF(C10="RELEASED IN PROD","Delivered",""))))))) -> Delivered | E10: 8 | G10: Siva | H10: Navya | I10: Preety | K10: 46142 | L10: April | P10: 46127 | T10: 46126 | X10: 46122 | AA10: Kelvin Hu | AB10: Yes | AD10: https://app.powerbi.com/groups/me/apps/7767030c-f4c8-4488-b3cb-36a860cb6ff2/reports/6fe40f7b-3dfe-45ee-9f81-cb977321242d/9d7e292e8fb40cfee194?experience=power-bi | AE10: https://app.powerbi.com/groups/me/apps/5b29b0dd-a398-4801-84ce-f3a7d8435827/reports/4268caf5-dcbd-4b00-8518-baf8239fff69/9d7e292e8fb40cfee194?experience=power-bi | AF10: No | AH10: =IF($AF10="Yes",IF($AG10<>"","Blocked - needs "&$AG10&" to fix","Blocked at "&$C10),"") | AI10: =IF($B10="","",COUNTIF('Rework Log'!$A$3:$A$500,$B10)) -> 0 | AJ10: =IF(OR($B10="",$AR10=0),"",INDEX('Rework Log'!$C:$C,$AR10)) | AK10: =IF(OR($B10="",$AR10=0),"",INDEX('Rework Log'!$H:$H,$AR10)) | AL10: =IF(OR($B10="",$AR10=0),"",INDEX('Rework Log'!$G:$G,$AR10)) | AM10: =IF($B10="","",IF(Z10<>"","DPO Approval",IF(V10<>"","QA",IF(R10<>"","PBI Dev",IF(N10<>"","DB Dev","NOT STARTED"))))) -> NOT STARTED | AN10: =IF($B10="","",IF(IF($C10="NOT STARTED",0,IF($C10="DB Dev",1,IF($C10="PBI Dev",2,IF($C10="QA",3,IF($C10="DPO Approval",4,IF($C10="RELEASED IN PROD",5,-1))))))<IF($AM10="NOT STARTED",0,IF($AM10="DB Dev",1,IF($AM10="PBI Dev",2,IF($AM10="QA",3,IF($AM10="DPO Approval",4,IF($AM10="RELEASED IN PROD",5,-1)))))),"Yes - was already at "&$AM10&", now back at "&$C10,"No")) -> No | AO10: =IF($B10="","",IF(AND(V10<>"",N10<>"",V10<N10),"QA target is before DB Dev target",IF(AND(V10<>"",R10<>"",V10<R10),"QA target is before PBI Dev target",IF(AND(Z10<>"",V10<>"",Z10<V10),"DPO Approval target is before QA target",IF(AND(AC10<>"",Z10<>"",AC10<Z10),"Confirmed Deployed date is before DPO Approval target",""))))) | AP10: =IF($B10="","",IF(COUNTIF($B$2:$B$500,$B10)>1,"Duplicate name - check row","")) | AQ10: 23/4 - Testing completed in QA and defect created https://jira.prod.nationalgrid.com/browse/GDMP-2227; Report is ready for testing 04/23/2026 | AR10: =IF($B10="","",SUMPRODUCT(MAX(('Rework Log'!$A$3:$A$500=$B10)*ROW('Rework Log'!$A$3:$A$500)))) -> 0
A11: Leaks | B11: RPT_04_Surveillances With Zero Readings | C11: RELEASED IN PROD | D11: =IF($B11="","",IF(C11="NOT STARTED",IF(K11="","No plan date set",IF(K11<TODAY(),"Review - planned start passed","On track")),IF(C11="DB Dev",IF(N11="","No target set",IF(AND(N11<TODAY(),P11=""),"Overdue","On track")),IF(C11="PBI Dev",IF(R11="","No target set",IF(AND(R11<TODAY(),T11=""),"Overdue","On track")),IF(C11="QA",IF(V11="","No target set",IF(AND(V11<TODAY(),X11=""),"Overdue","On track")),IF(C11="DPO Approval",IF(Z11="","No target set",IF(Z11<TODAY(),"Overdue","On track")),IF(C11="RELEASED IN PROD","Delivered",""))))))) -> Delivered | E11: 10 | G11: Sreevarsha | H11: Navya | I11: Kelvin | K11: 46173 | L11: May | T11: 46139 | X11: 46139 | AA11: Kelvin Hu | AB11: Yes | AD11: https://app.powerbi.com/groups/me/apps/eedba83d-be9a-45f9-9504-7bfa41e6051a/reports/743b79eb-5470-4cd4-ad54-81eb3b409ae8/ea184ec020032ecbdd43?ctid=f98a6a53-25f3-4212-901c-c7787fcd3495&experience=power-bi | AE11: https://app.powerbi.com/groups/me/apps/2c7180b1-0d3d-45be-979e-f7dc86b3557d/reports/c887cd5e-9172-4de3-921e-2c0edd2533bc/ea184ec020032ecbdd43?experience=power-bi | AF11: No | AH11: =IF($AF11="Yes",IF($AG11<>"","Blocked - needs "&$AG11&" to fix","Blocked at "&$C11),"") | AI11: =IF($B11="","",COUNTIF('Rework Log'!$A$3:$A$500,$B11)) -> 0 | AJ11: =IF(OR($B11="",$AR11=0),"",INDEX('Rework Log'!$C:$C,$AR11)) | AK11: =IF(OR($B11="",$AR11=0),"",INDEX('Rework Log'!$H:$H,$AR11)) | AL11: =IF(OR($B11="",$AR11=0),"",INDEX('Rework Log'!$G:$G,$AR11)) | AM11: =IF($B11="","",IF(Z11<>"","DPO Approval",IF(V11<>"","QA",IF(R11<>"","PBI Dev",IF(N11<>"","DB Dev","NOT STARTED"))))) -> NOT STARTED | AN11: =IF($B11="","",IF(IF($C11="NOT STARTED",0,IF($C11="DB Dev",1,IF($C11="PBI Dev",2,IF($C11="QA",3,IF($C11="DPO Approval",4,IF($C11="RELEASED IN PROD",5,-1))))))<IF($AM11="NOT STARTED",0,IF($AM11="DB Dev",1,IF($AM11="PBI Dev",2,IF($AM11="QA",3,IF($AM11="DPO Approval",4,IF($AM11="RELEASED IN PROD",5,-1)))))),"Yes - was already at "&$AM11&", now back at "&$C11,"No")) -> No | AO11: =IF($B11="","",IF(AND(V11<>"",N11<>"",V11<N11),"QA target is before DB Dev target",IF(AND(V11<>"",R11<>"",V11<R11),"QA target is before PBI Dev target",IF(AND(Z11<>"",V11<>"",Z11<V11),"DPO Approval target is before QA target",IF(AND(AC11<>"",Z11<>"",AC11<Z11),"Confirmed Deployed date is before DPO Approval target",""))))) | AP11: =IF($B11="","",IF(COUNTIF($B$2:$B$500,$B11)>1,"Duplicate name - check row","")) | AR11: =IF($B11="","",SUMPRODUCT(MAX(('Rework Log'!$A$3:$A$500=$B11)*ROW('Rework Log'!$A$3:$A$500)))) -> 0
A12: Leaks | B12: RPT_04 High Emitter leaks | C12: RELEASED IN PROD | D12: =IF($B12="","",IF(C12="NOT STARTED",IF(K12="","No plan date set",IF(K12<TODAY(),"Review - planned start passed","On track")),IF(C12="DB Dev",IF(N12="","No target set",IF(AND(N12<TODAY(),P12=""),"Overdue","On track")),IF(C12="PBI Dev",IF(R12="","No target set",IF(AND(R12<TODAY(),T12=""),"Overdue","On track")),IF(C12="QA",IF(V12="","No target set",IF(AND(V12<TODAY(),X12=""),"Overdue","On track")),IF(C12="DPO Approval",IF(Z12="","No target set",IF(Z12<TODAY(),"Overdue","On track")),IF(C12="RELEASED IN PROD","Delivered",""))))))) -> Delivered | E12: 11 | G12: Sreevarsha | H12: Navya | I12: Preety | K12: 46173 | L12: May | T12: 46141 | X12: 46141 | AA12: Kelvin Hu | AB12: Yes | AD12: https://app.powerbi.com/groups/me/apps/61b18507-2848-49b9-aacc-32c49ffe1e0b/reports/a44e7124-b1d0-4a09-a5d1-157e2043ba8e/ea184ec020032ecbdd43?ctid=f98a6a53-25f3-4212-901c-c7787fcd3495&experience=power-bi | AE12: https://app.powerbi.com/groups/me/apps/93d01997-58e0-48d8-bcca-ad8377094e64/reports/6d6fe558-e5d6-4a4b-b6fb-8a5f8735d1df/ea184ec020032ecbdd43?experience=power-bi | AF12: No | AH12: =IF($AF12="Yes",IF($AG12<>"","Blocked - needs "&$AG12&" to fix","Blocked at "&$C12),"") | AI12: =IF($B12="","",COUNTIF('Rework Log'!$A$3:$A$500,$B12)) -> 0 | AJ12: =IF(OR($B12="",$AR12=0),"",INDEX('Rework Log'!$C:$C,$AR12)) | AK12: =IF(OR($B12="",$AR12=0),"",INDEX('Rework Log'!$H:$H,$AR12)) | AL12: =IF(OR($B12="",$AR12=0),"",INDEX('Rework Log'!$G:$G,$AR12)) | AM12: =IF($B12="","",IF(Z12<>"","DPO Approval",IF(V12<>"","QA",IF(R12<>"","PBI Dev",IF(N12<>"","DB Dev","NOT STARTED"))))) -> NOT STARTED | AN12: =IF($B12="","",IF(IF($C12="NOT STARTED",0,IF($C12="DB Dev",1,IF($C12="PBI Dev",2,IF($C12="QA",3,IF($C12="DPO Approval",4,IF($C12="RELEASED IN PROD",5,-1))))))<IF($AM12="NOT STARTED",0,IF($AM12="DB Dev",1,IF($AM12="PBI Dev",2,IF($AM12="QA",3,IF($AM12="DPO Approval",4,IF($AM12="RELEASED IN PROD",5,-1)))))),"Yes - was already at "&$AM12&", now back at "&$C12,"No")) -> No | AO12: =IF($B12="","",IF(AND(V12<>"",N12<>"",V12<N12),"QA target is before DB Dev target",IF(AND(V12<>"",R12<>"",V12<R12),"QA target is before PBI Dev target",IF(AND(Z12<>"",V12<>"",Z12<V12),"DPO Approval target is before QA target",IF(AND(AC12<>"",Z12<>"",AC12<Z12),"Confirmed Deployed date is before DPO Approval target",""))))) | AP12: =IF($B12="","",IF(COUNTIF($B$2:$B$500,$B12)>1,"Duplicate name - check row","")) | AQ12: 05/05- defect raised https://jira.prod.nationalgrid.com/browse/GDMP-2230 | AR12: =IF($B12="","",SUMPRODUCT(MAX(('Rework Log'!$A$3:$A$500=$B12)*ROW('Rework Log'!$A$3:$A$500)))) -> 0
A13: Leaks | B13: RPT_04_School Zone Leaks Without Repair | C13: RELEASED IN PROD | D13: =IF($B13="","",IF(C13="NOT STARTED",IF(K13="","No plan date set",IF(K13<TODAY(),"Review - planned start passed","On track")),IF(C13="DB Dev",IF(N13="","No target set",IF(AND(N13<TODAY(),P13=""),"Overdue","On track")),IF(C13="PBI Dev",IF(R13="","No target set",IF(AND(R13<TODAY(),T13=""),"Overdue","On track")),IF(C13="QA",IF(V13="","No target set",IF(AND(V13<TODAY(),X13=""),"Overdue","On track")),IF(C13="DPO Approval",IF(Z13="","No target set",IF(Z13<TODAY(),"Overdue","On track")),IF(C13="RELEASED IN PROD","Delivered",""))))))) -> Delivered | E13: 12 | G13: Sreevarsha | H13: Sarath | I13: Preety | K13: 46173 | L13: May | T13: 46161 | X13: 46161 | AA13: Kelvin Hu | AB13: Yes | AD13: https://app.powerbi.com/groups/me/apps/eedba83d-be9a-45f9-9504-7bfa41e6051a/reports/0f3b2c1d-09ad-45db-9786-31e8c9401bc4/ReportSectionda782bb6769340acca9d?experience=power-bi | AE13: https://app.powerbi.com/groups/me/apps/2c7180b1-0d3d-45be-979e-f7dc86b3557d/reports/5e101b4d-8b08-431a-8b3a-04aafc85f314/ReportSection1e63b8fbeb9ea54074e1?experience=power-bi | AF13: No | AH13: =IF($AF13="Yes",IF($AG13<>"","Blocked - needs "&$AG13&" to fix","Blocked at "&$C13),"") | AI13: =IF($B13="","",COUNTIF('Rework Log'!$A$3:$A$500,$B13)) -> 0 | AJ13: =IF(OR($B13="",$AR13=0),"",INDEX('Rework Log'!$C:$C,$AR13)) | AK13: =IF(OR($B13="",$AR13=0),"",INDEX('Rework Log'!$H:$H,$AR13)) | AL13: =IF(OR($B13="",$AR13=0),"",INDEX('Rework Log'!$G:$G,$AR13)) | AM13: =IF($B13="","",IF(Z13<>"","DPO Approval",IF(V13<>"","QA",IF(R13<>"","PBI Dev",IF(N13<>"","DB Dev","NOT STARTED"))))) -> NOT STARTED | AN13: =IF($B13="","",IF(IF($C13="NOT STARTED",0,IF($C13="DB Dev",1,IF($C13="PBI Dev",2,IF($C13="QA",3,IF($C13="DPO Approval",4,IF($C13="RELEASED IN PROD",5,-1))))))<IF($AM13="NOT STARTED",0,IF($AM13="DB Dev",1,IF($AM13="PBI Dev",2,IF($AM13="QA",3,IF($AM13="DPO Approval",4,IF($AM13="RELEASED IN PROD",5,-1)))))),"Yes - was already at "&$AM13&", now back at "&$C13,"No")) -> No | AO13: =IF($B13="","",IF(AND(V13<>"",N13<>"",V13<N13),"QA target is before DB Dev target",IF(AND(V13<>"",R13<>"",V13<R13),"QA target is before PBI Dev target",IF(AND(Z13<>"",V13<>"",Z13<V13),"DPO Approval target is before QA target",IF(AND(AC13<>"",Z13<>"",AC13<Z13),"Confirmed Deployed date is before DPO Approval target",""))))) | AP13: =IF($B13="","",IF(COUNTIF($B$2:$B$500,$B13)>1,"Duplicate name - check row","")) | AR13: =IF($B13="","",SUMPRODUCT(MAX(('Rework Log'!$A$3:$A$500=$B13)*ROW('Rework Log'!$A$3:$A$500)))) -> 0
A14: Leaks | B14: RPT_04_PSC Quarterly Leak | C14: RELEASED IN PROD | D14: =IF($B14="","",IF(C14="NOT STARTED",IF(K14="","No plan date set",IF(K14<TODAY(),"Review - planned start passed","On track")),IF(C14="DB Dev",IF(N14="","No target set",IF(AND(N14<TODAY(),P14=""),"Overdue","On track")),IF(C14="PBI Dev",IF(R14="","No target set",IF(AND(R14<TODAY(),T14=""),"Overdue","On track")),IF(C14="QA",IF(V14="","No target set",IF(AND(V14<TODAY(),X14=""),"Overdue","On track")),IF(C14="DPO Approval",IF(Z14="","No target set",IF(Z14<TODAY(),"Overdue","On track")),IF(C14="RELEASED IN PROD","Delivered",""))))))) -> Delivered | E14: 13 | G14: Geetha | H14: Sarath | I14: Kelvin | K14: 46173 | L14: May | T14: 46175 | X14: 46175 | AA14: Kelvin Hu | AB14: Yes | AC14: 46184 | AE14: https://app.powerbi.com/groups/me/apps/93d01997-58e0-48d8-bcca-ad8377094e64/reports/bda83ba5-3e9d-4f8d-9496-bf14e91f7b20/ccfe9e7f0a40d49acb85?ctid=f98a6a53-25f3-4212-901c-c7787fcd3495&experience=power-bi | AF14: No | AH14: =IF($AF14="Yes",IF($AG14<>"","Blocked - needs "&$AG14&" to fix","Blocked at "&$C14),"") | AI14: =IF($B14="","",COUNTIF('Rework Log'!$A$3:$A$500,$B14)) -> 0 | AJ14: =IF(OR($B14="",$AR14=0),"",INDEX('Rework Log'!$C:$C,$AR14)) | AK14: =IF(OR($B14="",$AR14=0),"",INDEX('Rework Log'!$H:$H,$AR14)) | AL14: =IF(OR($B14="",$AR14=0),"",INDEX('Rework Log'!$G:$G,$AR14)) | AM14: =IF($B14="","",IF(Z14<>"","DPO Approval",IF(V14<>"","QA",IF(R14<>"","PBI Dev",IF(N14<>"","DB Dev","NOT STARTED"))))) -> NOT STARTED | AN14: =IF($B14="","",IF(IF($C14="NOT STARTED",0,IF($C14="DB Dev",1,IF($C14="PBI Dev",2,IF($C14="QA",3,IF($C14="DPO Approval",4,IF($C14="RELEASED IN PROD",5,-1))))))<IF($AM14="NOT STARTED",0,IF($AM14="DB Dev",1,IF($AM14="PBI Dev",2,IF($AM14="QA",3,IF($AM14="DPO Approval",4,IF($AM14="RELEASED IN PROD",5,-1)))))),"Yes - was already at "&$AM14&", now back at "&$C14,"No")) -> No | AO14: =IF($B14="","",IF(AND(V14<>"",N14<>"",V14<N14),"QA target is before DB Dev target",IF(AND(V14<>"",R14<>"",V14<R14),"QA target is before PBI Dev target",IF(AND(Z14<>"",V14<>"",Z14<V14),"DPO Approval target is before QA target",IF(AND(AC14<>"",Z14<>"",AC14<Z14),"Confirmed Deployed date is before DPO Approval target",""))))) | AP14: =IF($B14="","",IF(COUNTIF($B$2:$B$500,$B14)>1,"Duplicate name - check row","")) | AR14: =IF($B14="","",SUMPRODUCT(MAX(('Rework Log'!$A$3:$A$500=$B14)*ROW('Rework Log'!$A$3:$A$500)))) -> 0
A15: Leaks | B15: RPT_04_Rechecks Completed less than 14 days | C15: RELEASED IN PROD | D15: =IF($B15="","",IF(C15="NOT STARTED",IF(K15="","No plan date set",IF(K15<TODAY(),"Review - planned start passed","On track")),IF(C15="DB Dev",IF(N15="","No target set",IF(AND(N15<TODAY(),P15=""),"Overdue","On track")),IF(C15="PBI Dev",IF(R15="","No target set",IF(AND(R15<TODAY(),T15=""),"Overdue","On track")),IF(C15="QA",IF(V15="","No target set",IF(AND(V15<TODAY(),X15=""),"Overdue","On track")),IF(C15="DPO Approval",IF(Z15="","No target set",IF(Z15<TODAY(),"Overdue","On track")),IF(C15="RELEASED IN PROD","Delivered",""))))))) -> Delivered | E15: 14 | G15: Rupa | H15: Shraddha | I15: Preety | K15: 46173 | L15: May | T15: 46134 | X15: 46134 | AA15: Kelvin Hu | AB15: Yes | AD15: https://app.powerbi.com/groups/me/apps/7767030c-f4c8-4488-b3cb-36a860cb6ff2/reports/de1ad11f-021b-4cc1-b465-67efd542031c/3122b8024291693794eb?ctid=f98a6a53-25f3-4212-901c-c7787fcd3495&experience=power-bi | AE15: https://app.powerbi.com/groups/me/apps/5b29b0dd-a398-4801-84ce-f3a7d8435827/reports/0e063b20-0b38-4000-b436-fcbec11daa46/3122b8024291693794eb?experience=power-bi | AF15: No | AH15: =IF($AF15="Yes",IF($AG15<>"","Blocked - needs "&$AG15&" to fix","Blocked at "&$C15),"") | AI15: =IF($B15="","",COUNTIF('Rework Log'!$A$3:$A$500,$B15)) -> 0 | AJ15: =IF(OR($B15="",$AR15=0),"",INDEX('Rework Log'!$C:$C,$AR15)) | AK15: =IF(OR($B15="",$AR15=0),"",INDEX('Rework Log'!$H:$H,$AR15)) | AL15: =IF(OR($B15="",$AR15=0),"",INDEX('Rework Log'!$G:$G,$AR15)) | AM15: =IF($B15="","",IF(Z15<>"","DPO Approval",IF(V15<>"","QA",IF(R15<>"","PBI Dev",IF(N15<>"","DB Dev","NOT STARTED"))))) -> NOT STARTED | AN15: =IF($B15="","",IF(IF($C15="NOT STARTED",0,IF($C15="DB Dev",1,IF($C15="PBI Dev",2,IF($C15="QA",3,IF($C15="DPO Approval",4,IF($C15="RELEASED IN PROD",5,-1))))))<IF($AM15="NOT STARTED",0,IF($AM15="DB Dev",1,IF($AM15="PBI Dev",2,IF($AM15="QA",3,IF($AM15="DPO Approval",4,IF($AM15="RELEASED IN PROD",5,-1)))))),"Yes - was already at "&$AM15&", now back at "&$C15,"No")) -> No | AO15: =IF($B15="","",IF(AND(V15<>"",N15<>"",V15<N15),"QA target is before DB Dev target",IF(AND(V15<>"",R15<>"",V15<R15),"QA target is before PBI Dev target",IF(AND(Z15<>"",V15<>"",Z15<V15),"DPO Approval target is before QA target",IF(AND(AC15<>"",Z15<>"",AC15<Z15),"Confirmed Deployed date is before DPO Approval target",""))))) | AP15: =IF($B15="","",IF(COUNTIF($B$2:$B$500,$B15)>1,"Duplicate name - check row","")) | AR15: =IF($B15="","",SUMPRODUCT(MAX(('Rework Log'!$A$3:$A$500=$B15)*ROW('Rework Log'!$A$3:$A$500)))) -> 0
A16: Leaks | B16: RPT_04_SEI Leak Activity | C16: RELEASED IN PROD | D16: =IF($B16="","",IF(C16="NOT STARTED",IF(K16="","No plan date set",IF(K16<TODAY(),"Review - planned start passed","On track")),IF(C16="DB Dev",IF(N16="","No target set",IF(AND(N16<TODAY(),P16=""),"Overdue","On track")),IF(C16="PBI Dev",IF(R16="","No target set",IF(AND(R16<TODAY(),T16=""),"Overdue","On track")),IF(C16="QA",IF(V16="","No target set",IF(AND(V16<TODAY(),X16=""),"Overdue","On track")),IF(C16="DPO Approval",IF(Z16="","No target set",IF(Z16<TODAY(),"Overdue","On track")),IF(C16="RELEASED IN PROD","Delivered",""))))))) -> Delivered | E16: 15 | G16: Siva | H16: Shraddha | I16: Preety | K16: 46173 | L16: May | T16: 46139 | X16: 46139 | AA16: Kelvin Hu | AB16: Yes | AD16: https://app.powerbi.com/groups/me/apps/7767030c-f4c8-4488-b3cb-36a860cb6ff2/reports/c76693f4-bab2-46a1-ab2a-16752d7664fd/ea184ec020032ecbdd43?experience=power-bi | AE16: https://app.powerbi.com/groups/me/apps/5b29b0dd-a398-4801-84ce-f3a7d8435827/reports/9d9f5721-feb1-4ed3-91fd-18bc33ef38f1/ea184ec020032ecbdd43?experience=power-bi | AF16: No | AH16: =IF($AF16="Yes",IF($AG16<>"","Blocked - needs "&$AG16&" to fix","Blocked at "&$C16),"") | AI16: =IF($B16="","",COUNTIF('Rework Log'!$A$3:$A$500,$B16)) -> 0 | AJ16: =IF(OR($B16="",$AR16=0),"",INDEX('Rework Log'!$C:$C,$AR16)) | AK16: =IF(OR($B16="",$AR16=0),"",INDEX('Rework Log'!$H:$H,$AR16)) | AL16: =IF(OR($B16="",$AR16=0),"",INDEX('Rework Log'!$G:$G,$AR16)) | AM16: =IF($B16="","",IF(Z16<>"","DPO Approval",IF(V16<>"","QA",IF(R16<>"","PBI Dev",IF(N16<>"","DB Dev","NOT STARTED"))))) -> NOT STARTED | AN16: =IF($B16="","",IF(IF($C16="NOT STARTED",0,IF($C16="DB Dev",1,IF($C16="PBI Dev",2,IF($C16="QA",3,IF($C16="DPO Approval",4,IF($C16="RELEASED IN PROD",5,-1))))))<IF($AM16="NOT STARTED",0,IF($AM16="DB Dev",1,IF($AM16="PBI Dev",2,IF($AM16="QA",3,IF($AM16="DPO Approval",4,IF($AM16="RELEASED IN PROD",5,-1)))))),"Yes - was already at "&$AM16&", now back at "&$C16,"No")) -> No | AO16: =IF($B16="","",IF(AND(V16<>"",N16<>"",V16<N16),"QA target is before DB Dev target",IF(AND(V16<>"",R16<>"",V16<R16),"QA target is before PBI Dev target",IF(AND(Z16<>"",V16<>"",Z16<V16),"DPO Approval target is before QA target",IF(AND(AC16<>"",Z16<>"",AC16<Z16),"Confirmed Deployed date is before DPO Approval target",""))))) | AP16: =IF($B16="","",IF(COUNTIF($B$2:$B$500,$B16)>1,"Duplicate name - check row","")) | AR16: =IF($B16="","",SUMPRODUCT(MAX(('Rework Log'!$A$3:$A$500=$B16)*ROW('Rework Log'!$A$3:$A$500)))) -> 0
A17: Leaks | B17: RPT_04_CMS Leak Productivity | C17: RELEASED IN PROD | D17: =IF($B17="","",IF(C17="NOT STARTED",IF(K17="","No plan date set",IF(K17<TODAY(),"Review - planned start passed","On track")),IF(C17="DB Dev",IF(N17="","No target set",IF(AND(N17<TODAY(),P17=""),"Overdue","On track")),IF(C17="PBI Dev",IF(R17="","No target set",IF(AND(R17<TODAY(),T17=""),"Overdue","On track")),IF(C17="QA",IF(V17="","No target set",IF(AND(V17<TODAY(),X17=""),"Overdue","On track")),IF(C17="DPO Approval",IF(Z17="","No target set",IF(Z17<TODAY(),"Overdue","On track")),IF(C17="RELEASED IN PROD","Delivered",""))))))) -> Delivered | E17: 16 | G17: Siddu | H17: Navya | I17: Preety | K17: 46173 | L17: May | T17: 46147 | X17: 46147 | AA17: Kelvin Hu | AB17: Yes | AD17: https://app.powerbi.com/groups/me/apps/eedba83d-be9a-45f9-9504-7bfa41e6051a/reports/3440832e-c72e-45f2-b154-f6b1d66314fc/51a6cefeab19522827a6?experience=power-bi | AE17: https://app.powerbi.com/groups/me/apps/2c7180b1-0d3d-45be-979e-f7dc86b3557d/reports/18e31a06-f1af-4965-ad46-5a507f24ed56/51a6cefeab19522827a6?experience=power-bi | AF17: No | AH17: =IF($AF17="Yes",IF($AG17<>"","Blocked - needs "&$AG17&" to fix","Blocked at "&$C17),"") | AI17: =IF($B17="","",COUNTIF('Rework Log'!$A$3:$A$500,$B17)) -> 0 | AJ17: =IF(OR($B17="",$AR17=0),"",INDEX('Rework Log'!$C:$C,$AR17)) | AK17: =IF(OR($B17="",$AR17=0),"",INDEX('Rework Log'!$H:$H,$AR17)) | AL17: =IF(OR($B17="",$AR17=0),"",INDEX('Rework Log'!$G:$G,$AR17)) | AM17: =IF($B17="","",IF(Z17<>"","DPO Approval",IF(V17<>"","QA",IF(R17<>"","PBI Dev",IF(N17<>"","DB Dev","NOT STARTED"))))) -> NOT STARTED | AN17: =IF($B17="","",IF(IF($C17="NOT STARTED",0,IF($C17="DB Dev",1,IF($C17="PBI Dev",2,IF($C17="QA",3,IF($C17="DPO Approval",4,IF($C17="RELEASED IN PROD",5,-1))))))<IF($AM17="NOT STARTED",0,IF($AM17="DB Dev",1,IF($AM17="PBI Dev",2,IF($AM17="QA",3,IF($AM17="DPO Approval",4,IF($AM17="RELEASED IN PROD",5,-1)))))),"Yes - was already at "&$AM17&", now back at "&$C17,"No")) -> No | AO17: =IF($B17="","",IF(AND(V17<>"",N17<>"",V17<N17),"QA target is before DB Dev target",IF(AND(V17<>"",R17<>"",V17<R17),"QA target is before PBI Dev target",IF(AND(Z17<>"",V17<>"",Z17<V17),"DPO Approval target is before QA target",IF(AND(AC17<>"",Z17<>"",AC17<Z17),"Confirmed Deployed date is before DPO Approval target",""))))) | AP17: =IF($B17="","",IF(COUNTIF($B$2:$B$500,$B17)>1,"Duplicate name - check row","")) | AR17: =IF($B17="","",SUMPRODUCT(MAX(('Rework Log'!$A$3:$A$500=$B17)*ROW('Rework Log'!$A$3:$A$500)))) -> 0
A18: Leaks | B18: RPT_04_Main Break Corrosion and Leak Cluster | C18: RELEASED IN PROD | D18: =IF($B18="","",IF(C18="NOT STARTED",IF(K18="","No plan date set",IF(K18<TODAY(),"Review - planned start passed","On track")),IF(C18="DB Dev",IF(N18="","No target set",IF(AND(N18<TODAY(),P18=""),"Overdue","On track")),IF(C18="PBI Dev",IF(R18="","No target set",IF(AND(R18<TODAY(),T18=""),"Overdue","On track")),IF(C18="QA",IF(V18="","No target set",IF(AND(V18<TODAY(),X18=""),"Overdue","On track")),IF(C18="DPO Approval",IF(Z18="","No target set",IF(Z18<TODAY(),"Overdue","On track")),IF(C18="RELEASED IN PROD","Delivered",""))))))) -> Delivered | E18: 17 | G18: Siddu | H18: Sarath | I18: Kelvin | K18: 46173 | L18: May | T18: 46175 | X18: 46179 | AA18: Kelvin Hu | AD18: https://app.powerbi.com/groups/me/apps/eedba83d-be9a-45f9-9504-7bfa41e6051a/reports/efc0a204-1a7b-4be6-8334-c7582c9093b8/ReportSection81bc1123208781ca563a?experience=power-bi | AF18: No | AH18: =IF($AF18="Yes",IF($AG18<>"","Blocked - needs "&$AG18&" to fix","Blocked at "&$C18),"") | AI18: =IF($B18="","",COUNTIF('Rework Log'!$A$3:$A$500,$B18)) -> 0 | AJ18: =IF(OR($B18="",$AR18=0),"",INDEX('Rework Log'!$C:$C,$AR18)) | AK18: =IF(OR($B18="",$AR18=0),"",INDEX('Rework Log'!$H:$H,$AR18)) | AL18: =IF(OR($B18="",$AR18=0),"",INDEX('Rework Log'!$G:$G,$AR18)) | AM18: =IF($B18="","",IF(Z18<>"","DPO Approval",IF(V18<>"","QA",IF(R18<>"","PBI Dev",IF(N18<>"","DB Dev","NOT STARTED"))))) -> NOT STARTED | AN18: =IF($B18="","",IF(IF($C18="NOT STARTED",0,IF($C18="DB Dev",1,IF($C18="PBI Dev",2,IF($C18="QA",3,IF($C18="DPO Approval",4,IF($C18="RELEASED IN PROD",5,-1))))))<IF($AM18="NOT STARTED",0,IF($AM18="DB Dev",1,IF($AM18="PBI Dev",2,IF($AM18="QA",3,IF($AM18="DPO Approval",4,IF($AM18="RELEASED IN PROD",5,-1)))))),"Yes - was already at "&$AM18&", now back at "&$C18,"No")) -> No | AO18: =IF($B18="","",IF(AND(V18<>"",N18<>"",V18<N18),"QA target is before DB Dev target",IF(AND(V18<>"",R18<>"",V18<R18),"QA target is before PBI Dev target",IF(AND(Z18<>"",V18<>"",Z18<V18),"DPO Approval target is before QA target",IF(AND(AC18<>"",Z18<>"",AC18<Z18),"Confirmed Deployed date is before DPO Approval target",""))))) | AP18: =IF($B18="","",IF(COUNTIF($B$2:$B$500,$B18)>1,"Duplicate name - check row","")) | AR18: =IF($B18="","",SUMPRODUCT(MAX(('Rework Log'!$A$3:$A$500=$B18)*ROW('Rework Log'!$A$3:$A$500)))) -> 0
A19: Leaks | B19: RPT_04_Leak Summary Status | C19: RELEASED IN PROD | D19: =IF($B19="","",IF(C19="NOT STARTED",IF(K19="","No plan date set",IF(K19<TODAY(),"Review - planned start passed","On track")),IF(C19="DB Dev",IF(N19="","No target set",IF(AND(N19<TODAY(),P19=""),"Overdue","On track")),IF(C19="PBI Dev",IF(R19="","No target set",IF(AND(R19<TODAY(),T19=""),"Overdue","On track")),IF(C19="QA",IF(V19="","No target set",IF(AND(V19<TODAY(),X19=""),"Overdue","On track")),IF(C19="DPO Approval",IF(Z19="","No target set",IF(Z19<TODAY(),"Overdue","On track")),IF(C19="RELEASED IN PROD","Delivered",""))))))) -> Delivered | E19: 18 | G19: Fetwi | H19: Navya | I19: Kelvin | K19: 46173 | L19: May | T19: 46143 | X19: 46175 | AA19: Kelvin Hu | AB19: Yes | AC19: 46184 | AD19: https://app.powerbi.com/groups/me/apps/7767030c-f4c8-4488-b3cb-36a860cb6ff2/reports/184a9cdc-83f5-40b0-940d-d901ad9fb404/ReportSection6d915001f68ea4805272?ctid=f98a6a53-25f3-4212-901c-c7787fcd3495&experience=power-bi | AE19: https://app.powerbi.com/groups/me/apps/5b29b0dd-a398-4801-84ce-f3a7d8435827/reports/f7af2903-2d63-497e-b262-100f5a3b500b/ReportSection6d915001f68ea4805272?ctid=f98a6a53-25f3-4212-901c-c7787fcd3495&experience=power-bi | AF19: No | AH19: =IF($AF19="Yes",IF($AG19<>"","Blocked - needs "&$AG19&" to fix","Blocked at "&$C19),"") | AI19: =IF($B19="","",COUNTIF('Rework Log'!$A$3:$A$500,$B19)) -> 0 | AJ19: =IF(OR($B19="",$AR19=0),"",INDEX('Rework Log'!$C:$C,$AR19)) | AK19: =IF(OR($B19="",$AR19=0),"",INDEX('Rework Log'!$H:$H,$AR19)) | AL19: =IF(OR($B19="",$AR19=0),"",INDEX('Rework Log'!$G:$G,$AR19)) | AM19: =IF($B19="","",IF(Z19<>"","DPO Approval",IF(V19<>"","QA",IF(R19<>"","PBI Dev",IF(N19<>"","DB Dev","NOT STARTED"))))) -> NOT STARTED | AN19: =IF($B19="","",IF(IF($C19="NOT STARTED",0,IF($C19="DB Dev",1,IF($C19="PBI Dev",2,IF($C19="QA",3,IF($C19="DPO Approval",4,IF($C19="RELEASED IN PROD",5,-1))))))<IF($AM19="NOT STARTED",0,IF($AM19="DB Dev",1,IF($AM19="PBI Dev",2,IF($AM19="QA",3,IF($AM19="DPO Approval",4,IF($AM19="RELEASED IN PROD",5,-1)))))),"Yes - was already at "&$AM19&", now back at "&$C19,"No")) -> No | AO19: =IF($B19="","",IF(AND(V19<>"",N19<>"",V19<N19),"QA target is before DB Dev target",IF(AND(V19<>"",R19<>"",V19<R19),"QA target is before PBI Dev target",IF(AND(Z19<>"",V19<>"",Z19<V19),"DPO Approval target is before QA target",IF(AND(AC19<>"",Z19<>"",AC19<Z19),"Confirmed Deployed date is before DPO Approval target",""))))) | AP19: =IF($B19="","",IF(COUNTIF($B$2:$B$500,$B19)>1,"Duplicate name - check row","")) | AR19: =IF($B19="","",SUMPRODUCT(MAX(('Rework Log'!$A$3:$A$500=$B19)*ROW('Rework Log'!$A$3:$A$500)))) -> 0
A20: Leaks | B20: RPT_04_PSC Leak Printout | C20: RELEASED IN PROD | D20: =IF($B20="","",IF(C20="NOT STARTED",IF(K20="","No plan date set",IF(K20<TODAY(),"Review - planned start passed","On track")),IF(C20="DB Dev",IF(N20="","No target set",IF(AND(N20<TODAY(),P20=""),"Overdue","On track")),IF(C20="PBI Dev",IF(R20="","No target set",IF(AND(R20<TODAY(),T20=""),"Overdue","On track")),IF(C20="QA",IF(V20="","No target set",IF(AND(V20<TODAY(),X20=""),"Overdue","On track")),IF(C20="DPO Approval",IF(Z20="","No target set",IF(Z20<TODAY(),"Overdue","On track")),IF(C20="RELEASED IN PROD","Delivered",""))))))) -> Delivered | E20: 19 | G20: Fetwi | H20: Shraddha | I20: Preety | K20: 46173 | L20: May | P20: 46175 | T20: 46178 | X20: 46175 | AA20: Kelvin Hu | AB20: Yes | AC20: 46192 | AD20: https://app.powerbi.com/groups/me/apps/61b18507-2848-49b9-aacc-32c49ffe1e0b/rdlreports/84ee7713-075e-496c-8610-43022c6a55ab?ctid=f98a6a53-25f3-4212-901c-c7787fcd3495&experience=power-bi | AF20: No | AH20: =IF($AF20="Yes",IF($AG20<>"","Blocked - needs "&$AG20&" to fix","Blocked at "&$C20),"") | AI20: =IF($B20="","",COUNTIF('Rework Log'!$A$3:$A$500,$B20)) -> 0 | AJ20: =IF(OR($B20="",$AR20=0),"",INDEX('Rework Log'!$C:$C,$AR20)) | AK20: =IF(OR($B20="",$AR20=0),"",INDEX('Rework Log'!$H:$H,$AR20)) | AL20: =IF(OR($B20="",$AR20=0),"",INDEX('Rework Log'!$G:$G,$AR20)) | AM20: =IF($B20="","",IF(Z20<>"","DPO Approval",IF(V20<>"","QA",IF(R20<>"","PBI Dev",IF(N20<>"","DB Dev","NOT STARTED"))))) -> NOT STARTED | AN20: =IF($B20="","",IF(IF($C20="NOT STARTED",0,IF($C20="DB Dev",1,IF($C20="PBI Dev",2,IF($C20="QA",3,IF($C20="DPO Approval",4,IF($C20="RELEASED IN PROD",5,-1))))))<IF($AM20="NOT STARTED",0,IF($AM20="DB Dev",1,IF($AM20="PBI Dev",2,IF($AM20="QA",3,IF($AM20="DPO Approval",4,IF($AM20="RELEASED IN PROD",5,-1)))))),"Yes - was already at "&$AM20&", now back at "&$C20,"No")) -> No | AO20: =IF($B20="","",IF(AND(V20<>"",N20<>"",V20<N20),"QA target is before DB Dev target",IF(AND(V20<>"",R20<>"",V20<R20),"QA target is before PBI Dev target",IF(AND(Z20<>"",V20<>"",Z20<V20),"DPO Approval target is before QA target",IF(AND(AC20<>"",Z20<>"",AC20<Z20),"Confirmed Deployed date is before DPO Approval target",""))))) | AP20: =IF($B20="","",IF(COUNTIF($B$2:$B$500,$B20)>1,"Duplicate name - check row","")) | AQ20: [Historical, May/June 2026]: Fetwi was investigating a slowness issue in this report. | AR20: =IF($B20="","",SUMPRODUCT(MAX(('Rework Log'!$A$3:$A$500=$B20)*ROW('Rework Log'!$A$3:$A$500)))) -> 0
A21: Leaks | B21: RPT_04_Leak Control Report | C21: RELEASED IN PROD | D21: =IF($B21="","",IF(C21="NOT STARTED",IF(K21="","No plan date set",IF(K21<TODAY(),"Review - planned start passed","On track")),IF(C21="DB Dev",IF(N21="","No target set",IF(AND(N21<TODAY(),P21=""),"Overdue","On track")),IF(C21="PBI Dev",IF(R21="","No target set",IF(AND(R21<TODAY(),T21=""),"Overdue","On track")),IF(C21="QA",IF(V21="","No target set",IF(AND(V21<TODAY(),X21=""),"Overdue","On track")),IF(C21="DPO Approval",IF(Z21="","No target set",IF(Z21<TODAY(),"Overdue","On track")),IF(C21="RELEASED IN PROD","Delivered",""))))))) -> Delivered | E21: 20 | G21: Geetha | H21: Navya | I21: Preety | K21: 46203 | L21: June | P21: 46148 | T21: 46183 | X21: 46195 | AF21: No | AH21: =IF($AF21="Yes",IF($AG21<>"","Blocked - needs "&$AG21&" to fix","Blocked at "&$C21),"") | AI21: =IF($B21="","",COUNTIF('Rework Log'!$A$3:$A$500,$B21)) -> 0 | AJ21: =IF(OR($B21="",$AR21=0),"",INDEX('Rework Log'!$C:$C,$AR21)) | AK21: =IF(OR($B21="",$AR21=0),"",INDEX('Rework Log'!$H:$H,$AR21)) | AL21: =IF(OR($B21="",$AR21=0),"",INDEX('Rework Log'!$G:$G,$AR21)) | AM21: =IF($B21="","",IF(Z21<>"","DPO Approval",IF(V21<>"","QA",IF(R21<>"","PBI Dev",IF(N21<>"","DB Dev","NOT STARTED"))))) -> NOT STARTED | AN21: =IF($B21="","",IF(IF($C21="NOT STARTED",0,IF($C21="DB Dev",1,IF($C21="PBI Dev",2,IF($C21="QA",3,IF($C21="DPO Approval",4,IF($C21="RELEASED IN PROD",5,-1))))))<IF($AM21="NOT STARTED",0,IF($AM21="DB Dev",1,IF($AM21="PBI Dev",2,IF($AM21="QA",3,IF($AM21="DPO Approval",4,IF($AM21="RELEASED IN PROD",5,-1)))))),"Yes - was already at "&$AM21&", now back at "&$C21,"No")) -> No | AO21: =IF($B21="","",IF(AND(V21<>"",N21<>"",V21<N21),"QA target is before DB Dev target",IF(AND(V21<>"",R21<>"",V21<R21),"QA target is before PBI Dev target",IF(AND(Z21<>"",V21<>"",Z21<V21),"DPO Approval target is before QA target",IF(AND(AC21<>"",Z21<>"",AC21<Z21),"Confirmed Deployed date is before DPO Approval target",""))))) | AP21: =IF($B21="","",IF(COUNTIF($B$2:$B$500,$B21)>1,"Duplicate name - check row","")) | AR21: =IF($B21="","",SUMPRODUCT(MAX(('Rework Log'!$A$3:$A$500=$B21)*ROW('Rework Log'!$A$3:$A$500)))) -> 0
A22: Leaks | B22: RPT_04_Leak Life Cycle | C22: RELEASED IN PROD | D22: =IF($B22="","",IF(C22="NOT STARTED",IF(K22="","No plan date set",IF(K22<TODAY(),"Review - planned start passed","On track")),IF(C22="DB Dev",IF(N22="","No target set",IF(AND(N22<TODAY(),P22=""),"Overdue","On track")),IF(C22="PBI Dev",IF(R22="","No target set",IF(AND(R22<TODAY(),T22=""),"Overdue","On track")),IF(C22="QA",IF(V22="","No target set",IF(AND(V22<TODAY(),X22=""),"Overdue","On track")),IF(C22="DPO Approval",IF(Z22="","No target set",IF(Z22<TODAY(),"Overdue","On track")),IF(C22="RELEASED IN PROD","Delivered",""))))))) -> Delivered | E22: 21 | G22: Geetha | H22: Shraddha | I22: Preety | K22: 46203 | L22: June | P22: 46162 | T22: 46182 | X22: 46198 | AF22: No | AH22: =IF($AF22="Yes",IF($AG22<>"","Blocked - needs "&$AG22&" to fix","Blocked at "&$C22),"") | AI22: =IF($B22="","",COUNTIF('Rework Log'!$A$3:$A$500,$B22)) -> 0 | AJ22: =IF(OR($B22="",$AR22=0),"",INDEX('Rework Log'!$C:$C,$AR22)) | AK22: =IF(OR($B22="",$AR22=0),"",INDEX('Rework Log'!$H:$H,$AR22)) | AL22: =IF(OR($B22="",$AR22=0),"",INDEX('Rework Log'!$G:$G,$AR22)) | AM22: =IF($B22="","",IF(Z22<>"","DPO Approval",IF(V22<>"","QA",IF(R22<>"","PBI Dev",IF(N22<>"","DB Dev","NOT STARTED"))))) -> NOT STARTED | AN22: =IF($B22="","",IF(IF($C22="NOT STARTED",0,IF($C22="DB Dev",1,IF($C22="PBI Dev",2,IF($C22="QA",3,IF($C22="DPO Approval",4,IF($C22="RELEASED IN PROD",5,-1))))))<IF($AM22="NOT STARTED",0,IF($AM22="DB Dev",1,IF($AM22="PBI Dev",2,IF($AM22="QA",3,IF($AM22="DPO Approval",4,IF($AM22="RELEASED IN PROD",5,-1)))))),"Yes - was already at "&$AM22&", now back at "&$C22,"No")) -> No | AO22: =IF($B22="","",IF(AND(V22<>"",N22<>"",V22<N22),"QA target is before DB Dev target",IF(AND(V22<>"",R22<>"",V22<R22),"QA target is before PBI Dev target",IF(AND(Z22<>"",V22<>"",Z22<V22),"DPO Approval target is before QA target",IF(AND(AC22<>"",Z22<>"",AC22<Z22),"Confirmed Deployed date is before DPO Approval target",""))))) | AP22: =IF($B22="","",IF(COUNTIF($B$2:$B$500,$B22)>1,"Duplicate name - check row","")) | AQ22: [Historical, June 2026]: Waiting on Kelvin's approval to deploy to UAT. | AR22: =IF($B22="","",SUMPRODUCT(MAX(('Rework Log'!$A$3:$A$500=$B22)*ROW('Rework Log'!$A$3:$A$500)))) -> 0
