Workbook

Sheet CMS PBI RPT View Details
A1: Business Value (Rank) | B1: Reports | C1: DB Developers | D1: PBI Developers | E1: Schema | F1: Snowflake DEV View | G1: QA View Staus | H1: UAT View Staus | I1: PROD View Staus | J1: Reporting Sprint Goal | K1: Report Number
A2: 1 | B2: RPT_02_CO Flue Warning Tag Control | C2: Rupa | D2: Navya | F2: gdm_rpt.vw_CO_Flue_Warning_Tag_Control | K2: 28
A3: 2 | B3: RPT_02_Warning Tag HEFPA | C3: Sree | D3: Shraddha | E3: GDM_RPT | F3: VW_WARNING_TAG_HEFPA | K3: 29
A4: 3 | B4: RPT_02_Warning tag Printout | C4: Sree | D4: Navya | K4: 30
A5: 4 | B5: RPT_02_Corrosion | C5: Siva | D5: Sarath | K5: 31
A6: 5 | B6: RPT_02_House Pipe Test Comment Control | C6: Geeta | D6: Shraddha | E6: GDM_RPT | F6: GDM_RPT.VW_CMS_HOUSE_PIPE_TEST_COMMENT | K6: 32
A7: 6 | B7: RPT_02 _Required Regulator Inspection Performed Control | C7: Siddu | D7: Navya | E7: GDM_RPT | F7: GDM_RPT.VW_REQUIRED_REGULATOR_INSPECTIONS_PERFORMED_CONTROL | K7: 33
A8: 7 | B8: RPT_02_Service Regulator Inspections | C8: Sree | D8: Sarath | E8: GDM_RPT | F8: GDM_RPT.VW_SERVICE_REGULATOR_INSPECTIONS | K8: 34
A9: 8 | B9: RPT_02_Service Regulator Inspection Printout | C9: Sree | D9: Sarath | E9: GDM_RPT | F9: GDM_RPT.VW_SERVICE_REGULATOR_INSPECTION_PRINTOUT | K9: 35
A10: 9 | B10: RPT_02_20 Year Regulator Inspection | C10: Siddu | D10: Navya | K10: 36
A11: 10 | B11: RPT_02_Fixed Factor | C11: Nick | D11: Shraddha | K11: 37
A12: 11 | B12: RPT_02_Fixed Factor Printout | C12: Nick | D12: Shraddha | K12: 38
A13: 12 | B13: RPT_02_Fixed Factor Mismatch | C13: Rupa | D13: Sarath | K13: 39
A14: 13 | B14: RPT_02_Work Order Completion Printout | C14: Rupa | D14: Sarath | K14: 40
A15: 14 | B15: RPT_02_GRO Control | C15: Siva | D15: Navya | K15: 41
A16: 15 | B16: RPT_02_GRO Monitor | D16: Navya | K16: 42

Sheet Report Migration Status
A1: April Delivery | G1: Release Date Schedule | P1: Total
A2: Leak Reports | B2: In Progress | C2: DEV | D2: PBI | E2: In QA | F2: In UAT | G2: In Production | H2: 46142 | I2: 46149 | J2: 46166 | K2: 46170 | L2: 46177 | M2: 46184 | N2: 46191 | O2: 46198
A3: 8 | H3: 7 | I3: 1 | J3: 0
P5: =SUM(G3:N3) -> 8
A6: May Delivery | G6: Release Date Schedule
A7: Leak Reports | B7: In progress | C7: DEV | D7: PBI | E7: In QA | F7: In UAT | G7: In Production | H7: 46142 | I7: 46149 | J7: 46166 | K7: 46170 | L7: 46177 | M7: 46184 | N7: 46191 | O7: 46198
A8: 10 | H8: 0 | J8: 0 | K8: 4 | L8: 2 | M8: 2 | N8: 2 | P8: Total
P10: =SUM(G8:O8) -> 10
A11: JuneDelivery | G11: Release Date Schedule
A12: Leak Reports | B12: In progress | C12: DEV | D12: PBI | E12: In QA | F12: In UAT | G12: In Production | H12: 46142 | I12: 46149 | J12: 46166 | K12: 46170 | L12: 46177 | M12: 46184 | N12: 46191 | O12: 46198
A13: 9 | C13: 3 | D13: 1 | F13: 2 | H13: 0 | J13: 0 | M13: 1 | N13: 1 | O13: 1 | P13: Total
P15: =SUM(G13:O13) -> 3

Sheet Leaks PBI RPT View Details 
A1: Business Value (Rank) | B1: Report Name | C1: DB Developers | D1: PBI Developers | E1: Schema | F1: Snowflake DEV View | G1: QA View Staus | H1: UAT View Staus | I1: PROD View Staus | J1: Reporting Sprint Goal | K1: Report Number
A2: 1 | B2: RPT_04_Active Leaks | C2: Fetwi | D2: Sarath | E2: GDM_RPT | F2: DEV_GDM_DEV_DB.GDM_RPT.VW_ACTIVE_LEAKS | G2: Ready | J2: Sprint 1 | K2: 1
A3: 2 | B3: RPT_04_Count of Active Leaks On Hand | C3: Fetwi | D3: Sarath | E3: GDM_RPT | F3: DEV_GDM_DEV_DB.GDM_RPT.VW_ACTIVE_LEAKS | G3: Ready | J3: Sprint 1 | K3: 2
A4: 4 | B4: RPT_04_Leak Scheduling | C4: Sreevarsha | D4: Sarath | E4: GDM_RPT | F4: DEV_GDM_DEV.GDM_RPT.VW_GAS_LEAK_SCHEDULING | K4: NA
A5: 5 | B5: RPT_04_Leak Days Remaining | C5: Siva | D5: Navya | E5: GDM_RPT | F5: DEV_GDM_DEV_DB.GDM_RPT.VW_LEAK_DAYS_REMAINING | G5: Ready | J5: Sprint 1 | K5: 3
A6: 3 | B6: RPT_04_Cleared Leaks | C6: Sreevarsha | D6: Sarath | E6: GDM_RPT | F6: DEV_GDM_DEV_DB.GDM_RPT.VW_CLEARED_LEAKS | G6: Ready | J6: Sprint 2 | K6: 4
A7: 6 | B7: RPT_04_Leaks Repaired Detail | C7: Rupa | D7: Shraddha | E7: GDM_RPT | F7: GDM_RPT.VW_LEAKS_REPAIRED_DETAIL | G7: Ready | J7: Sprint 2 | K7: 5
A8: 7 | B8: RPT_04_Leaks Aging | C8: Sreevarsha | D8: Navya | E8: GDM_RPT | F8: GDM_RPT.VW_LEAKS_AGING | G8: Ready | J8: Sprint 2 | K8: 6
A9: 9 | B9: RPT_04_Prior Leak Readings | C9: Siddhu | D9: Navya | E9: GDM_RPT | F9: DEV_GDM_DEV_DB.GDM_RPT.VW_PRIOR_LEAK_READINGS | G9: Ready | J9: Sprint 2 | K9: 7
A10: 8 | B10: RSS_04_Leak Grade Change History | C10: Siva | D10: Navya | E10: GDM_RPT | F10: DEV_GDM_DEV.GDM_RPT.VW_LEAK_GRADE_CHANGE_HISTORY | K10: 8
A11: 14 | B11: RPT_04_Rechecks Completed less than 14 days | C11: Rupa | D11: Shraddha | E11: GDM_RPT | F11: gdm_rpt.vw_Rechecks_Completed_less_than_14days | J11: Sprint 3 | K11: 9
A12: 15 | B12: RPT_04_SEI Leak Activity | C12: Siva | D12: Shraddha | E12: GDM_RPT | F12: DEV_GDM_DEV_DB.GDM_RPT.VW_SEI_LEAK_ACTIVITY_LEAK_EXTENT | J12: Sprint 3 | K12: 10
E13: GDM_RPT | F13: DEV_GDM_DEV_DB.GDM_RPT.VW_SEI_LEAK_ACTIVITY_LEAKS_LOC
A14: 13 | B14: RPT_04_PSC Quarterly Leak | C14: Geetha | D14: Sarath | E14: GDM_RPT | F14: DEV_GDM_DEV_DB.GDM_RPT.VW_PSC_QUARTERLY_LEAKS | J14: Sprint 3 | K14: 11
A15: 10 | B15: RPT_04_Surveillances With Zero Readings | C15: Sreevarsha | D15: Navya | E15: GDM_RPT | F15: GDM_RPT.VW_SURVEILLANCES_WITH_ZERO_READINGS | J15: Sprint 3 | K15: 12
A16: 11 | B16: RPT_04 High Emitter leaks | C16: Sreevarsha | D16: Navya | E16: GDM_RPT | F16: GDM_RPT.VW_HIGH_EMITTER_LEAKS | J16: Sprint 3 | K16: 13
A17: 12 | B17: RPT_04_School Zone Leaks Without Repair | C17: Sreevarsha | D17: Sarath | E17: GDM_RPT | F17: GDM_RPT.VW_SCHOOL_ZONE_LEAKS_REPORT | K17: 14
A18: 16 | B18: RPT_04_CMS Leak Productivity | C18: Siddu | D18: Navya | E18: GDM_RPT | F18: VW_CMS_LEAK_PRODUCTIVITY | K18: 15
A19: 17 | B19: RPT_04_Main Break Corrosion and Leak Cluster | C19: Siddu | D19: Sarath | E19: GDM_RPT | F19: VW_Leak_Cluster and VW_Main_Break | K19: 16
A20: 18 | B20: RPT_04_Leak Summary Status | C20: Fetwi | D20: Navya | E20: GDM_RPT | F20: DEV_GDM_DEV_DB.GDM_RPT.VW_LEAK_SUMMARY_STATUS | K20: 17
A21: 19 | B21: RPT_04_PSC Leak Printout | C21: Fetwi | D21: Shraddha | E21: GDM_RPT | F21: DEV_GDM_DEV_DB.GDM_RPT.VW_PSC_LEAK_PRINTOUT | K21: 18
A22: 20 | B22: RPT_04_Leak Increase Reads | C22: Fetwi | D22: Navya | E22: GDM_RPT | F22: DEV_GDM_DEV_DB.GDM_RPT.VW_LEAK_INCREASE_READS | K22: 19
A23: 21 | B23: RPT_04_Leak Control Report | C23: Geetha | D23: Navya | E23: GDM_RPT | F23: VW_LEAK_CONTROL, | K23: 20
E24: GDM_RPT | F24: VW_LEAK_CONTROL_COMPLETE, | K24: 20
E25: GDM_RPT | F25: VW_LEAK_CONTROL_REPAIR, | K25: 20
E26: GDM_RPT | F26: VW_LEAK_CONTROL_BACKLOG. | K26: 20
A27: 22 | B27: RPT_04_Leak Life Cycle | C27: Geetha | D27: Shraddha | E27: GDM_RPT | F27: VW_LEAK_LIFE_CYCLE_REPORT_LEAK_INVENTORY VW_Leak_Life_Cycle_Report_LeakInventoryWOSummary VW_LEAK_LIFE_CYCLE_REPORT_LEAKRECHECKSURVEY VW_LEAK_LIFE_CYCLE_REPORT_LEAK_READING VW_Leak_Life_Cycle_Report_LeakRepair VW_LEAK_LIFE_CYCLE_REPORT_LEAKREPAIRRESURVEY | K27: 21
A28: 23 | B28: RPT_04_Leak Life Cycle Legacy LMS LI | D28: Navya | F28: VW_DH_LEAK_LIFE_CYCLE_REPORT_LEAK_READING_LMS VW_DH_LEAK_LIFE_CYCLE_REPORT_LEAKINVENTORY_LMS VW_DH_LEAK_LIFE_CYCLE_REPORT_LEAKINVENTORYWOSUMMARY_LMS VW_DH_LEAK_LIFE_CYCLE_REPORT_LEAKRECHECKSURVEY_LMS VW_DH_LEAK_LIFE_CYCLE_REPORT_LEAKREPAIR_LMS VW_DH_LEAK_LIFE_CYCLE_REPORT_LEAKREPAIRRESURVEY_LMS | K28: 22
A29: 24 | B29: Leak 360 Dashboard | C29: Siva | D29: Sarath | E29: GDM_RPT | F29: VW_LEAKS360_DASHBOARD | K29: 23
F30: VW_LEAKS360_DASHBOARD_LEAKSWORKORDER | K30: 23
A31: 25 | B31: RPT_04_Leak Recheck Control | C31: Siva | D31: Shraddha | E31: GDM_RPT | F31: GDM_RPT.VW_LEAK_RECHECK_CONTROL_FAILED_LEAKS_R30 | K31: 24
E32: GDM_RPT | F32: GDM_RPT.VW_LEAK_RECHECK_CONTROL_FMEXCEPTION
E33: GDM_RPT | F33: GDM_RPT.VW_LEAK_RECHECK_CONTROL_LEAK_EXCEPTION
E34: GDM_RPT | F34: GDM_RPT.VW_LEAK_RECHECK_CONTROL_LEAK_GRADE_CHANGE_SAME_DAY
E35: GDM_RPT
E36: GDM_RPT | F36: GDM_RPT.VW_LEAK_RECHECK_CONTROL_LEAK_RECHECK_ANALYSIS
A37: 26 | B37: RPT_04_Main_Replacement Report | C37: Sreevarsha | D37: Navya | F37: vw_Main_Replacement_Report | K37: 25
A38: 27 | B38: RPT_04_ Leak Repair Exception | C38: Geetha | D38: Shraddha | F38: GDM_RPT.VW_LEAK_REPAIR_EXCEPTIONS | K38: 26
A39: 28 | B39: New Report called Leak_Sample_Point_Mismatch | C39: Siddu | D39: Shraddha | E39: GDM_RPT | F39: DEV_GDM_DEV_DB.GDM_RPT.VW_Leak_Sample_Point_Mismatch; | K39: 27
B46: * for QA/UAT/PROD provide status for availabilty

Sheet Fact Table
A1: Domain | B1: Status | C1: Status Start Date | D1: Expected Release Date | E1: Actual Release Date | F1: Report Name | G1: DB Developers | H1: PBI Developers | I1: Schema | J1: PO
A2: Leaks | B2: In Production | D2: 46142 | E2: 46142 | F2: RPT_04_Active Leaks | G2: Fetwi | H2: Sarath | I2: GDM_RPT | J2: PO3
A3: Leaks | B3: In Production | D3: 46203 | E3: 46203 | F3: RPT_04_Count of Active Leaks On Hand | J3: PO2
A4: Leaks | B4: In Production | D4: 46203 | E4: 46203 | F4: RPT_04_Leak Days Remaining | J4: PO3
A5: Leaks | B5: In Production | D5: 46203 | E5: 46203 | F5: RPT_04_Cleared Leaks | J5: PO1
A6: Leaks | B6: In Production | D6: 46203 | E6: 46203 | F6: RPT_04_Leaks Repaired Detail | J6: PO1
A7: Leaks | B7: In Production | D7: 46203 | E7: 46203 | F7: RPT_04_Leaks Aging | J7: PO1
A8: Leaks | B8: In Production | D8: 46203 | E8: 46203 | F8: RPT_04_Prior Leak Readings | J8: PO3
A9: Leaks | B9: In Production | D9: 46203 | E9: 46203 | F9: RSS_04_Leak Grade Change History | J9: PO3
A10: Leaks | B10: In Production | D10: 46203 | E10: 46203 | F10: RPT_04_Surveillances With Zero Readings | J10: PO2
A11: Leaks | B11: In Production | D11: 46203 | E11: 46203 | F11: RPT_04 High Emitter leaks | J11: PO1
A12: Leaks | B12: In Production | D12: 46203 | E12: 46203 | F12: RPT_04_School Zone Leaks Without Repair | J12: PO1
A13: Leaks | B13: In Production | D13: 46203 | E13: 46203 | F13: RPT_04_PSC Quarterly Leak | J13: PO1
A14: Leaks | B14: In Production | D14: 46203 | E14: 46203 | F14: RPT_04_Rechecks Completed less than 14 days | J14: PO2
... A23: Leaks | B23: In Production | D23: 46203 | E23: 46203 | F23: RPT_04_Leak Life Cycle | J23: PO2
A24: Leaks | B24: In Production | D24: 46203 | E24: 46219 | F24: RPT_04_Leak Life Cycle Legacy LMS LI | G24: Fetwi | H24: Navya | J24: PO3
A25: Leaks | B25: QA | D25: 46203 | E25: 46219 | F25: Leak 360 Dashboard | G25: Siva | H25: Sarath | J25: PO3
A26: Leaks | B26: In Production | D26: 46203 | E26: 46203 | F26: RPT_04_Leak Recheck Control | J26: PO2
A27: Leaks | B27: In Production | D27: 46203 | E27: 46203 | F27: Leak reading sample point mismatch | J27: PO1
A28: CMS | B28: Dev | D28: 46234 | F28: RPT_02_CO Flue Warning Tag Control | J28: PO1
A29: CMS | B29: Dev | D29: 46234 | F29: RPT_02_Warning Tag HEFPA | J29: PO3
A30: CMS | B30: Dev | D30: 46234 | F30: RPT_02_Warning tag Printout | J30: PO1
A31: CMS | B31: Dev | D31: 46234 | F31: RPT_02_Corrosion | J31: PO2
A32: CMS | B32: Dev | D32: 46234 | F32: RPT_02_House Pipe Test Comment Control | J32: PO2
A33: CMS | B33: Dev | D33: 46234 | F33: RPT_02 _Required Regulator Inspection Performed Control | J33: PO1
A34: CMS | B34: Dev | D34: 46234 | F34: RPT_02_Service Regulator Inspections | J34: PO1
A35: CMS | B35: Dev | D35: 46234 | F35: RPT_02_Service Regulator Inspection Printout | J35: PO2
A36: CMS | B36: Dev | D36: 46234 | F36: RPT_02_20 Year Regulator Inspection | J36: PO3
A37: CMS | B37: Dev | D37: 46234 | F37: RPT_02_Fixed Factor | J37: PO3
A38: CMS | B38: Dev | D38: 46234 | F38: RPT_02_Fixed Factor Printout | J38: PO2
A39: CMS | B39: Dev | D39: 46234 | F39: RPT_02_Work Order Completion Printout | J39: PO2
... A41: CMS | B41: Dev | D41: 46264 | F41: RPT_02_GRO Monitor | J41: PO2
A42: CMS | B42: Dev | D42: 46264 | F42: RPT_02_Public Buildings Inspection | G42: Geetha | J42: PO3
A43: CMS | B43: Dev | D43: 46264 | F43: RPT_02_Investigate Wall Check and Service Check | G43: Sree | J43: PO3
A44: CMS | B44: Dev | D44: 46264 | F44: RPT_02_Cut Out Orders | G44: Fetwi | J44: PO1
A45: CMS | B45: Dev | D45: 46264 | F45: RPT_02_Gas Trouble | G45: Siddu | J45: PO1
A46: CMS | B46: Not Started | D46: 46264 | F46: RPT_02_Wall Check Control | J46: PO3
A47: CMS | B47: Not Started | D47: 46264 | F47: RPT_02_High Pressure Steel Inside Inspection | J47: PO2
A48: CMS | B48: Not Started | D48: 46264 | F48: RPT_02_Large Gas Outage | J48: PO3
A49: CMS | B49: Not Started | D49: 46264 | F49: RPT_02_Fitting Work | J49: PO2
...

Sheet Dim Table
A1: Domain | B1: Expected Report Count | C1: Expected Release Date
A2: Leaks | B2: 8 | C2: 46142
A3: Leaks | B3: 10 | C3: 46172
A4: Leaks | B4: 9 | C4: 46203
A5: CMS | B5: 15 | C5: 46233
A6: CMS | B6: 15 | C6: 46264
A7: CMS | B7: 17 | C7: 46295
A8: CMS | B8: 20 | C8: 46325
A9: CMS | B9: 20 | C9: 46356
A10: Maintenance and Construction | B10: 18 | C10: 46386
A11: Maintenance and Construction | B11: 18 | C11: 46417
A12: Maintenance and Construction | B12: 19 | C12: 46446
A13: Meter Management | B13: 9 | C13: 46476
A14: Assets and Engineering | B14: 8 | C14: 46476

Sheet Sheet3
A2: In Progress
A3: DEV
A4: PBI
A5: In QA
A6: In UAT
A7: In Production

Sheet Timeline Chart
A1: Reports Migration & Data Product Timelines
A3: Data Product | B3: Count | D3: Apr-26 | E3: May-26 | F3: Jun-26 | G3: Jul-26 | H3: Aug-26 | I3: Sep-26 | J3: Oct-26 | K3: Nov-26 | L3: Dec-26 | M3: Jan-27 | N3: Feb-27 | O3: Mar-27
A4: Leaks (RPT) | B4: =SUMIF(Table2[Domain],"Leaks",Table2[Expected Report Count]) -> 27 | D4: ='Dim Table'!B2 -> 8 | E4: ='Dim Table'!B3 -> 10 | F4: ='Dim Table'!B4 -> 9
A5: CMS (includes Dispatch) (RPT) | B5: =SUMIF(Table2[Domain],"CMS",Table2[Expected Report Count]) -> 87 | G5: ='Dim Table'!B5 -> 15 | H5: ='Dim Table'!B6 -> 15 | I5: ='Dim Table'!B7 -> 17 | J5: ='Dim Table'!B8 -> 20 | K5: ='Dim Table'!B9 -> 20
A6: Maintenance and Construction (RPT) | B6: =SUMIF(Table2[Domain],"Maintenance and Construction",Table2[Expected Report Count]) -> 55 | L6: ='Dim Table'!B10 -> 18 | M6: ='Dim Table'!B11 -> 18 | N6: ='Dim Table'!B12 -> 19
A7: Meter Management (RPT) | B7: =SUMIF(Table2[Domain],"Meter Management",Table2[Expected Report Count]) -> 9 | O7: ='Dim Table'!B13 -> 9
A8: Assets and Engineering (RPT) | B8: =SUMIF(Table2[Domain],"Assets and Engineering",Table2[Expected Report Count]) -> 8 | O8: ='Dim Table'!B14 -> 8
A9: Total | B9: =SUM(B4:B8) -> 186

Sheet Sheet1
A1: Not Started
A2: DEV
A3: QA
A4: DPO Approval
A5: In Production

Sheet Sheet2
